{
 "cells": [
  {
   "cell_type": "code",
   "execution_count": 1,
   "metadata": {
    "id": "M-2nabK6Nb3w",
    "scrolled": true
   },
   "outputs": [],
   "source": [
    "%%capture\n",
    "!sudo curl -L https://github.com/dolthub/dolt/releases/latest/download/install.sh | sudo bash\n",
    "!pip install pymysql\n",
    "!dolt clone onefact/paylesshealth\n",
    "  "
   ]
  },
  {
   "cell_type": "code",
   "execution_count": 2,
   "metadata": {
    "id": "Q1E9MzzDvNmN",
    "scrolled": true
   },
   "outputs": [],
   "source": [
    "!cd paylesshealth/ && dolt sql -q \"select * from hospitals where cdm_url is not null;\" -r csv > hospitals.csv"
   ]
  },
  {
   "cell_type": "code",
   "execution_count": 48,
   "metadata": {
    "colab": {
     "base_uri": "https://localhost:8080/",
     "height": 409
    },
    "id": "t2eHYzw1vUKt",
    "outputId": "329c8be5-416b-4688-8de9-a268262b72eb",
    "scrolled": true
   },
   "outputs": [],
   "source": [
    "import pandas as pd\n",
    "# df = pd.read_csv('paylesshealth/hospitals.csv')\n",
    "df = pd.read_csv('non-null.csv')\n",
    "# df = df.head()"
   ]
  },
  {
   "cell_type": "code",
   "execution_count": 31,
   "metadata": {
    "id": "UVOkJyDov5ek",
    "scrolled": false
   },
   "outputs": [
    {
     "name": "stderr",
     "output_type": "stream",
     "text": [
      "Task exception was never retrieved\n",
      "future: <Task finished name='Task-28894' coro=<tqdm_asyncio.gather.<locals>.wrap_awaitable() done, defined at c:\\users\\adria\\miniconda3\\envs\\scraper\\lib\\site-packages\\tqdm\\asyncio.py:75> exception=ServerDisconnectedError('Server disconnected')>\n",
      "Traceback (most recent call last):\n",
      "  File \"c:\\users\\adria\\miniconda3\\envs\\scraper\\lib\\site-packages\\tqdm\\asyncio.py\", line 76, in wrap_awaitable\n",
      "    return i, await f\n",
      "  File \"C:\\Users\\adria\\AppData\\Local\\Temp\\ipykernel_27608\\3299729886.py\", line 22, in checker\n",
      "    async with session.get(url, allow_redirects=True, ssl=False, raise_for_status=True, timeout=100, headers=headers) as r:\n",
      "  File \"c:\\users\\adria\\miniconda3\\envs\\scraper\\lib\\site-packages\\aiohttp\\client.py\", line 1141, in __aenter__\n",
      "    self._resp = await self._coro\n",
      "  File \"c:\\users\\adria\\miniconda3\\envs\\scraper\\lib\\site-packages\\aiohttp\\client.py\", line 560, in _request\n",
      "    await resp.start(conn)\n",
      "  File \"c:\\users\\adria\\miniconda3\\envs\\scraper\\lib\\site-packages\\aiohttp\\client_reqrep.py\", line 899, in start\n",
      "    message, payload = await protocol.read()  # type: ignore[union-attr]\n",
      "  File \"c:\\users\\adria\\miniconda3\\envs\\scraper\\lib\\site-packages\\aiohttp\\streams.py\", line 616, in read\n",
      "    await self._waiter\n",
      "aiohttp.client_exceptions.ServerDisconnectedError: Server disconnected\n",
      "Task exception was never retrieved\n",
      "future: <Task finished name='Task-27390' coro=<tqdm_asyncio.gather.<locals>.wrap_awaitable() done, defined at c:\\users\\adria\\miniconda3\\envs\\scraper\\lib\\site-packages\\tqdm\\asyncio.py:75> exception=ServerDisconnectedError('Server disconnected')>\n",
      "Traceback (most recent call last):\n",
      "  File \"c:\\users\\adria\\miniconda3\\envs\\scraper\\lib\\site-packages\\tqdm\\asyncio.py\", line 76, in wrap_awaitable\n",
      "    return i, await f\n",
      "  File \"C:\\Users\\adria\\AppData\\Local\\Temp\\ipykernel_27608\\3299729886.py\", line 22, in checker\n",
      "    async with session.get(url, allow_redirects=True, ssl=False, raise_for_status=True, timeout=100, headers=headers) as r:\n",
      "  File \"c:\\users\\adria\\miniconda3\\envs\\scraper\\lib\\site-packages\\aiohttp\\client.py\", line 1141, in __aenter__\n",
      "    self._resp = await self._coro\n",
      "  File \"c:\\users\\adria\\miniconda3\\envs\\scraper\\lib\\site-packages\\aiohttp\\client.py\", line 560, in _request\n",
      "    await resp.start(conn)\n",
      "  File \"c:\\users\\adria\\miniconda3\\envs\\scraper\\lib\\site-packages\\aiohttp\\client_reqrep.py\", line 899, in start\n",
      "    message, payload = await protocol.read()  # type: ignore[union-attr]\n",
      "  File \"c:\\users\\adria\\miniconda3\\envs\\scraper\\lib\\site-packages\\aiohttp\\streams.py\", line 616, in read\n",
      "    await self._waiter\n",
      "aiohttp.client_exceptions.ServerDisconnectedError: Server disconnected\n",
      "Task exception was never retrieved\n",
      "future: <Task finished name='Task-30516' coro=<tqdm_asyncio.gather.<locals>.wrap_awaitable() done, defined at c:\\users\\adria\\miniconda3\\envs\\scraper\\lib\\site-packages\\tqdm\\asyncio.py:75> exception=ServerDisconnectedError('Server disconnected')>\n",
      "Traceback (most recent call last):\n",
      "  File \"c:\\users\\adria\\miniconda3\\envs\\scraper\\lib\\site-packages\\tqdm\\asyncio.py\", line 76, in wrap_awaitable\n",
      "    return i, await f\n",
      "  File \"C:\\Users\\adria\\AppData\\Local\\Temp\\ipykernel_27608\\3299729886.py\", line 22, in checker\n",
      "    async with session.get(url, allow_redirects=True, ssl=False, raise_for_status=True, timeout=100, headers=headers) as r:\n",
      "  File \"c:\\users\\adria\\miniconda3\\envs\\scraper\\lib\\site-packages\\aiohttp\\client.py\", line 1141, in __aenter__\n",
      "    self._resp = await self._coro\n",
      "  File \"c:\\users\\adria\\miniconda3\\envs\\scraper\\lib\\site-packages\\aiohttp\\client.py\", line 560, in _request\n",
      "    await resp.start(conn)\n",
      "  File \"c:\\users\\adria\\miniconda3\\envs\\scraper\\lib\\site-packages\\aiohttp\\client_reqrep.py\", line 899, in start\n",
      "    message, payload = await protocol.read()  # type: ignore[union-attr]\n",
      "  File \"c:\\users\\adria\\miniconda3\\envs\\scraper\\lib\\site-packages\\aiohttp\\streams.py\", line 616, in read\n",
      "    await self._waiter\n",
      "aiohttp.client_exceptions.ServerDisconnectedError: Server disconnected\n",
      "Task exception was never retrieved\n",
      "future: <Task finished name='Task-26887' coro=<tqdm_asyncio.gather.<locals>.wrap_awaitable() done, defined at c:\\users\\adria\\miniconda3\\envs\\scraper\\lib\\site-packages\\tqdm\\asyncio.py:75> exception=ClientConnectionError('Connector is closed.')>\n",
      "Traceback (most recent call last):\n",
      "  File \"c:\\users\\adria\\miniconda3\\envs\\scraper\\lib\\site-packages\\tqdm\\asyncio.py\", line 76, in wrap_awaitable\n",
      "    return i, await f\n",
      "  File \"C:\\Users\\adria\\AppData\\Local\\Temp\\ipykernel_27608\\3299729886.py\", line 22, in checker\n",
      "    async with session.get(url, allow_redirects=True, ssl=False, raise_for_status=True, timeout=100, headers=headers) as r:\n",
      "  File \"c:\\users\\adria\\miniconda3\\envs\\scraper\\lib\\site-packages\\aiohttp\\client.py\", line 1141, in __aenter__\n",
      "    self._resp = await self._coro\n",
      "  File \"c:\\users\\adria\\miniconda3\\envs\\scraper\\lib\\site-packages\\aiohttp\\client.py\", line 536, in _request\n",
      "    conn = await self._connector.connect(\n",
      "  File \"c:\\users\\adria\\miniconda3\\envs\\scraper\\lib\\site-packages\\aiohttp\\connector.py\", line 543, in connect\n",
      "    raise ClientConnectionError(\"Connector is closed.\")\n",
      "aiohttp.client_exceptions.ClientConnectionError: Connector is closed.\n",
      "Task exception was never retrieved\n",
      "future: <Task finished name='Task-30826' coro=<tqdm_asyncio.gather.<locals>.wrap_awaitable() done, defined at c:\\users\\adria\\miniconda3\\envs\\scraper\\lib\\site-packages\\tqdm\\asyncio.py:75> exception=ClientConnectionError('Connector is closed.')>\n",
      "Traceback (most recent call last):\n",
      "  File \"c:\\users\\adria\\miniconda3\\envs\\scraper\\lib\\site-packages\\tqdm\\asyncio.py\", line 76, in wrap_awaitable\n",
      "    return i, await f\n",
      "  File \"C:\\Users\\adria\\AppData\\Local\\Temp\\ipykernel_27608\\3299729886.py\", line 22, in checker\n",
      "    async with session.get(url, allow_redirects=True, ssl=False, raise_for_status=True, timeout=100, headers=headers) as r:\n",
      "  File \"c:\\users\\adria\\miniconda3\\envs\\scraper\\lib\\site-packages\\aiohttp\\client.py\", line 1141, in __aenter__\n",
      "    self._resp = await self._coro\n",
      "  File \"c:\\users\\adria\\miniconda3\\envs\\scraper\\lib\\site-packages\\aiohttp\\client.py\", line 536, in _request\n",
      "    conn = await self._connector.connect(\n",
      "  File \"c:\\users\\adria\\miniconda3\\envs\\scraper\\lib\\site-packages\\aiohttp\\connector.py\", line 543, in connect\n",
      "    raise ClientConnectionError(\"Connector is closed.\")\n",
      "aiohttp.client_exceptions.ClientConnectionError: Connector is closed.\n",
      "Task exception was never retrieved\n",
      "future: <Task finished name='Task-30458' coro=<tqdm_asyncio.gather.<locals>.wrap_awaitable() done, defined at c:\\users\\adria\\miniconda3\\envs\\scraper\\lib\\site-packages\\tqdm\\asyncio.py:75> exception=ClientConnectionError('Connector is closed.')>\n",
      "Traceback (most recent call last):\n",
      "  File \"c:\\users\\adria\\miniconda3\\envs\\scraper\\lib\\site-packages\\tqdm\\asyncio.py\", line 76, in wrap_awaitable\n",
      "    return i, await f\n",
      "  File \"C:\\Users\\adria\\AppData\\Local\\Temp\\ipykernel_27608\\3299729886.py\", line 22, in checker\n",
      "    async with session.get(url, allow_redirects=True, ssl=False, raise_for_status=True, timeout=100, headers=headers) as r:\n",
      "  File \"c:\\users\\adria\\miniconda3\\envs\\scraper\\lib\\site-packages\\aiohttp\\client.py\", line 1141, in __aenter__\n",
      "    self._resp = await self._coro\n",
      "  File \"c:\\users\\adria\\miniconda3\\envs\\scraper\\lib\\site-packages\\aiohttp\\client.py\", line 536, in _request\n",
      "    conn = await self._connector.connect(\n",
      "  File \"c:\\users\\adria\\miniconda3\\envs\\scraper\\lib\\site-packages\\aiohttp\\connector.py\", line 543, in connect\n",
      "    raise ClientConnectionError(\"Connector is closed.\")\n",
      "aiohttp.client_exceptions.ClientConnectionError: Connector is closed.\n",
      "Task exception was never retrieved\n",
      "future: <Task finished name='Task-27149' coro=<tqdm_asyncio.gather.<locals>.wrap_awaitable() done, defined at c:\\users\\adria\\miniconda3\\envs\\scraper\\lib\\site-packages\\tqdm\\asyncio.py:75> exception=ClientConnectionError('Connector is closed.')>\n",
      "Traceback (most recent call last):\n",
      "  File \"c:\\users\\adria\\miniconda3\\envs\\scraper\\lib\\site-packages\\tqdm\\asyncio.py\", line 76, in wrap_awaitable\n",
      "    return i, await f\n",
      "  File \"C:\\Users\\adria\\AppData\\Local\\Temp\\ipykernel_27608\\3299729886.py\", line 22, in checker\n",
      "    async with session.get(url, allow_redirects=True, ssl=False, raise_for_status=True, timeout=100, headers=headers) as r:\n",
      "  File \"c:\\users\\adria\\miniconda3\\envs\\scraper\\lib\\site-packages\\aiohttp\\client.py\", line 1141, in __aenter__\n",
      "    self._resp = await self._coro\n",
      "  File \"c:\\users\\adria\\miniconda3\\envs\\scraper\\lib\\site-packages\\aiohttp\\client.py\", line 536, in _request\n",
      "    conn = await self._connector.connect(\n",
      "  File \"c:\\users\\adria\\miniconda3\\envs\\scraper\\lib\\site-packages\\aiohttp\\connector.py\", line 543, in connect\n",
      "    raise ClientConnectionError(\"Connector is closed.\")\n",
      "aiohttp.client_exceptions.ClientConnectionError: Connector is closed.\n"
     ]
    },
    {
     "name": "stderr",
     "output_type": "stream",
     "text": [
      "Task exception was never retrieved\n",
      "future: <Task finished name='Task-29862' coro=<tqdm_asyncio.gather.<locals>.wrap_awaitable() done, defined at c:\\users\\adria\\miniconda3\\envs\\scraper\\lib\\site-packages\\tqdm\\asyncio.py:75> exception=ClientConnectionError('Connector is closed.')>\n",
      "Traceback (most recent call last):\n",
      "  File \"c:\\users\\adria\\miniconda3\\envs\\scraper\\lib\\site-packages\\tqdm\\asyncio.py\", line 76, in wrap_awaitable\n",
      "    return i, await f\n",
      "  File \"C:\\Users\\adria\\AppData\\Local\\Temp\\ipykernel_27608\\3299729886.py\", line 22, in checker\n",
      "    async with session.get(url, allow_redirects=True, ssl=False, raise_for_status=True, timeout=100, headers=headers) as r:\n",
      "  File \"c:\\users\\adria\\miniconda3\\envs\\scraper\\lib\\site-packages\\aiohttp\\client.py\", line 1141, in __aenter__\n",
      "    self._resp = await self._coro\n",
      "  File \"c:\\users\\adria\\miniconda3\\envs\\scraper\\lib\\site-packages\\aiohttp\\client.py\", line 536, in _request\n",
      "    conn = await self._connector.connect(\n",
      "  File \"c:\\users\\adria\\miniconda3\\envs\\scraper\\lib\\site-packages\\aiohttp\\connector.py\", line 543, in connect\n",
      "    raise ClientConnectionError(\"Connector is closed.\")\n",
      "aiohttp.client_exceptions.ClientConnectionError: Connector is closed.\n",
      "Task exception was never retrieved\n",
      "future: <Task finished name='Task-31207' coro=<tqdm_asyncio.gather.<locals>.wrap_awaitable() done, defined at c:\\users\\adria\\miniconda3\\envs\\scraper\\lib\\site-packages\\tqdm\\asyncio.py:75> exception=ClientConnectionError('Connector is closed.')>\n",
      "Traceback (most recent call last):\n",
      "  File \"c:\\users\\adria\\miniconda3\\envs\\scraper\\lib\\site-packages\\tqdm\\asyncio.py\", line 76, in wrap_awaitable\n",
      "    return i, await f\n",
      "  File \"C:\\Users\\adria\\AppData\\Local\\Temp\\ipykernel_27608\\3299729886.py\", line 22, in checker\n",
      "    async with session.get(url, allow_redirects=True, ssl=False, raise_for_status=True, timeout=100, headers=headers) as r:\n",
      "  File \"c:\\users\\adria\\miniconda3\\envs\\scraper\\lib\\site-packages\\aiohttp\\client.py\", line 1141, in __aenter__\n",
      "    self._resp = await self._coro\n",
      "  File \"c:\\users\\adria\\miniconda3\\envs\\scraper\\lib\\site-packages\\aiohttp\\client.py\", line 536, in _request\n",
      "    conn = await self._connector.connect(\n",
      "  File \"c:\\users\\adria\\miniconda3\\envs\\scraper\\lib\\site-packages\\aiohttp\\connector.py\", line 543, in connect\n",
      "    raise ClientConnectionError(\"Connector is closed.\")\n",
      "aiohttp.client_exceptions.ClientConnectionError: Connector is closed.\n",
      "Task exception was never retrieved\n",
      "future: <Task finished name='Task-31206' coro=<tqdm_asyncio.gather.<locals>.wrap_awaitable() done, defined at c:\\users\\adria\\miniconda3\\envs\\scraper\\lib\\site-packages\\tqdm\\asyncio.py:75> exception=ClientConnectionError('Connector is closed.')>\n",
      "Traceback (most recent call last):\n",
      "  File \"c:\\users\\adria\\miniconda3\\envs\\scraper\\lib\\site-packages\\tqdm\\asyncio.py\", line 76, in wrap_awaitable\n",
      "    return i, await f\n",
      "  File \"C:\\Users\\adria\\AppData\\Local\\Temp\\ipykernel_27608\\3299729886.py\", line 22, in checker\n",
      "    async with session.get(url, allow_redirects=True, ssl=False, raise_for_status=True, timeout=100, headers=headers) as r:\n",
      "  File \"c:\\users\\adria\\miniconda3\\envs\\scraper\\lib\\site-packages\\aiohttp\\client.py\", line 1141, in __aenter__\n",
      "    self._resp = await self._coro\n",
      "  File \"c:\\users\\adria\\miniconda3\\envs\\scraper\\lib\\site-packages\\aiohttp\\client.py\", line 536, in _request\n",
      "    conn = await self._connector.connect(\n",
      "  File \"c:\\users\\adria\\miniconda3\\envs\\scraper\\lib\\site-packages\\aiohttp\\connector.py\", line 543, in connect\n",
      "    raise ClientConnectionError(\"Connector is closed.\")\n",
      "aiohttp.client_exceptions.ClientConnectionError: Connector is closed.\n",
      "Task exception was never retrieved\n",
      "future: <Task finished name='Task-29454' coro=<tqdm_asyncio.gather.<locals>.wrap_awaitable() done, defined at c:\\users\\adria\\miniconda3\\envs\\scraper\\lib\\site-packages\\tqdm\\asyncio.py:75> exception=ClientConnectionError('Connector is closed.')>\n",
      "Traceback (most recent call last):\n",
      "  File \"c:\\users\\adria\\miniconda3\\envs\\scraper\\lib\\site-packages\\tqdm\\asyncio.py\", line 76, in wrap_awaitable\n",
      "    return i, await f\n",
      "  File \"C:\\Users\\adria\\AppData\\Local\\Temp\\ipykernel_27608\\3299729886.py\", line 22, in checker\n",
      "    async with session.get(url, allow_redirects=True, ssl=False, raise_for_status=True, timeout=100, headers=headers) as r:\n",
      "  File \"c:\\users\\adria\\miniconda3\\envs\\scraper\\lib\\site-packages\\aiohttp\\client.py\", line 1141, in __aenter__\n",
      "    self._resp = await self._coro\n",
      "  File \"c:\\users\\adria\\miniconda3\\envs\\scraper\\lib\\site-packages\\aiohttp\\client.py\", line 536, in _request\n",
      "    conn = await self._connector.connect(\n",
      "  File \"c:\\users\\adria\\miniconda3\\envs\\scraper\\lib\\site-packages\\aiohttp\\connector.py\", line 543, in connect\n",
      "    raise ClientConnectionError(\"Connector is closed.\")\n",
      "aiohttp.client_exceptions.ClientConnectionError: Connector is closed.\n",
      "Task exception was never retrieved\n",
      "future: <Task finished name='Task-27260' coro=<tqdm_asyncio.gather.<locals>.wrap_awaitable() done, defined at c:\\users\\adria\\miniconda3\\envs\\scraper\\lib\\site-packages\\tqdm\\asyncio.py:75> exception=ClientConnectionError('Connector is closed.')>\n",
      "Traceback (most recent call last):\n",
      "  File \"c:\\users\\adria\\miniconda3\\envs\\scraper\\lib\\site-packages\\tqdm\\asyncio.py\", line 76, in wrap_awaitable\n",
      "    return i, await f\n",
      "  File \"C:\\Users\\adria\\AppData\\Local\\Temp\\ipykernel_27608\\3299729886.py\", line 22, in checker\n",
      "    async with session.get(url, allow_redirects=True, ssl=False, raise_for_status=True, timeout=100, headers=headers) as r:\n",
      "  File \"c:\\users\\adria\\miniconda3\\envs\\scraper\\lib\\site-packages\\aiohttp\\client.py\", line 1141, in __aenter__\n",
      "    self._resp = await self._coro\n",
      "  File \"c:\\users\\adria\\miniconda3\\envs\\scraper\\lib\\site-packages\\aiohttp\\client.py\", line 536, in _request\n",
      "    conn = await self._connector.connect(\n",
      "  File \"c:\\users\\adria\\miniconda3\\envs\\scraper\\lib\\site-packages\\aiohttp\\connector.py\", line 543, in connect\n",
      "    raise ClientConnectionError(\"Connector is closed.\")\n",
      "aiohttp.client_exceptions.ClientConnectionError: Connector is closed.\n",
      "Task exception was never retrieved\n",
      "future: <Task finished name='Task-30835' coro=<tqdm_asyncio.gather.<locals>.wrap_awaitable() done, defined at c:\\users\\adria\\miniconda3\\envs\\scraper\\lib\\site-packages\\tqdm\\asyncio.py:75> exception=ClientConnectionError('Connector is closed.')>\n",
      "Traceback (most recent call last):\n",
      "  File \"c:\\users\\adria\\miniconda3\\envs\\scraper\\lib\\site-packages\\tqdm\\asyncio.py\", line 76, in wrap_awaitable\n",
      "    return i, await f\n",
      "  File \"C:\\Users\\adria\\AppData\\Local\\Temp\\ipykernel_27608\\3299729886.py\", line 22, in checker\n",
      "    async with session.get(url, allow_redirects=True, ssl=False, raise_for_status=True, timeout=100, headers=headers) as r:\n",
      "  File \"c:\\users\\adria\\miniconda3\\envs\\scraper\\lib\\site-packages\\aiohttp\\client.py\", line 1141, in __aenter__\n",
      "    self._resp = await self._coro\n",
      "  File \"c:\\users\\adria\\miniconda3\\envs\\scraper\\lib\\site-packages\\aiohttp\\client.py\", line 536, in _request\n",
      "    conn = await self._connector.connect(\n",
      "  File \"c:\\users\\adria\\miniconda3\\envs\\scraper\\lib\\site-packages\\aiohttp\\connector.py\", line 543, in connect\n",
      "    raise ClientConnectionError(\"Connector is closed.\")\n",
      "aiohttp.client_exceptions.ClientConnectionError: Connector is closed.\n",
      "Task exception was never retrieved\n",
      "future: <Task finished name='Task-29218' coro=<tqdm_asyncio.gather.<locals>.wrap_awaitable() done, defined at c:\\users\\adria\\miniconda3\\envs\\scraper\\lib\\site-packages\\tqdm\\asyncio.py:75> exception=ClientConnectionError('Connector is closed.')>\n",
      "Traceback (most recent call last):\n",
      "  File \"c:\\users\\adria\\miniconda3\\envs\\scraper\\lib\\site-packages\\tqdm\\asyncio.py\", line 76, in wrap_awaitable\n",
      "    return i, await f\n",
      "  File \"C:\\Users\\adria\\AppData\\Local\\Temp\\ipykernel_27608\\3299729886.py\", line 22, in checker\n",
      "    async with session.get(url, allow_redirects=True, ssl=False, raise_for_status=True, timeout=100, headers=headers) as r:\n",
      "  File \"c:\\users\\adria\\miniconda3\\envs\\scraper\\lib\\site-packages\\aiohttp\\client.py\", line 1141, in __aenter__\n",
      "    self._resp = await self._coro\n",
      "  File \"c:\\users\\adria\\miniconda3\\envs\\scraper\\lib\\site-packages\\aiohttp\\client.py\", line 536, in _request\n",
      "    conn = await self._connector.connect(\n",
      "  File \"c:\\users\\adria\\miniconda3\\envs\\scraper\\lib\\site-packages\\aiohttp\\connector.py\", line 543, in connect\n",
      "    raise ClientConnectionError(\"Connector is closed.\")\n",
      "aiohttp.client_exceptions.ClientConnectionError: Connector is closed.\n"
     ]
    },
    {
     "name": "stderr",
     "output_type": "stream",
     "text": [
      "Task exception was never retrieved\n",
      "future: <Task finished name='Task-31172' coro=<tqdm_asyncio.gather.<locals>.wrap_awaitable() done, defined at c:\\users\\adria\\miniconda3\\envs\\scraper\\lib\\site-packages\\tqdm\\asyncio.py:75> exception=ClientConnectionError('Connector is closed.')>\n",
      "Traceback (most recent call last):\n",
      "  File \"c:\\users\\adria\\miniconda3\\envs\\scraper\\lib\\site-packages\\tqdm\\asyncio.py\", line 76, in wrap_awaitable\n",
      "    return i, await f\n",
      "  File \"C:\\Users\\adria\\AppData\\Local\\Temp\\ipykernel_27608\\3299729886.py\", line 22, in checker\n",
      "    async with session.get(url, allow_redirects=True, ssl=False, raise_for_status=True, timeout=100, headers=headers) as r:\n",
      "  File \"c:\\users\\adria\\miniconda3\\envs\\scraper\\lib\\site-packages\\aiohttp\\client.py\", line 1141, in __aenter__\n",
      "    self._resp = await self._coro\n",
      "  File \"c:\\users\\adria\\miniconda3\\envs\\scraper\\lib\\site-packages\\aiohttp\\client.py\", line 536, in _request\n",
      "    conn = await self._connector.connect(\n",
      "  File \"c:\\users\\adria\\miniconda3\\envs\\scraper\\lib\\site-packages\\aiohttp\\connector.py\", line 543, in connect\n",
      "    raise ClientConnectionError(\"Connector is closed.\")\n",
      "aiohttp.client_exceptions.ClientConnectionError: Connector is closed.\n",
      "Task exception was never retrieved\n",
      "future: <Task finished name='Task-28515' coro=<tqdm_asyncio.gather.<locals>.wrap_awaitable() done, defined at c:\\users\\adria\\miniconda3\\envs\\scraper\\lib\\site-packages\\tqdm\\asyncio.py:75> exception=ClientConnectionError('Connector is closed.')>\n",
      "Traceback (most recent call last):\n",
      "  File \"c:\\users\\adria\\miniconda3\\envs\\scraper\\lib\\site-packages\\tqdm\\asyncio.py\", line 76, in wrap_awaitable\n",
      "    return i, await f\n",
      "  File \"C:\\Users\\adria\\AppData\\Local\\Temp\\ipykernel_27608\\3299729886.py\", line 22, in checker\n",
      "    async with session.get(url, allow_redirects=True, ssl=False, raise_for_status=True, timeout=100, headers=headers) as r:\n",
      "  File \"c:\\users\\adria\\miniconda3\\envs\\scraper\\lib\\site-packages\\aiohttp\\client.py\", line 1141, in __aenter__\n",
      "    self._resp = await self._coro\n",
      "  File \"c:\\users\\adria\\miniconda3\\envs\\scraper\\lib\\site-packages\\aiohttp\\client.py\", line 536, in _request\n",
      "    conn = await self._connector.connect(\n",
      "  File \"c:\\users\\adria\\miniconda3\\envs\\scraper\\lib\\site-packages\\aiohttp\\connector.py\", line 543, in connect\n",
      "    raise ClientConnectionError(\"Connector is closed.\")\n",
      "aiohttp.client_exceptions.ClientConnectionError: Connector is closed.\n",
      "Task exception was never retrieved\n",
      "future: <Task finished name='Task-30121' coro=<tqdm_asyncio.gather.<locals>.wrap_awaitable() done, defined at c:\\users\\adria\\miniconda3\\envs\\scraper\\lib\\site-packages\\tqdm\\asyncio.py:75> exception=ClientConnectionError('Connector is closed.')>\n",
      "Traceback (most recent call last):\n",
      "  File \"c:\\users\\adria\\miniconda3\\envs\\scraper\\lib\\site-packages\\tqdm\\asyncio.py\", line 76, in wrap_awaitable\n",
      "    return i, await f\n",
      "  File \"C:\\Users\\adria\\AppData\\Local\\Temp\\ipykernel_27608\\3299729886.py\", line 22, in checker\n",
      "    async with session.get(url, allow_redirects=True, ssl=False, raise_for_status=True, timeout=100, headers=headers) as r:\n",
      "  File \"c:\\users\\adria\\miniconda3\\envs\\scraper\\lib\\site-packages\\aiohttp\\client.py\", line 1141, in __aenter__\n",
      "    self._resp = await self._coro\n",
      "  File \"c:\\users\\adria\\miniconda3\\envs\\scraper\\lib\\site-packages\\aiohttp\\client.py\", line 536, in _request\n",
      "    conn = await self._connector.connect(\n",
      "  File \"c:\\users\\adria\\miniconda3\\envs\\scraper\\lib\\site-packages\\aiohttp\\connector.py\", line 543, in connect\n",
      "    raise ClientConnectionError(\"Connector is closed.\")\n",
      "aiohttp.client_exceptions.ClientConnectionError: Connector is closed.\n",
      "Task exception was never retrieved\n",
      "future: <Task finished name='Task-26568' coro=<tqdm_asyncio.gather.<locals>.wrap_awaitable() done, defined at c:\\users\\adria\\miniconda3\\envs\\scraper\\lib\\site-packages\\tqdm\\asyncio.py:75> exception=ClientConnectionError('Connector is closed.')>\n",
      "Traceback (most recent call last):\n",
      "  File \"c:\\users\\adria\\miniconda3\\envs\\scraper\\lib\\site-packages\\tqdm\\asyncio.py\", line 76, in wrap_awaitable\n",
      "    return i, await f\n",
      "  File \"C:\\Users\\adria\\AppData\\Local\\Temp\\ipykernel_27608\\3299729886.py\", line 22, in checker\n",
      "    async with session.get(url, allow_redirects=True, ssl=False, raise_for_status=True, timeout=100, headers=headers) as r:\n",
      "  File \"c:\\users\\adria\\miniconda3\\envs\\scraper\\lib\\site-packages\\aiohttp\\client.py\", line 1141, in __aenter__\n",
      "    self._resp = await self._coro\n",
      "  File \"c:\\users\\adria\\miniconda3\\envs\\scraper\\lib\\site-packages\\aiohttp\\client.py\", line 536, in _request\n",
      "    conn = await self._connector.connect(\n",
      "  File \"c:\\users\\adria\\miniconda3\\envs\\scraper\\lib\\site-packages\\aiohttp\\connector.py\", line 543, in connect\n",
      "    raise ClientConnectionError(\"Connector is closed.\")\n",
      "aiohttp.client_exceptions.ClientConnectionError: Connector is closed.\n",
      "Task exception was never retrieved\n",
      "future: <Task finished name='Task-30336' coro=<tqdm_asyncio.gather.<locals>.wrap_awaitable() done, defined at c:\\users\\adria\\miniconda3\\envs\\scraper\\lib\\site-packages\\tqdm\\asyncio.py:75> exception=ClientConnectionError('Connector is closed.')>\n",
      "Traceback (most recent call last):\n",
      "  File \"c:\\users\\adria\\miniconda3\\envs\\scraper\\lib\\site-packages\\tqdm\\asyncio.py\", line 76, in wrap_awaitable\n",
      "    return i, await f\n",
      "  File \"C:\\Users\\adria\\AppData\\Local\\Temp\\ipykernel_27608\\3299729886.py\", line 22, in checker\n",
      "    async with session.get(url, allow_redirects=True, ssl=False, raise_for_status=True, timeout=100, headers=headers) as r:\n",
      "  File \"c:\\users\\adria\\miniconda3\\envs\\scraper\\lib\\site-packages\\aiohttp\\client.py\", line 1141, in __aenter__\n",
      "    self._resp = await self._coro\n",
      "  File \"c:\\users\\adria\\miniconda3\\envs\\scraper\\lib\\site-packages\\aiohttp\\client.py\", line 536, in _request\n",
      "    conn = await self._connector.connect(\n",
      "  File \"c:\\users\\adria\\miniconda3\\envs\\scraper\\lib\\site-packages\\aiohttp\\connector.py\", line 543, in connect\n",
      "    raise ClientConnectionError(\"Connector is closed.\")\n",
      "aiohttp.client_exceptions.ClientConnectionError: Connector is closed.\n",
      "Task exception was never retrieved\n",
      "future: <Task finished name='Task-28969' coro=<tqdm_asyncio.gather.<locals>.wrap_awaitable() done, defined at c:\\users\\adria\\miniconda3\\envs\\scraper\\lib\\site-packages\\tqdm\\asyncio.py:75> exception=ClientConnectionError('Connector is closed.')>\n",
      "Traceback (most recent call last):\n",
      "  File \"c:\\users\\adria\\miniconda3\\envs\\scraper\\lib\\site-packages\\tqdm\\asyncio.py\", line 76, in wrap_awaitable\n",
      "    return i, await f\n",
      "  File \"C:\\Users\\adria\\AppData\\Local\\Temp\\ipykernel_27608\\3299729886.py\", line 22, in checker\n",
      "    async with session.get(url, allow_redirects=True, ssl=False, raise_for_status=True, timeout=100, headers=headers) as r:\n",
      "  File \"c:\\users\\adria\\miniconda3\\envs\\scraper\\lib\\site-packages\\aiohttp\\client.py\", line 1141, in __aenter__\n",
      "    self._resp = await self._coro\n",
      "  File \"c:\\users\\adria\\miniconda3\\envs\\scraper\\lib\\site-packages\\aiohttp\\client.py\", line 536, in _request\n",
      "    conn = await self._connector.connect(\n",
      "  File \"c:\\users\\adria\\miniconda3\\envs\\scraper\\lib\\site-packages\\aiohttp\\connector.py\", line 543, in connect\n",
      "    raise ClientConnectionError(\"Connector is closed.\")\n",
      "aiohttp.client_exceptions.ClientConnectionError: Connector is closed.\n",
      "Task exception was never retrieved\n",
      "future: <Task finished name='Task-30579' coro=<tqdm_asyncio.gather.<locals>.wrap_awaitable() done, defined at c:\\users\\adria\\miniconda3\\envs\\scraper\\lib\\site-packages\\tqdm\\asyncio.py:75> exception=ClientConnectionError('Connector is closed.')>\n",
      "Traceback (most recent call last):\n",
      "  File \"c:\\users\\adria\\miniconda3\\envs\\scraper\\lib\\site-packages\\tqdm\\asyncio.py\", line 76, in wrap_awaitable\n",
      "    return i, await f\n",
      "  File \"C:\\Users\\adria\\AppData\\Local\\Temp\\ipykernel_27608\\3299729886.py\", line 22, in checker\n",
      "    async with session.get(url, allow_redirects=True, ssl=False, raise_for_status=True, timeout=100, headers=headers) as r:\n",
      "  File \"c:\\users\\adria\\miniconda3\\envs\\scraper\\lib\\site-packages\\aiohttp\\client.py\", line 1141, in __aenter__\n",
      "    self._resp = await self._coro\n",
      "  File \"c:\\users\\adria\\miniconda3\\envs\\scraper\\lib\\site-packages\\aiohttp\\client.py\", line 536, in _request\n",
      "    conn = await self._connector.connect(\n",
      "  File \"c:\\users\\adria\\miniconda3\\envs\\scraper\\lib\\site-packages\\aiohttp\\connector.py\", line 543, in connect\n",
      "    raise ClientConnectionError(\"Connector is closed.\")\n",
      "aiohttp.client_exceptions.ClientConnectionError: Connector is closed.\n"
     ]
    },
    {
     "name": "stderr",
     "output_type": "stream",
     "text": [
      "Task exception was never retrieved\n",
      "future: <Task finished name='Task-28845' coro=<tqdm_asyncio.gather.<locals>.wrap_awaitable() done, defined at c:\\users\\adria\\miniconda3\\envs\\scraper\\lib\\site-packages\\tqdm\\asyncio.py:75> exception=ClientConnectionError('Connector is closed.')>\n",
      "Traceback (most recent call last):\n",
      "  File \"c:\\users\\adria\\miniconda3\\envs\\scraper\\lib\\site-packages\\tqdm\\asyncio.py\", line 76, in wrap_awaitable\n",
      "    return i, await f\n",
      "  File \"C:\\Users\\adria\\AppData\\Local\\Temp\\ipykernel_27608\\3299729886.py\", line 22, in checker\n",
      "    async with session.get(url, allow_redirects=True, ssl=False, raise_for_status=True, timeout=100, headers=headers) as r:\n",
      "  File \"c:\\users\\adria\\miniconda3\\envs\\scraper\\lib\\site-packages\\aiohttp\\client.py\", line 1141, in __aenter__\n",
      "    self._resp = await self._coro\n",
      "  File \"c:\\users\\adria\\miniconda3\\envs\\scraper\\lib\\site-packages\\aiohttp\\client.py\", line 536, in _request\n",
      "    conn = await self._connector.connect(\n",
      "  File \"c:\\users\\adria\\miniconda3\\envs\\scraper\\lib\\site-packages\\aiohttp\\connector.py\", line 543, in connect\n",
      "    raise ClientConnectionError(\"Connector is closed.\")\n",
      "aiohttp.client_exceptions.ClientConnectionError: Connector is closed.\n",
      "Task exception was never retrieved\n",
      "future: <Task finished name='Task-30150' coro=<tqdm_asyncio.gather.<locals>.wrap_awaitable() done, defined at c:\\users\\adria\\miniconda3\\envs\\scraper\\lib\\site-packages\\tqdm\\asyncio.py:75> exception=ClientConnectionError('Connector is closed.')>\n",
      "Traceback (most recent call last):\n",
      "  File \"c:\\users\\adria\\miniconda3\\envs\\scraper\\lib\\site-packages\\tqdm\\asyncio.py\", line 76, in wrap_awaitable\n",
      "    return i, await f\n",
      "  File \"C:\\Users\\adria\\AppData\\Local\\Temp\\ipykernel_27608\\3299729886.py\", line 22, in checker\n",
      "    async with session.get(url, allow_redirects=True, ssl=False, raise_for_status=True, timeout=100, headers=headers) as r:\n",
      "  File \"c:\\users\\adria\\miniconda3\\envs\\scraper\\lib\\site-packages\\aiohttp\\client.py\", line 1141, in __aenter__\n",
      "    self._resp = await self._coro\n",
      "  File \"c:\\users\\adria\\miniconda3\\envs\\scraper\\lib\\site-packages\\aiohttp\\client.py\", line 536, in _request\n",
      "    conn = await self._connector.connect(\n",
      "  File \"c:\\users\\adria\\miniconda3\\envs\\scraper\\lib\\site-packages\\aiohttp\\connector.py\", line 543, in connect\n",
      "    raise ClientConnectionError(\"Connector is closed.\")\n",
      "aiohttp.client_exceptions.ClientConnectionError: Connector is closed.\n",
      "Task exception was never retrieved\n",
      "future: <Task finished name='Task-31106' coro=<tqdm_asyncio.gather.<locals>.wrap_awaitable() done, defined at c:\\users\\adria\\miniconda3\\envs\\scraper\\lib\\site-packages\\tqdm\\asyncio.py:75> exception=ClientConnectionError('Connector is closed.')>\n",
      "Traceback (most recent call last):\n",
      "  File \"c:\\users\\adria\\miniconda3\\envs\\scraper\\lib\\site-packages\\tqdm\\asyncio.py\", line 76, in wrap_awaitable\n",
      "    return i, await f\n",
      "  File \"C:\\Users\\adria\\AppData\\Local\\Temp\\ipykernel_27608\\3299729886.py\", line 22, in checker\n",
      "    async with session.get(url, allow_redirects=True, ssl=False, raise_for_status=True, timeout=100, headers=headers) as r:\n",
      "  File \"c:\\users\\adria\\miniconda3\\envs\\scraper\\lib\\site-packages\\aiohttp\\client.py\", line 1141, in __aenter__\n",
      "    self._resp = await self._coro\n",
      "  File \"c:\\users\\adria\\miniconda3\\envs\\scraper\\lib\\site-packages\\aiohttp\\client.py\", line 536, in _request\n",
      "    conn = await self._connector.connect(\n",
      "  File \"c:\\users\\adria\\miniconda3\\envs\\scraper\\lib\\site-packages\\aiohttp\\connector.py\", line 543, in connect\n",
      "    raise ClientConnectionError(\"Connector is closed.\")\n",
      "aiohttp.client_exceptions.ClientConnectionError: Connector is closed.\n",
      "Task exception was never retrieved\n",
      "future: <Task finished name='Task-26629' coro=<tqdm_asyncio.gather.<locals>.wrap_awaitable() done, defined at c:\\users\\adria\\miniconda3\\envs\\scraper\\lib\\site-packages\\tqdm\\asyncio.py:75> exception=ClientConnectionError('Connector is closed.')>\n",
      "Traceback (most recent call last):\n",
      "  File \"c:\\users\\adria\\miniconda3\\envs\\scraper\\lib\\site-packages\\tqdm\\asyncio.py\", line 76, in wrap_awaitable\n",
      "    return i, await f\n",
      "  File \"C:\\Users\\adria\\AppData\\Local\\Temp\\ipykernel_27608\\3299729886.py\", line 22, in checker\n",
      "    async with session.get(url, allow_redirects=True, ssl=False, raise_for_status=True, timeout=100, headers=headers) as r:\n",
      "  File \"c:\\users\\adria\\miniconda3\\envs\\scraper\\lib\\site-packages\\aiohttp\\client.py\", line 1141, in __aenter__\n",
      "    self._resp = await self._coro\n",
      "  File \"c:\\users\\adria\\miniconda3\\envs\\scraper\\lib\\site-packages\\aiohttp\\client.py\", line 536, in _request\n",
      "    conn = await self._connector.connect(\n",
      "  File \"c:\\users\\adria\\miniconda3\\envs\\scraper\\lib\\site-packages\\aiohttp\\connector.py\", line 543, in connect\n",
      "    raise ClientConnectionError(\"Connector is closed.\")\n",
      "aiohttp.client_exceptions.ClientConnectionError: Connector is closed.\n",
      "Task exception was never retrieved\n",
      "future: <Task finished name='Task-28497' coro=<tqdm_asyncio.gather.<locals>.wrap_awaitable() done, defined at c:\\users\\adria\\miniconda3\\envs\\scraper\\lib\\site-packages\\tqdm\\asyncio.py:75> exception=ClientConnectionError('Connector is closed.')>\n",
      "Traceback (most recent call last):\n",
      "  File \"c:\\users\\adria\\miniconda3\\envs\\scraper\\lib\\site-packages\\tqdm\\asyncio.py\", line 76, in wrap_awaitable\n",
      "    return i, await f\n",
      "  File \"C:\\Users\\adria\\AppData\\Local\\Temp\\ipykernel_27608\\3299729886.py\", line 22, in checker\n",
      "    async with session.get(url, allow_redirects=True, ssl=False, raise_for_status=True, timeout=100, headers=headers) as r:\n",
      "  File \"c:\\users\\adria\\miniconda3\\envs\\scraper\\lib\\site-packages\\aiohttp\\client.py\", line 1141, in __aenter__\n",
      "    self._resp = await self._coro\n",
      "  File \"c:\\users\\adria\\miniconda3\\envs\\scraper\\lib\\site-packages\\aiohttp\\client.py\", line 536, in _request\n",
      "    conn = await self._connector.connect(\n",
      "  File \"c:\\users\\adria\\miniconda3\\envs\\scraper\\lib\\site-packages\\aiohttp\\connector.py\", line 543, in connect\n",
      "    raise ClientConnectionError(\"Connector is closed.\")\n",
      "aiohttp.client_exceptions.ClientConnectionError: Connector is closed.\n",
      "Task exception was never retrieved\n",
      "future: <Task finished name='Task-26870' coro=<tqdm_asyncio.gather.<locals>.wrap_awaitable() done, defined at c:\\users\\adria\\miniconda3\\envs\\scraper\\lib\\site-packages\\tqdm\\asyncio.py:75> exception=ClientConnectionError('Connector is closed.')>\n",
      "Traceback (most recent call last):\n",
      "  File \"c:\\users\\adria\\miniconda3\\envs\\scraper\\lib\\site-packages\\tqdm\\asyncio.py\", line 76, in wrap_awaitable\n",
      "    return i, await f\n",
      "  File \"C:\\Users\\adria\\AppData\\Local\\Temp\\ipykernel_27608\\3299729886.py\", line 22, in checker\n",
      "    async with session.get(url, allow_redirects=True, ssl=False, raise_for_status=True, timeout=100, headers=headers) as r:\n",
      "  File \"c:\\users\\adria\\miniconda3\\envs\\scraper\\lib\\site-packages\\aiohttp\\client.py\", line 1141, in __aenter__\n",
      "    self._resp = await self._coro\n",
      "  File \"c:\\users\\adria\\miniconda3\\envs\\scraper\\lib\\site-packages\\aiohttp\\client.py\", line 536, in _request\n",
      "    conn = await self._connector.connect(\n",
      "  File \"c:\\users\\adria\\miniconda3\\envs\\scraper\\lib\\site-packages\\aiohttp\\connector.py\", line 543, in connect\n",
      "    raise ClientConnectionError(\"Connector is closed.\")\n",
      "aiohttp.client_exceptions.ClientConnectionError: Connector is closed.\n",
      "Task exception was never retrieved\n",
      "future: <Task finished name='Task-29219' coro=<tqdm_asyncio.gather.<locals>.wrap_awaitable() done, defined at c:\\users\\adria\\miniconda3\\envs\\scraper\\lib\\site-packages\\tqdm\\asyncio.py:75> exception=ClientConnectionError('Connector is closed.')>\n",
      "Traceback (most recent call last):\n",
      "  File \"c:\\users\\adria\\miniconda3\\envs\\scraper\\lib\\site-packages\\tqdm\\asyncio.py\", line 76, in wrap_awaitable\n",
      "    return i, await f\n",
      "  File \"C:\\Users\\adria\\AppData\\Local\\Temp\\ipykernel_27608\\3299729886.py\", line 22, in checker\n",
      "    async with session.get(url, allow_redirects=True, ssl=False, raise_for_status=True, timeout=100, headers=headers) as r:\n",
      "  File \"c:\\users\\adria\\miniconda3\\envs\\scraper\\lib\\site-packages\\aiohttp\\client.py\", line 1141, in __aenter__\n",
      "    self._resp = await self._coro\n",
      "  File \"c:\\users\\adria\\miniconda3\\envs\\scraper\\lib\\site-packages\\aiohttp\\client.py\", line 536, in _request\n",
      "    conn = await self._connector.connect(\n",
      "  File \"c:\\users\\adria\\miniconda3\\envs\\scraper\\lib\\site-packages\\aiohttp\\connector.py\", line 543, in connect\n",
      "    raise ClientConnectionError(\"Connector is closed.\")\n",
      "aiohttp.client_exceptions.ClientConnectionError: Connector is closed.\n"
     ]
    },
    {
     "name": "stderr",
     "output_type": "stream",
     "text": [
      "Task exception was never retrieved\n",
      "future: <Task finished name='Task-26953' coro=<tqdm_asyncio.gather.<locals>.wrap_awaitable() done, defined at c:\\users\\adria\\miniconda3\\envs\\scraper\\lib\\site-packages\\tqdm\\asyncio.py:75> exception=ClientConnectionError('Connector is closed.')>\n",
      "Traceback (most recent call last):\n",
      "  File \"c:\\users\\adria\\miniconda3\\envs\\scraper\\lib\\site-packages\\tqdm\\asyncio.py\", line 76, in wrap_awaitable\n",
      "    return i, await f\n",
      "  File \"C:\\Users\\adria\\AppData\\Local\\Temp\\ipykernel_27608\\3299729886.py\", line 22, in checker\n",
      "    async with session.get(url, allow_redirects=True, ssl=False, raise_for_status=True, timeout=100, headers=headers) as r:\n",
      "  File \"c:\\users\\adria\\miniconda3\\envs\\scraper\\lib\\site-packages\\aiohttp\\client.py\", line 1141, in __aenter__\n",
      "    self._resp = await self._coro\n",
      "  File \"c:\\users\\adria\\miniconda3\\envs\\scraper\\lib\\site-packages\\aiohttp\\client.py\", line 536, in _request\n",
      "    conn = await self._connector.connect(\n",
      "  File \"c:\\users\\adria\\miniconda3\\envs\\scraper\\lib\\site-packages\\aiohttp\\connector.py\", line 543, in connect\n",
      "    raise ClientConnectionError(\"Connector is closed.\")\n",
      "aiohttp.client_exceptions.ClientConnectionError: Connector is closed.\n",
      "Task exception was never retrieved\n",
      "future: <Task finished name='Task-26835' coro=<tqdm_asyncio.gather.<locals>.wrap_awaitable() done, defined at c:\\users\\adria\\miniconda3\\envs\\scraper\\lib\\site-packages\\tqdm\\asyncio.py:75> exception=ClientConnectionError('Connector is closed.')>\n",
      "Traceback (most recent call last):\n",
      "  File \"c:\\users\\adria\\miniconda3\\envs\\scraper\\lib\\site-packages\\tqdm\\asyncio.py\", line 76, in wrap_awaitable\n",
      "    return i, await f\n",
      "  File \"C:\\Users\\adria\\AppData\\Local\\Temp\\ipykernel_27608\\3299729886.py\", line 22, in checker\n",
      "    async with session.get(url, allow_redirects=True, ssl=False, raise_for_status=True, timeout=100, headers=headers) as r:\n",
      "  File \"c:\\users\\adria\\miniconda3\\envs\\scraper\\lib\\site-packages\\aiohttp\\client.py\", line 1141, in __aenter__\n",
      "    self._resp = await self._coro\n",
      "  File \"c:\\users\\adria\\miniconda3\\envs\\scraper\\lib\\site-packages\\aiohttp\\client.py\", line 536, in _request\n",
      "    conn = await self._connector.connect(\n",
      "  File \"c:\\users\\adria\\miniconda3\\envs\\scraper\\lib\\site-packages\\aiohttp\\connector.py\", line 543, in connect\n",
      "    raise ClientConnectionError(\"Connector is closed.\")\n",
      "aiohttp.client_exceptions.ClientConnectionError: Connector is closed.\n",
      "Task exception was never retrieved\n",
      "future: <Task finished name='Task-28369' coro=<tqdm_asyncio.gather.<locals>.wrap_awaitable() done, defined at c:\\users\\adria\\miniconda3\\envs\\scraper\\lib\\site-packages\\tqdm\\asyncio.py:75> exception=ClientConnectionError('Connector is closed.')>\n",
      "Traceback (most recent call last):\n",
      "  File \"c:\\users\\adria\\miniconda3\\envs\\scraper\\lib\\site-packages\\tqdm\\asyncio.py\", line 76, in wrap_awaitable\n",
      "    return i, await f\n",
      "  File \"C:\\Users\\adria\\AppData\\Local\\Temp\\ipykernel_27608\\3299729886.py\", line 22, in checker\n",
      "    async with session.get(url, allow_redirects=True, ssl=False, raise_for_status=True, timeout=100, headers=headers) as r:\n",
      "  File \"c:\\users\\adria\\miniconda3\\envs\\scraper\\lib\\site-packages\\aiohttp\\client.py\", line 1141, in __aenter__\n",
      "    self._resp = await self._coro\n",
      "  File \"c:\\users\\adria\\miniconda3\\envs\\scraper\\lib\\site-packages\\aiohttp\\client.py\", line 536, in _request\n",
      "    conn = await self._connector.connect(\n",
      "  File \"c:\\users\\adria\\miniconda3\\envs\\scraper\\lib\\site-packages\\aiohttp\\connector.py\", line 543, in connect\n",
      "    raise ClientConnectionError(\"Connector is closed.\")\n",
      "aiohttp.client_exceptions.ClientConnectionError: Connector is closed.\n",
      "Task exception was never retrieved\n",
      "future: <Task finished name='Task-30594' coro=<tqdm_asyncio.gather.<locals>.wrap_awaitable() done, defined at c:\\users\\adria\\miniconda3\\envs\\scraper\\lib\\site-packages\\tqdm\\asyncio.py:75> exception=ClientConnectionError('Connector is closed.')>\n",
      "Traceback (most recent call last):\n",
      "  File \"c:\\users\\adria\\miniconda3\\envs\\scraper\\lib\\site-packages\\tqdm\\asyncio.py\", line 76, in wrap_awaitable\n",
      "    return i, await f\n",
      "  File \"C:\\Users\\adria\\AppData\\Local\\Temp\\ipykernel_27608\\3299729886.py\", line 22, in checker\n",
      "    async with session.get(url, allow_redirects=True, ssl=False, raise_for_status=True, timeout=100, headers=headers) as r:\n",
      "  File \"c:\\users\\adria\\miniconda3\\envs\\scraper\\lib\\site-packages\\aiohttp\\client.py\", line 1141, in __aenter__\n",
      "    self._resp = await self._coro\n",
      "  File \"c:\\users\\adria\\miniconda3\\envs\\scraper\\lib\\site-packages\\aiohttp\\client.py\", line 536, in _request\n",
      "    conn = await self._connector.connect(\n",
      "  File \"c:\\users\\adria\\miniconda3\\envs\\scraper\\lib\\site-packages\\aiohttp\\connector.py\", line 543, in connect\n",
      "    raise ClientConnectionError(\"Connector is closed.\")\n",
      "aiohttp.client_exceptions.ClientConnectionError: Connector is closed.\n",
      "Task exception was never retrieved\n",
      "future: <Task finished name='Task-29683' coro=<tqdm_asyncio.gather.<locals>.wrap_awaitable() done, defined at c:\\users\\adria\\miniconda3\\envs\\scraper\\lib\\site-packages\\tqdm\\asyncio.py:75> exception=ClientConnectionError('Connector is closed.')>\n",
      "Traceback (most recent call last):\n",
      "  File \"c:\\users\\adria\\miniconda3\\envs\\scraper\\lib\\site-packages\\tqdm\\asyncio.py\", line 76, in wrap_awaitable\n",
      "    return i, await f\n",
      "  File \"C:\\Users\\adria\\AppData\\Local\\Temp\\ipykernel_27608\\3299729886.py\", line 22, in checker\n",
      "    async with session.get(url, allow_redirects=True, ssl=False, raise_for_status=True, timeout=100, headers=headers) as r:\n",
      "  File \"c:\\users\\adria\\miniconda3\\envs\\scraper\\lib\\site-packages\\aiohttp\\client.py\", line 1141, in __aenter__\n",
      "    self._resp = await self._coro\n",
      "  File \"c:\\users\\adria\\miniconda3\\envs\\scraper\\lib\\site-packages\\aiohttp\\client.py\", line 536, in _request\n",
      "    conn = await self._connector.connect(\n",
      "  File \"c:\\users\\adria\\miniconda3\\envs\\scraper\\lib\\site-packages\\aiohttp\\connector.py\", line 543, in connect\n",
      "    raise ClientConnectionError(\"Connector is closed.\")\n",
      "aiohttp.client_exceptions.ClientConnectionError: Connector is closed.\n",
      "Task exception was never retrieved\n",
      "future: <Task finished name='Task-26542' coro=<tqdm_asyncio.gather.<locals>.wrap_awaitable() done, defined at c:\\users\\adria\\miniconda3\\envs\\scraper\\lib\\site-packages\\tqdm\\asyncio.py:75> exception=ClientConnectionError('Connector is closed.')>\n",
      "Traceback (most recent call last):\n",
      "  File \"c:\\users\\adria\\miniconda3\\envs\\scraper\\lib\\site-packages\\tqdm\\asyncio.py\", line 76, in wrap_awaitable\n",
      "    return i, await f\n",
      "  File \"C:\\Users\\adria\\AppData\\Local\\Temp\\ipykernel_27608\\3299729886.py\", line 22, in checker\n",
      "    async with session.get(url, allow_redirects=True, ssl=False, raise_for_status=True, timeout=100, headers=headers) as r:\n",
      "  File \"c:\\users\\adria\\miniconda3\\envs\\scraper\\lib\\site-packages\\aiohttp\\client.py\", line 1141, in __aenter__\n",
      "    self._resp = await self._coro\n",
      "  File \"c:\\users\\adria\\miniconda3\\envs\\scraper\\lib\\site-packages\\aiohttp\\client.py\", line 536, in _request\n",
      "    conn = await self._connector.connect(\n",
      "  File \"c:\\users\\adria\\miniconda3\\envs\\scraper\\lib\\site-packages\\aiohttp\\connector.py\", line 543, in connect\n",
      "    raise ClientConnectionError(\"Connector is closed.\")\n",
      "aiohttp.client_exceptions.ClientConnectionError: Connector is closed.\n",
      "Task exception was never retrieved\n",
      "future: <Task finished name='Task-27473' coro=<tqdm_asyncio.gather.<locals>.wrap_awaitable() done, defined at c:\\users\\adria\\miniconda3\\envs\\scraper\\lib\\site-packages\\tqdm\\asyncio.py:75> exception=ClientConnectionError('Connector is closed.')>\n",
      "Traceback (most recent call last):\n",
      "  File \"c:\\users\\adria\\miniconda3\\envs\\scraper\\lib\\site-packages\\tqdm\\asyncio.py\", line 76, in wrap_awaitable\n",
      "    return i, await f\n",
      "  File \"C:\\Users\\adria\\AppData\\Local\\Temp\\ipykernel_27608\\3299729886.py\", line 22, in checker\n",
      "    async with session.get(url, allow_redirects=True, ssl=False, raise_for_status=True, timeout=100, headers=headers) as r:\n",
      "  File \"c:\\users\\adria\\miniconda3\\envs\\scraper\\lib\\site-packages\\aiohttp\\client.py\", line 1141, in __aenter__\n",
      "    self._resp = await self._coro\n",
      "  File \"c:\\users\\adria\\miniconda3\\envs\\scraper\\lib\\site-packages\\aiohttp\\client.py\", line 536, in _request\n",
      "    conn = await self._connector.connect(\n",
      "  File \"c:\\users\\adria\\miniconda3\\envs\\scraper\\lib\\site-packages\\aiohttp\\connector.py\", line 543, in connect\n",
      "    raise ClientConnectionError(\"Connector is closed.\")\n",
      "aiohttp.client_exceptions.ClientConnectionError: Connector is closed.\n"
     ]
    },
    {
     "name": "stderr",
     "output_type": "stream",
     "text": [
      "Task exception was never retrieved\n",
      "future: <Task finished name='Task-30244' coro=<tqdm_asyncio.gather.<locals>.wrap_awaitable() done, defined at c:\\users\\adria\\miniconda3\\envs\\scraper\\lib\\site-packages\\tqdm\\asyncio.py:75> exception=ClientConnectionError('Connector is closed.')>\n",
      "Traceback (most recent call last):\n",
      "  File \"c:\\users\\adria\\miniconda3\\envs\\scraper\\lib\\site-packages\\tqdm\\asyncio.py\", line 76, in wrap_awaitable\n",
      "    return i, await f\n",
      "  File \"C:\\Users\\adria\\AppData\\Local\\Temp\\ipykernel_27608\\3299729886.py\", line 22, in checker\n",
      "    async with session.get(url, allow_redirects=True, ssl=False, raise_for_status=True, timeout=100, headers=headers) as r:\n",
      "  File \"c:\\users\\adria\\miniconda3\\envs\\scraper\\lib\\site-packages\\aiohttp\\client.py\", line 1141, in __aenter__\n",
      "    self._resp = await self._coro\n",
      "  File \"c:\\users\\adria\\miniconda3\\envs\\scraper\\lib\\site-packages\\aiohttp\\client.py\", line 536, in _request\n",
      "    conn = await self._connector.connect(\n",
      "  File \"c:\\users\\adria\\miniconda3\\envs\\scraper\\lib\\site-packages\\aiohttp\\connector.py\", line 543, in connect\n",
      "    raise ClientConnectionError(\"Connector is closed.\")\n",
      "aiohttp.client_exceptions.ClientConnectionError: Connector is closed.\n",
      "Task exception was never retrieved\n",
      "future: <Task finished name='Task-29702' coro=<tqdm_asyncio.gather.<locals>.wrap_awaitable() done, defined at c:\\users\\adria\\miniconda3\\envs\\scraper\\lib\\site-packages\\tqdm\\asyncio.py:75> exception=ClientConnectionError('Connector is closed.')>\n",
      "Traceback (most recent call last):\n",
      "  File \"c:\\users\\adria\\miniconda3\\envs\\scraper\\lib\\site-packages\\tqdm\\asyncio.py\", line 76, in wrap_awaitable\n",
      "    return i, await f\n",
      "  File \"C:\\Users\\adria\\AppData\\Local\\Temp\\ipykernel_27608\\3299729886.py\", line 22, in checker\n",
      "    async with session.get(url, allow_redirects=True, ssl=False, raise_for_status=True, timeout=100, headers=headers) as r:\n",
      "  File \"c:\\users\\adria\\miniconda3\\envs\\scraper\\lib\\site-packages\\aiohttp\\client.py\", line 1141, in __aenter__\n",
      "    self._resp = await self._coro\n",
      "  File \"c:\\users\\adria\\miniconda3\\envs\\scraper\\lib\\site-packages\\aiohttp\\client.py\", line 536, in _request\n",
      "    conn = await self._connector.connect(\n",
      "  File \"c:\\users\\adria\\miniconda3\\envs\\scraper\\lib\\site-packages\\aiohttp\\connector.py\", line 543, in connect\n",
      "    raise ClientConnectionError(\"Connector is closed.\")\n",
      "aiohttp.client_exceptions.ClientConnectionError: Connector is closed.\n",
      "Task exception was never retrieved\n",
      "future: <Task finished name='Task-30805' coro=<tqdm_asyncio.gather.<locals>.wrap_awaitable() done, defined at c:\\users\\adria\\miniconda3\\envs\\scraper\\lib\\site-packages\\tqdm\\asyncio.py:75> exception=ClientConnectionError('Connector is closed.')>\n",
      "Traceback (most recent call last):\n",
      "  File \"c:\\users\\adria\\miniconda3\\envs\\scraper\\lib\\site-packages\\tqdm\\asyncio.py\", line 76, in wrap_awaitable\n",
      "    return i, await f\n",
      "  File \"C:\\Users\\adria\\AppData\\Local\\Temp\\ipykernel_27608\\3299729886.py\", line 22, in checker\n",
      "    async with session.get(url, allow_redirects=True, ssl=False, raise_for_status=True, timeout=100, headers=headers) as r:\n",
      "  File \"c:\\users\\adria\\miniconda3\\envs\\scraper\\lib\\site-packages\\aiohttp\\client.py\", line 1141, in __aenter__\n",
      "    self._resp = await self._coro\n",
      "  File \"c:\\users\\adria\\miniconda3\\envs\\scraper\\lib\\site-packages\\aiohttp\\client.py\", line 536, in _request\n",
      "    conn = await self._connector.connect(\n",
      "  File \"c:\\users\\adria\\miniconda3\\envs\\scraper\\lib\\site-packages\\aiohttp\\connector.py\", line 543, in connect\n",
      "    raise ClientConnectionError(\"Connector is closed.\")\n",
      "aiohttp.client_exceptions.ClientConnectionError: Connector is closed.\n",
      "Task exception was never retrieved\n",
      "future: <Task finished name='Task-30817' coro=<tqdm_asyncio.gather.<locals>.wrap_awaitable() done, defined at c:\\users\\adria\\miniconda3\\envs\\scraper\\lib\\site-packages\\tqdm\\asyncio.py:75> exception=ClientConnectionError('Connector is closed.')>\n",
      "Traceback (most recent call last):\n",
      "  File \"c:\\users\\adria\\miniconda3\\envs\\scraper\\lib\\site-packages\\tqdm\\asyncio.py\", line 76, in wrap_awaitable\n",
      "    return i, await f\n",
      "  File \"C:\\Users\\adria\\AppData\\Local\\Temp\\ipykernel_27608\\3299729886.py\", line 22, in checker\n",
      "    async with session.get(url, allow_redirects=True, ssl=False, raise_for_status=True, timeout=100, headers=headers) as r:\n",
      "  File \"c:\\users\\adria\\miniconda3\\envs\\scraper\\lib\\site-packages\\aiohttp\\client.py\", line 1141, in __aenter__\n",
      "    self._resp = await self._coro\n",
      "  File \"c:\\users\\adria\\miniconda3\\envs\\scraper\\lib\\site-packages\\aiohttp\\client.py\", line 536, in _request\n",
      "    conn = await self._connector.connect(\n",
      "  File \"c:\\users\\adria\\miniconda3\\envs\\scraper\\lib\\site-packages\\aiohttp\\connector.py\", line 543, in connect\n",
      "    raise ClientConnectionError(\"Connector is closed.\")\n",
      "aiohttp.client_exceptions.ClientConnectionError: Connector is closed.\n",
      "Task exception was never retrieved\n",
      "future: <Task finished name='Task-31287' coro=<tqdm_asyncio.gather.<locals>.wrap_awaitable() done, defined at c:\\users\\adria\\miniconda3\\envs\\scraper\\lib\\site-packages\\tqdm\\asyncio.py:75> exception=ClientConnectionError('Connector is closed.')>\n",
      "Traceback (most recent call last):\n",
      "  File \"c:\\users\\adria\\miniconda3\\envs\\scraper\\lib\\site-packages\\tqdm\\asyncio.py\", line 76, in wrap_awaitable\n",
      "    return i, await f\n",
      "  File \"C:\\Users\\adria\\AppData\\Local\\Temp\\ipykernel_27608\\3299729886.py\", line 22, in checker\n",
      "    async with session.get(url, allow_redirects=True, ssl=False, raise_for_status=True, timeout=100, headers=headers) as r:\n",
      "  File \"c:\\users\\adria\\miniconda3\\envs\\scraper\\lib\\site-packages\\aiohttp\\client.py\", line 1141, in __aenter__\n",
      "    self._resp = await self._coro\n",
      "  File \"c:\\users\\adria\\miniconda3\\envs\\scraper\\lib\\site-packages\\aiohttp\\client.py\", line 536, in _request\n",
      "    conn = await self._connector.connect(\n",
      "  File \"c:\\users\\adria\\miniconda3\\envs\\scraper\\lib\\site-packages\\aiohttp\\connector.py\", line 543, in connect\n",
      "    raise ClientConnectionError(\"Connector is closed.\")\n",
      "aiohttp.client_exceptions.ClientConnectionError: Connector is closed.\n",
      "Task exception was never retrieved\n",
      "future: <Task finished name='Task-26972' coro=<tqdm_asyncio.gather.<locals>.wrap_awaitable() done, defined at c:\\users\\adria\\miniconda3\\envs\\scraper\\lib\\site-packages\\tqdm\\asyncio.py:75> exception=ClientConnectionError('Connector is closed.')>\n",
      "Traceback (most recent call last):\n",
      "  File \"c:\\users\\adria\\miniconda3\\envs\\scraper\\lib\\site-packages\\tqdm\\asyncio.py\", line 76, in wrap_awaitable\n",
      "    return i, await f\n",
      "  File \"C:\\Users\\adria\\AppData\\Local\\Temp\\ipykernel_27608\\3299729886.py\", line 22, in checker\n",
      "    async with session.get(url, allow_redirects=True, ssl=False, raise_for_status=True, timeout=100, headers=headers) as r:\n",
      "  File \"c:\\users\\adria\\miniconda3\\envs\\scraper\\lib\\site-packages\\aiohttp\\client.py\", line 1141, in __aenter__\n",
      "    self._resp = await self._coro\n",
      "  File \"c:\\users\\adria\\miniconda3\\envs\\scraper\\lib\\site-packages\\aiohttp\\client.py\", line 536, in _request\n",
      "    conn = await self._connector.connect(\n",
      "  File \"c:\\users\\adria\\miniconda3\\envs\\scraper\\lib\\site-packages\\aiohttp\\connector.py\", line 543, in connect\n",
      "    raise ClientConnectionError(\"Connector is closed.\")\n",
      "aiohttp.client_exceptions.ClientConnectionError: Connector is closed.\n",
      "Task exception was never retrieved\n",
      "future: <Task finished name='Task-29732' coro=<tqdm_asyncio.gather.<locals>.wrap_awaitable() done, defined at c:\\users\\adria\\miniconda3\\envs\\scraper\\lib\\site-packages\\tqdm\\asyncio.py:75> exception=ClientConnectionError('Connector is closed.')>\n",
      "Traceback (most recent call last):\n",
      "  File \"c:\\users\\adria\\miniconda3\\envs\\scraper\\lib\\site-packages\\tqdm\\asyncio.py\", line 76, in wrap_awaitable\n",
      "    return i, await f\n",
      "  File \"C:\\Users\\adria\\AppData\\Local\\Temp\\ipykernel_27608\\3299729886.py\", line 22, in checker\n",
      "    async with session.get(url, allow_redirects=True, ssl=False, raise_for_status=True, timeout=100, headers=headers) as r:\n",
      "  File \"c:\\users\\adria\\miniconda3\\envs\\scraper\\lib\\site-packages\\aiohttp\\client.py\", line 1141, in __aenter__\n",
      "    self._resp = await self._coro\n",
      "  File \"c:\\users\\adria\\miniconda3\\envs\\scraper\\lib\\site-packages\\aiohttp\\client.py\", line 536, in _request\n",
      "    conn = await self._connector.connect(\n",
      "  File \"c:\\users\\adria\\miniconda3\\envs\\scraper\\lib\\site-packages\\aiohttp\\connector.py\", line 543, in connect\n",
      "    raise ClientConnectionError(\"Connector is closed.\")\n",
      "aiohttp.client_exceptions.ClientConnectionError: Connector is closed.\n"
     ]
    },
    {
     "name": "stderr",
     "output_type": "stream",
     "text": [
      "Task exception was never retrieved\n",
      "future: <Task finished name='Task-27361' coro=<tqdm_asyncio.gather.<locals>.wrap_awaitable() done, defined at c:\\users\\adria\\miniconda3\\envs\\scraper\\lib\\site-packages\\tqdm\\asyncio.py:75> exception=ClientConnectionError('Connector is closed.')>\n",
      "Traceback (most recent call last):\n",
      "  File \"c:\\users\\adria\\miniconda3\\envs\\scraper\\lib\\site-packages\\tqdm\\asyncio.py\", line 76, in wrap_awaitable\n",
      "    return i, await f\n",
      "  File \"C:\\Users\\adria\\AppData\\Local\\Temp\\ipykernel_27608\\3299729886.py\", line 22, in checker\n",
      "    async with session.get(url, allow_redirects=True, ssl=False, raise_for_status=True, timeout=100, headers=headers) as r:\n",
      "  File \"c:\\users\\adria\\miniconda3\\envs\\scraper\\lib\\site-packages\\aiohttp\\client.py\", line 1141, in __aenter__\n",
      "    self._resp = await self._coro\n",
      "  File \"c:\\users\\adria\\miniconda3\\envs\\scraper\\lib\\site-packages\\aiohttp\\client.py\", line 536, in _request\n",
      "    conn = await self._connector.connect(\n",
      "  File \"c:\\users\\adria\\miniconda3\\envs\\scraper\\lib\\site-packages\\aiohttp\\connector.py\", line 543, in connect\n",
      "    raise ClientConnectionError(\"Connector is closed.\")\n",
      "aiohttp.client_exceptions.ClientConnectionError: Connector is closed.\n",
      "Task exception was never retrieved\n",
      "future: <Task finished name='Task-26484' coro=<tqdm_asyncio.gather.<locals>.wrap_awaitable() done, defined at c:\\users\\adria\\miniconda3\\envs\\scraper\\lib\\site-packages\\tqdm\\asyncio.py:75> exception=ClientOSError(1, '[SSL: APPLICATION_DATA_AFTER_CLOSE_NOTIFY] application data after close notify (_ssl.c:2747)')>\n",
      "Traceback (most recent call last):\n",
      "  File \"c:\\users\\adria\\miniconda3\\envs\\scraper\\lib\\site-packages\\tqdm\\asyncio.py\", line 76, in wrap_awaitable\n",
      "    return i, await f\n",
      "  File \"C:\\Users\\adria\\AppData\\Local\\Temp\\ipykernel_27608\\3299729886.py\", line 22, in checker\n",
      "    async with session.get(url, allow_redirects=True, ssl=False, raise_for_status=True, timeout=100, headers=headers) as r:\n",
      "  File \"c:\\users\\adria\\miniconda3\\envs\\scraper\\lib\\site-packages\\aiohttp\\client.py\", line 1141, in __aenter__\n",
      "    self._resp = await self._coro\n",
      "  File \"c:\\users\\adria\\miniconda3\\envs\\scraper\\lib\\site-packages\\aiohttp\\client.py\", line 560, in _request\n",
      "    await resp.start(conn)\n",
      "  File \"c:\\users\\adria\\miniconda3\\envs\\scraper\\lib\\site-packages\\aiohttp\\client_reqrep.py\", line 899, in start\n",
      "    message, payload = await protocol.read()  # type: ignore[union-attr]\n",
      "  File \"c:\\users\\adria\\miniconda3\\envs\\scraper\\lib\\site-packages\\aiohttp\\streams.py\", line 616, in read\n",
      "    await self._waiter\n",
      "aiohttp.client_exceptions.ClientOSError: [Errno 1] [SSL: APPLICATION_DATA_AFTER_CLOSE_NOTIFY] application data after close notify (_ssl.c:2747)\n",
      "Task exception was never retrieved\n",
      "future: <Task finished name='Task-30733' coro=<tqdm_asyncio.gather.<locals>.wrap_awaitable() done, defined at c:\\users\\adria\\miniconda3\\envs\\scraper\\lib\\site-packages\\tqdm\\asyncio.py:75> exception=ClientConnectionError('Connector is closed.')>\n",
      "Traceback (most recent call last):\n",
      "  File \"c:\\users\\adria\\miniconda3\\envs\\scraper\\lib\\site-packages\\tqdm\\asyncio.py\", line 76, in wrap_awaitable\n",
      "    return i, await f\n",
      "  File \"C:\\Users\\adria\\AppData\\Local\\Temp\\ipykernel_27608\\3299729886.py\", line 22, in checker\n",
      "    async with session.get(url, allow_redirects=True, ssl=False, raise_for_status=True, timeout=100, headers=headers) as r:\n",
      "  File \"c:\\users\\adria\\miniconda3\\envs\\scraper\\lib\\site-packages\\aiohttp\\client.py\", line 1141, in __aenter__\n",
      "    self._resp = await self._coro\n",
      "  File \"c:\\users\\adria\\miniconda3\\envs\\scraper\\lib\\site-packages\\aiohttp\\client.py\", line 536, in _request\n",
      "    conn = await self._connector.connect(\n",
      "  File \"c:\\users\\adria\\miniconda3\\envs\\scraper\\lib\\site-packages\\aiohttp\\connector.py\", line 543, in connect\n",
      "    raise ClientConnectionError(\"Connector is closed.\")\n",
      "aiohttp.client_exceptions.ClientConnectionError: Connector is closed.\n",
      "Task exception was never retrieved\n",
      "future: <Task finished name='Task-27076' coro=<tqdm_asyncio.gather.<locals>.wrap_awaitable() done, defined at c:\\users\\adria\\miniconda3\\envs\\scraper\\lib\\site-packages\\tqdm\\asyncio.py:75> exception=ClientConnectionError('Connector is closed.')>\n",
      "Traceback (most recent call last):\n",
      "  File \"c:\\users\\adria\\miniconda3\\envs\\scraper\\lib\\site-packages\\tqdm\\asyncio.py\", line 76, in wrap_awaitable\n",
      "    return i, await f\n",
      "  File \"C:\\Users\\adria\\AppData\\Local\\Temp\\ipykernel_27608\\3299729886.py\", line 22, in checker\n",
      "    async with session.get(url, allow_redirects=True, ssl=False, raise_for_status=True, timeout=100, headers=headers) as r:\n",
      "  File \"c:\\users\\adria\\miniconda3\\envs\\scraper\\lib\\site-packages\\aiohttp\\client.py\", line 1141, in __aenter__\n",
      "    self._resp = await self._coro\n",
      "  File \"c:\\users\\adria\\miniconda3\\envs\\scraper\\lib\\site-packages\\aiohttp\\client.py\", line 536, in _request\n",
      "    conn = await self._connector.connect(\n",
      "  File \"c:\\users\\adria\\miniconda3\\envs\\scraper\\lib\\site-packages\\aiohttp\\connector.py\", line 543, in connect\n",
      "    raise ClientConnectionError(\"Connector is closed.\")\n",
      "aiohttp.client_exceptions.ClientConnectionError: Connector is closed.\n",
      "Task exception was never retrieved\n",
      "future: <Task finished name='Task-30631' coro=<tqdm_asyncio.gather.<locals>.wrap_awaitable() done, defined at c:\\users\\adria\\miniconda3\\envs\\scraper\\lib\\site-packages\\tqdm\\asyncio.py:75> exception=ClientConnectionError('Connector is closed.')>\n",
      "Traceback (most recent call last):\n",
      "  File \"c:\\users\\adria\\miniconda3\\envs\\scraper\\lib\\site-packages\\tqdm\\asyncio.py\", line 76, in wrap_awaitable\n",
      "    return i, await f\n",
      "  File \"C:\\Users\\adria\\AppData\\Local\\Temp\\ipykernel_27608\\3299729886.py\", line 22, in checker\n",
      "    async with session.get(url, allow_redirects=True, ssl=False, raise_for_status=True, timeout=100, headers=headers) as r:\n",
      "  File \"c:\\users\\adria\\miniconda3\\envs\\scraper\\lib\\site-packages\\aiohttp\\client.py\", line 1141, in __aenter__\n",
      "    self._resp = await self._coro\n",
      "  File \"c:\\users\\adria\\miniconda3\\envs\\scraper\\lib\\site-packages\\aiohttp\\client.py\", line 536, in _request\n",
      "    conn = await self._connector.connect(\n",
      "  File \"c:\\users\\adria\\miniconda3\\envs\\scraper\\lib\\site-packages\\aiohttp\\connector.py\", line 543, in connect\n",
      "    raise ClientConnectionError(\"Connector is closed.\")\n",
      "aiohttp.client_exceptions.ClientConnectionError: Connector is closed.\n",
      "Task exception was never retrieved\n",
      "future: <Task finished name='Task-30243' coro=<tqdm_asyncio.gather.<locals>.wrap_awaitable() done, defined at c:\\users\\adria\\miniconda3\\envs\\scraper\\lib\\site-packages\\tqdm\\asyncio.py:75> exception=ClientConnectionError('Connector is closed.')>\n",
      "Traceback (most recent call last):\n",
      "  File \"c:\\users\\adria\\miniconda3\\envs\\scraper\\lib\\site-packages\\tqdm\\asyncio.py\", line 76, in wrap_awaitable\n",
      "    return i, await f\n",
      "  File \"C:\\Users\\adria\\AppData\\Local\\Temp\\ipykernel_27608\\3299729886.py\", line 22, in checker\n",
      "    async with session.get(url, allow_redirects=True, ssl=False, raise_for_status=True, timeout=100, headers=headers) as r:\n",
      "  File \"c:\\users\\adria\\miniconda3\\envs\\scraper\\lib\\site-packages\\aiohttp\\client.py\", line 1141, in __aenter__\n",
      "    self._resp = await self._coro\n",
      "  File \"c:\\users\\adria\\miniconda3\\envs\\scraper\\lib\\site-packages\\aiohttp\\client.py\", line 536, in _request\n",
      "    conn = await self._connector.connect(\n",
      "  File \"c:\\users\\adria\\miniconda3\\envs\\scraper\\lib\\site-packages\\aiohttp\\connector.py\", line 543, in connect\n",
      "    raise ClientConnectionError(\"Connector is closed.\")\n",
      "aiohttp.client_exceptions.ClientConnectionError: Connector is closed.\n",
      "Task exception was never retrieved\n",
      "future: <Task finished name='Task-29947' coro=<tqdm_asyncio.gather.<locals>.wrap_awaitable() done, defined at c:\\users\\adria\\miniconda3\\envs\\scraper\\lib\\site-packages\\tqdm\\asyncio.py:75> exception=ClientConnectionError('Connector is closed.')>\n",
      "Traceback (most recent call last):\n",
      "  File \"c:\\users\\adria\\miniconda3\\envs\\scraper\\lib\\site-packages\\tqdm\\asyncio.py\", line 76, in wrap_awaitable\n",
      "    return i, await f\n",
      "  File \"C:\\Users\\adria\\AppData\\Local\\Temp\\ipykernel_27608\\3299729886.py\", line 22, in checker\n",
      "    async with session.get(url, allow_redirects=True, ssl=False, raise_for_status=True, timeout=100, headers=headers) as r:\n",
      "  File \"c:\\users\\adria\\miniconda3\\envs\\scraper\\lib\\site-packages\\aiohttp\\client.py\", line 1141, in __aenter__\n",
      "    self._resp = await self._coro\n",
      "  File \"c:\\users\\adria\\miniconda3\\envs\\scraper\\lib\\site-packages\\aiohttp\\client.py\", line 536, in _request\n",
      "    conn = await self._connector.connect(\n",
      "  File \"c:\\users\\adria\\miniconda3\\envs\\scraper\\lib\\site-packages\\aiohttp\\connector.py\", line 543, in connect\n",
      "    raise ClientConnectionError(\"Connector is closed.\")\n",
      "aiohttp.client_exceptions.ClientConnectionError: Connector is closed.\n"
     ]
    },
    {
     "name": "stderr",
     "output_type": "stream",
     "text": [
      "Task exception was never retrieved\n",
      "future: <Task finished name='Task-29279' coro=<tqdm_asyncio.gather.<locals>.wrap_awaitable() done, defined at c:\\users\\adria\\miniconda3\\envs\\scraper\\lib\\site-packages\\tqdm\\asyncio.py:75> exception=ClientConnectionError('Connector is closed.')>\n",
      "Traceback (most recent call last):\n",
      "  File \"c:\\users\\adria\\miniconda3\\envs\\scraper\\lib\\site-packages\\tqdm\\asyncio.py\", line 76, in wrap_awaitable\n",
      "    return i, await f\n",
      "  File \"C:\\Users\\adria\\AppData\\Local\\Temp\\ipykernel_27608\\3299729886.py\", line 22, in checker\n",
      "    async with session.get(url, allow_redirects=True, ssl=False, raise_for_status=True, timeout=100, headers=headers) as r:\n",
      "  File \"c:\\users\\adria\\miniconda3\\envs\\scraper\\lib\\site-packages\\aiohttp\\client.py\", line 1141, in __aenter__\n",
      "    self._resp = await self._coro\n",
      "  File \"c:\\users\\adria\\miniconda3\\envs\\scraper\\lib\\site-packages\\aiohttp\\client.py\", line 536, in _request\n",
      "    conn = await self._connector.connect(\n",
      "  File \"c:\\users\\adria\\miniconda3\\envs\\scraper\\lib\\site-packages\\aiohttp\\connector.py\", line 543, in connect\n",
      "    raise ClientConnectionError(\"Connector is closed.\")\n",
      "aiohttp.client_exceptions.ClientConnectionError: Connector is closed.\n",
      "Task exception was never retrieved\n",
      "future: <Task finished name='Task-26541' coro=<tqdm_asyncio.gather.<locals>.wrap_awaitable() done, defined at c:\\users\\adria\\miniconda3\\envs\\scraper\\lib\\site-packages\\tqdm\\asyncio.py:75> exception=ClientConnectionError('Connector is closed.')>\n",
      "Traceback (most recent call last):\n",
      "  File \"c:\\users\\adria\\miniconda3\\envs\\scraper\\lib\\site-packages\\tqdm\\asyncio.py\", line 76, in wrap_awaitable\n",
      "    return i, await f\n",
      "  File \"C:\\Users\\adria\\AppData\\Local\\Temp\\ipykernel_27608\\3299729886.py\", line 22, in checker\n",
      "    async with session.get(url, allow_redirects=True, ssl=False, raise_for_status=True, timeout=100, headers=headers) as r:\n",
      "  File \"c:\\users\\adria\\miniconda3\\envs\\scraper\\lib\\site-packages\\aiohttp\\client.py\", line 1141, in __aenter__\n",
      "    self._resp = await self._coro\n",
      "  File \"c:\\users\\adria\\miniconda3\\envs\\scraper\\lib\\site-packages\\aiohttp\\client.py\", line 536, in _request\n",
      "    conn = await self._connector.connect(\n",
      "  File \"c:\\users\\adria\\miniconda3\\envs\\scraper\\lib\\site-packages\\aiohttp\\connector.py\", line 543, in connect\n",
      "    raise ClientConnectionError(\"Connector is closed.\")\n",
      "aiohttp.client_exceptions.ClientConnectionError: Connector is closed.\n",
      "Task exception was never retrieved\n",
      "future: <Task finished name='Task-27346' coro=<tqdm_asyncio.gather.<locals>.wrap_awaitable() done, defined at c:\\users\\adria\\miniconda3\\envs\\scraper\\lib\\site-packages\\tqdm\\asyncio.py:75> exception=ClientConnectionError('Connector is closed.')>\n",
      "Traceback (most recent call last):\n",
      "  File \"c:\\users\\adria\\miniconda3\\envs\\scraper\\lib\\site-packages\\tqdm\\asyncio.py\", line 76, in wrap_awaitable\n",
      "    return i, await f\n",
      "  File \"C:\\Users\\adria\\AppData\\Local\\Temp\\ipykernel_27608\\3299729886.py\", line 22, in checker\n",
      "    async with session.get(url, allow_redirects=True, ssl=False, raise_for_status=True, timeout=100, headers=headers) as r:\n",
      "  File \"c:\\users\\adria\\miniconda3\\envs\\scraper\\lib\\site-packages\\aiohttp\\client.py\", line 1141, in __aenter__\n",
      "    self._resp = await self._coro\n",
      "  File \"c:\\users\\adria\\miniconda3\\envs\\scraper\\lib\\site-packages\\aiohttp\\client.py\", line 536, in _request\n",
      "    conn = await self._connector.connect(\n",
      "  File \"c:\\users\\adria\\miniconda3\\envs\\scraper\\lib\\site-packages\\aiohttp\\connector.py\", line 543, in connect\n",
      "    raise ClientConnectionError(\"Connector is closed.\")\n",
      "aiohttp.client_exceptions.ClientConnectionError: Connector is closed.\n",
      "Task exception was never retrieved\n",
      "future: <Task finished name='Task-31170' coro=<tqdm_asyncio.gather.<locals>.wrap_awaitable() done, defined at c:\\users\\adria\\miniconda3\\envs\\scraper\\lib\\site-packages\\tqdm\\asyncio.py:75> exception=ClientConnectionError('Connector is closed.')>\n",
      "Traceback (most recent call last):\n",
      "  File \"c:\\users\\adria\\miniconda3\\envs\\scraper\\lib\\site-packages\\tqdm\\asyncio.py\", line 76, in wrap_awaitable\n",
      "    return i, await f\n",
      "  File \"C:\\Users\\adria\\AppData\\Local\\Temp\\ipykernel_27608\\3299729886.py\", line 22, in checker\n",
      "    async with session.get(url, allow_redirects=True, ssl=False, raise_for_status=True, timeout=100, headers=headers) as r:\n",
      "  File \"c:\\users\\adria\\miniconda3\\envs\\scraper\\lib\\site-packages\\aiohttp\\client.py\", line 1141, in __aenter__\n",
      "    self._resp = await self._coro\n",
      "  File \"c:\\users\\adria\\miniconda3\\envs\\scraper\\lib\\site-packages\\aiohttp\\client.py\", line 536, in _request\n",
      "    conn = await self._connector.connect(\n",
      "  File \"c:\\users\\adria\\miniconda3\\envs\\scraper\\lib\\site-packages\\aiohttp\\connector.py\", line 543, in connect\n",
      "    raise ClientConnectionError(\"Connector is closed.\")\n",
      "aiohttp.client_exceptions.ClientConnectionError: Connector is closed.\n",
      "Task exception was never retrieved\n",
      "future: <Task finished name='Task-28622' coro=<tqdm_asyncio.gather.<locals>.wrap_awaitable() done, defined at c:\\users\\adria\\miniconda3\\envs\\scraper\\lib\\site-packages\\tqdm\\asyncio.py:75> exception=ClientConnectionError('Connector is closed.')>\n",
      "Traceback (most recent call last):\n",
      "  File \"c:\\users\\adria\\miniconda3\\envs\\scraper\\lib\\site-packages\\tqdm\\asyncio.py\", line 76, in wrap_awaitable\n",
      "    return i, await f\n",
      "  File \"C:\\Users\\adria\\AppData\\Local\\Temp\\ipykernel_27608\\3299729886.py\", line 22, in checker\n",
      "    async with session.get(url, allow_redirects=True, ssl=False, raise_for_status=True, timeout=100, headers=headers) as r:\n",
      "  File \"c:\\users\\adria\\miniconda3\\envs\\scraper\\lib\\site-packages\\aiohttp\\client.py\", line 1141, in __aenter__\n",
      "    self._resp = await self._coro\n",
      "  File \"c:\\users\\adria\\miniconda3\\envs\\scraper\\lib\\site-packages\\aiohttp\\client.py\", line 536, in _request\n",
      "    conn = await self._connector.connect(\n",
      "  File \"c:\\users\\adria\\miniconda3\\envs\\scraper\\lib\\site-packages\\aiohttp\\connector.py\", line 543, in connect\n",
      "    raise ClientConnectionError(\"Connector is closed.\")\n",
      "aiohttp.client_exceptions.ClientConnectionError: Connector is closed.\n",
      "Task exception was never retrieved\n",
      "future: <Task finished name='Task-28734' coro=<tqdm_asyncio.gather.<locals>.wrap_awaitable() done, defined at c:\\users\\adria\\miniconda3\\envs\\scraper\\lib\\site-packages\\tqdm\\asyncio.py:75> exception=ClientConnectionError('Connector is closed.')>\n",
      "Traceback (most recent call last):\n",
      "  File \"c:\\users\\adria\\miniconda3\\envs\\scraper\\lib\\site-packages\\tqdm\\asyncio.py\", line 76, in wrap_awaitable\n",
      "    return i, await f\n",
      "  File \"C:\\Users\\adria\\AppData\\Local\\Temp\\ipykernel_27608\\3299729886.py\", line 22, in checker\n",
      "    async with session.get(url, allow_redirects=True, ssl=False, raise_for_status=True, timeout=100, headers=headers) as r:\n",
      "  File \"c:\\users\\adria\\miniconda3\\envs\\scraper\\lib\\site-packages\\aiohttp\\client.py\", line 1141, in __aenter__\n",
      "    self._resp = await self._coro\n",
      "  File \"c:\\users\\adria\\miniconda3\\envs\\scraper\\lib\\site-packages\\aiohttp\\client.py\", line 536, in _request\n",
      "    conn = await self._connector.connect(\n",
      "  File \"c:\\users\\adria\\miniconda3\\envs\\scraper\\lib\\site-packages\\aiohttp\\connector.py\", line 543, in connect\n",
      "    raise ClientConnectionError(\"Connector is closed.\")\n",
      "aiohttp.client_exceptions.ClientConnectionError: Connector is closed.\n",
      "Task exception was never retrieved\n",
      "future: <Task finished name='Task-30680' coro=<tqdm_asyncio.gather.<locals>.wrap_awaitable() done, defined at c:\\users\\adria\\miniconda3\\envs\\scraper\\lib\\site-packages\\tqdm\\asyncio.py:75> exception=ClientConnectionError('Connector is closed.')>\n",
      "Traceback (most recent call last):\n",
      "  File \"c:\\users\\adria\\miniconda3\\envs\\scraper\\lib\\site-packages\\tqdm\\asyncio.py\", line 76, in wrap_awaitable\n",
      "    return i, await f\n",
      "  File \"C:\\Users\\adria\\AppData\\Local\\Temp\\ipykernel_27608\\3299729886.py\", line 22, in checker\n",
      "    async with session.get(url, allow_redirects=True, ssl=False, raise_for_status=True, timeout=100, headers=headers) as r:\n",
      "  File \"c:\\users\\adria\\miniconda3\\envs\\scraper\\lib\\site-packages\\aiohttp\\client.py\", line 1141, in __aenter__\n",
      "    self._resp = await self._coro\n",
      "  File \"c:\\users\\adria\\miniconda3\\envs\\scraper\\lib\\site-packages\\aiohttp\\client.py\", line 536, in _request\n",
      "    conn = await self._connector.connect(\n",
      "  File \"c:\\users\\adria\\miniconda3\\envs\\scraper\\lib\\site-packages\\aiohttp\\connector.py\", line 543, in connect\n",
      "    raise ClientConnectionError(\"Connector is closed.\")\n",
      "aiohttp.client_exceptions.ClientConnectionError: Connector is closed.\n"
     ]
    },
    {
     "name": "stderr",
     "output_type": "stream",
     "text": [
      "Task exception was never retrieved\n",
      "future: <Task finished name='Task-28529' coro=<tqdm_asyncio.gather.<locals>.wrap_awaitable() done, defined at c:\\users\\adria\\miniconda3\\envs\\scraper\\lib\\site-packages\\tqdm\\asyncio.py:75> exception=ClientConnectionError('Connector is closed.')>\n",
      "Traceback (most recent call last):\n",
      "  File \"c:\\users\\adria\\miniconda3\\envs\\scraper\\lib\\site-packages\\tqdm\\asyncio.py\", line 76, in wrap_awaitable\n",
      "    return i, await f\n",
      "  File \"C:\\Users\\adria\\AppData\\Local\\Temp\\ipykernel_27608\\3299729886.py\", line 22, in checker\n",
      "    async with session.get(url, allow_redirects=True, ssl=False, raise_for_status=True, timeout=100, headers=headers) as r:\n",
      "  File \"c:\\users\\adria\\miniconda3\\envs\\scraper\\lib\\site-packages\\aiohttp\\client.py\", line 1141, in __aenter__\n",
      "    self._resp = await self._coro\n",
      "  File \"c:\\users\\adria\\miniconda3\\envs\\scraper\\lib\\site-packages\\aiohttp\\client.py\", line 536, in _request\n",
      "    conn = await self._connector.connect(\n",
      "  File \"c:\\users\\adria\\miniconda3\\envs\\scraper\\lib\\site-packages\\aiohttp\\connector.py\", line 543, in connect\n",
      "    raise ClientConnectionError(\"Connector is closed.\")\n",
      "aiohttp.client_exceptions.ClientConnectionError: Connector is closed.\n",
      "Task exception was never retrieved\n",
      "future: <Task finished name='Task-28027' coro=<tqdm_asyncio.gather.<locals>.wrap_awaitable() done, defined at c:\\users\\adria\\miniconda3\\envs\\scraper\\lib\\site-packages\\tqdm\\asyncio.py:75> exception=ClientConnectionError('Connector is closed.')>\n",
      "Traceback (most recent call last):\n",
      "  File \"c:\\users\\adria\\miniconda3\\envs\\scraper\\lib\\site-packages\\tqdm\\asyncio.py\", line 76, in wrap_awaitable\n",
      "    return i, await f\n",
      "  File \"C:\\Users\\adria\\AppData\\Local\\Temp\\ipykernel_27608\\3299729886.py\", line 22, in checker\n",
      "    async with session.get(url, allow_redirects=True, ssl=False, raise_for_status=True, timeout=100, headers=headers) as r:\n",
      "  File \"c:\\users\\adria\\miniconda3\\envs\\scraper\\lib\\site-packages\\aiohttp\\client.py\", line 1141, in __aenter__\n",
      "    self._resp = await self._coro\n",
      "  File \"c:\\users\\adria\\miniconda3\\envs\\scraper\\lib\\site-packages\\aiohttp\\client.py\", line 536, in _request\n",
      "    conn = await self._connector.connect(\n",
      "  File \"c:\\users\\adria\\miniconda3\\envs\\scraper\\lib\\site-packages\\aiohttp\\connector.py\", line 543, in connect\n",
      "    raise ClientConnectionError(\"Connector is closed.\")\n",
      "aiohttp.client_exceptions.ClientConnectionError: Connector is closed.\n",
      "Task exception was never retrieved\n",
      "future: <Task finished name='Task-27841' coro=<tqdm_asyncio.gather.<locals>.wrap_awaitable() done, defined at c:\\users\\adria\\miniconda3\\envs\\scraper\\lib\\site-packages\\tqdm\\asyncio.py:75> exception=ClientConnectionError('Connector is closed.')>\n",
      "Traceback (most recent call last):\n",
      "  File \"c:\\users\\adria\\miniconda3\\envs\\scraper\\lib\\site-packages\\tqdm\\asyncio.py\", line 76, in wrap_awaitable\n",
      "    return i, await f\n",
      "  File \"C:\\Users\\adria\\AppData\\Local\\Temp\\ipykernel_27608\\3299729886.py\", line 22, in checker\n",
      "    async with session.get(url, allow_redirects=True, ssl=False, raise_for_status=True, timeout=100, headers=headers) as r:\n",
      "  File \"c:\\users\\adria\\miniconda3\\envs\\scraper\\lib\\site-packages\\aiohttp\\client.py\", line 1141, in __aenter__\n",
      "    self._resp = await self._coro\n",
      "  File \"c:\\users\\adria\\miniconda3\\envs\\scraper\\lib\\site-packages\\aiohttp\\client.py\", line 536, in _request\n",
      "    conn = await self._connector.connect(\n",
      "  File \"c:\\users\\adria\\miniconda3\\envs\\scraper\\lib\\site-packages\\aiohttp\\connector.py\", line 543, in connect\n",
      "    raise ClientConnectionError(\"Connector is closed.\")\n",
      "aiohttp.client_exceptions.ClientConnectionError: Connector is closed.\n",
      "Task exception was never retrieved\n",
      "future: <Task finished name='Task-28705' coro=<tqdm_asyncio.gather.<locals>.wrap_awaitable() done, defined at c:\\users\\adria\\miniconda3\\envs\\scraper\\lib\\site-packages\\tqdm\\asyncio.py:75> exception=ClientConnectionError('Connector is closed.')>\n",
      "Traceback (most recent call last):\n",
      "  File \"c:\\users\\adria\\miniconda3\\envs\\scraper\\lib\\site-packages\\tqdm\\asyncio.py\", line 76, in wrap_awaitable\n",
      "    return i, await f\n",
      "  File \"C:\\Users\\adria\\AppData\\Local\\Temp\\ipykernel_27608\\3299729886.py\", line 22, in checker\n",
      "    async with session.get(url, allow_redirects=True, ssl=False, raise_for_status=True, timeout=100, headers=headers) as r:\n",
      "  File \"c:\\users\\adria\\miniconda3\\envs\\scraper\\lib\\site-packages\\aiohttp\\client.py\", line 1141, in __aenter__\n",
      "    self._resp = await self._coro\n",
      "  File \"c:\\users\\adria\\miniconda3\\envs\\scraper\\lib\\site-packages\\aiohttp\\client.py\", line 536, in _request\n",
      "    conn = await self._connector.connect(\n",
      "  File \"c:\\users\\adria\\miniconda3\\envs\\scraper\\lib\\site-packages\\aiohttp\\connector.py\", line 543, in connect\n",
      "    raise ClientConnectionError(\"Connector is closed.\")\n",
      "aiohttp.client_exceptions.ClientConnectionError: Connector is closed.\n",
      "Task exception was never retrieved\n",
      "future: <Task finished name='Task-28541' coro=<tqdm_asyncio.gather.<locals>.wrap_awaitable() done, defined at c:\\users\\adria\\miniconda3\\envs\\scraper\\lib\\site-packages\\tqdm\\asyncio.py:75> exception=ClientConnectionError('Connector is closed.')>\n",
      "Traceback (most recent call last):\n",
      "  File \"c:\\users\\adria\\miniconda3\\envs\\scraper\\lib\\site-packages\\tqdm\\asyncio.py\", line 76, in wrap_awaitable\n",
      "    return i, await f\n",
      "  File \"C:\\Users\\adria\\AppData\\Local\\Temp\\ipykernel_27608\\3299729886.py\", line 22, in checker\n",
      "    async with session.get(url, allow_redirects=True, ssl=False, raise_for_status=True, timeout=100, headers=headers) as r:\n",
      "  File \"c:\\users\\adria\\miniconda3\\envs\\scraper\\lib\\site-packages\\aiohttp\\client.py\", line 1141, in __aenter__\n",
      "    self._resp = await self._coro\n",
      "  File \"c:\\users\\adria\\miniconda3\\envs\\scraper\\lib\\site-packages\\aiohttp\\client.py\", line 536, in _request\n",
      "    conn = await self._connector.connect(\n",
      "  File \"c:\\users\\adria\\miniconda3\\envs\\scraper\\lib\\site-packages\\aiohttp\\connector.py\", line 543, in connect\n",
      "    raise ClientConnectionError(\"Connector is closed.\")\n",
      "aiohttp.client_exceptions.ClientConnectionError: Connector is closed.\n",
      "Task exception was never retrieved\n",
      "future: <Task finished name='Task-29738' coro=<tqdm_asyncio.gather.<locals>.wrap_awaitable() done, defined at c:\\users\\adria\\miniconda3\\envs\\scraper\\lib\\site-packages\\tqdm\\asyncio.py:75> exception=ClientConnectionError('Connector is closed.')>\n",
      "Traceback (most recent call last):\n",
      "  File \"c:\\users\\adria\\miniconda3\\envs\\scraper\\lib\\site-packages\\tqdm\\asyncio.py\", line 76, in wrap_awaitable\n",
      "    return i, await f\n",
      "  File \"C:\\Users\\adria\\AppData\\Local\\Temp\\ipykernel_27608\\3299729886.py\", line 22, in checker\n",
      "    async with session.get(url, allow_redirects=True, ssl=False, raise_for_status=True, timeout=100, headers=headers) as r:\n",
      "  File \"c:\\users\\adria\\miniconda3\\envs\\scraper\\lib\\site-packages\\aiohttp\\client.py\", line 1141, in __aenter__\n",
      "    self._resp = await self._coro\n",
      "  File \"c:\\users\\adria\\miniconda3\\envs\\scraper\\lib\\site-packages\\aiohttp\\client.py\", line 536, in _request\n",
      "    conn = await self._connector.connect(\n",
      "  File \"c:\\users\\adria\\miniconda3\\envs\\scraper\\lib\\site-packages\\aiohttp\\connector.py\", line 543, in connect\n",
      "    raise ClientConnectionError(\"Connector is closed.\")\n",
      "aiohttp.client_exceptions.ClientConnectionError: Connector is closed.\n",
      "Task exception was never retrieved\n",
      "future: <Task finished name='Task-26522' coro=<tqdm_asyncio.gather.<locals>.wrap_awaitable() done, defined at c:\\users\\adria\\miniconda3\\envs\\scraper\\lib\\site-packages\\tqdm\\asyncio.py:75> exception=ClientConnectionError('Connector is closed.')>\n",
      "Traceback (most recent call last):\n",
      "  File \"c:\\users\\adria\\miniconda3\\envs\\scraper\\lib\\site-packages\\tqdm\\asyncio.py\", line 76, in wrap_awaitable\n",
      "    return i, await f\n",
      "  File \"C:\\Users\\adria\\AppData\\Local\\Temp\\ipykernel_27608\\3299729886.py\", line 22, in checker\n",
      "    async with session.get(url, allow_redirects=True, ssl=False, raise_for_status=True, timeout=100, headers=headers) as r:\n",
      "  File \"c:\\users\\adria\\miniconda3\\envs\\scraper\\lib\\site-packages\\aiohttp\\client.py\", line 1141, in __aenter__\n",
      "    self._resp = await self._coro\n",
      "  File \"c:\\users\\adria\\miniconda3\\envs\\scraper\\lib\\site-packages\\aiohttp\\client.py\", line 536, in _request\n",
      "    conn = await self._connector.connect(\n",
      "  File \"c:\\users\\adria\\miniconda3\\envs\\scraper\\lib\\site-packages\\aiohttp\\connector.py\", line 543, in connect\n",
      "    raise ClientConnectionError(\"Connector is closed.\")\n",
      "aiohttp.client_exceptions.ClientConnectionError: Connector is closed.\n"
     ]
    },
    {
     "name": "stderr",
     "output_type": "stream",
     "text": [
      "Task exception was never retrieved\n",
      "future: <Task finished name='Task-28064' coro=<tqdm_asyncio.gather.<locals>.wrap_awaitable() done, defined at c:\\users\\adria\\miniconda3\\envs\\scraper\\lib\\site-packages\\tqdm\\asyncio.py:75> exception=ClientConnectionError('Connector is closed.')>\n",
      "Traceback (most recent call last):\n",
      "  File \"c:\\users\\adria\\miniconda3\\envs\\scraper\\lib\\site-packages\\tqdm\\asyncio.py\", line 76, in wrap_awaitable\n",
      "    return i, await f\n",
      "  File \"C:\\Users\\adria\\AppData\\Local\\Temp\\ipykernel_27608\\3299729886.py\", line 22, in checker\n",
      "    async with session.get(url, allow_redirects=True, ssl=False, raise_for_status=True, timeout=100, headers=headers) as r:\n",
      "  File \"c:\\users\\adria\\miniconda3\\envs\\scraper\\lib\\site-packages\\aiohttp\\client.py\", line 1141, in __aenter__\n",
      "    self._resp = await self._coro\n",
      "  File \"c:\\users\\adria\\miniconda3\\envs\\scraper\\lib\\site-packages\\aiohttp\\client.py\", line 536, in _request\n",
      "    conn = await self._connector.connect(\n",
      "  File \"c:\\users\\adria\\miniconda3\\envs\\scraper\\lib\\site-packages\\aiohttp\\connector.py\", line 543, in connect\n",
      "    raise ClientConnectionError(\"Connector is closed.\")\n",
      "aiohttp.client_exceptions.ClientConnectionError: Connector is closed.\n",
      "Task exception was never retrieved\n",
      "future: <Task finished name='Task-30862' coro=<tqdm_asyncio.gather.<locals>.wrap_awaitable() done, defined at c:\\users\\adria\\miniconda3\\envs\\scraper\\lib\\site-packages\\tqdm\\asyncio.py:75> exception=ClientConnectionError('Connector is closed.')>\n",
      "Traceback (most recent call last):\n",
      "  File \"c:\\users\\adria\\miniconda3\\envs\\scraper\\lib\\site-packages\\tqdm\\asyncio.py\", line 76, in wrap_awaitable\n",
      "    return i, await f\n",
      "  File \"C:\\Users\\adria\\AppData\\Local\\Temp\\ipykernel_27608\\3299729886.py\", line 22, in checker\n",
      "    async with session.get(url, allow_redirects=True, ssl=False, raise_for_status=True, timeout=100, headers=headers) as r:\n",
      "  File \"c:\\users\\adria\\miniconda3\\envs\\scraper\\lib\\site-packages\\aiohttp\\client.py\", line 1141, in __aenter__\n",
      "    self._resp = await self._coro\n",
      "  File \"c:\\users\\adria\\miniconda3\\envs\\scraper\\lib\\site-packages\\aiohttp\\client.py\", line 536, in _request\n",
      "    conn = await self._connector.connect(\n",
      "  File \"c:\\users\\adria\\miniconda3\\envs\\scraper\\lib\\site-packages\\aiohttp\\connector.py\", line 543, in connect\n",
      "    raise ClientConnectionError(\"Connector is closed.\")\n",
      "aiohttp.client_exceptions.ClientConnectionError: Connector is closed.\n",
      "Task exception was never retrieved\n",
      "future: <Task finished name='Task-30208' coro=<tqdm_asyncio.gather.<locals>.wrap_awaitable() done, defined at c:\\users\\adria\\miniconda3\\envs\\scraper\\lib\\site-packages\\tqdm\\asyncio.py:75> exception=ClientConnectionError('Connector is closed.')>\n",
      "Traceback (most recent call last):\n",
      "  File \"c:\\users\\adria\\miniconda3\\envs\\scraper\\lib\\site-packages\\tqdm\\asyncio.py\", line 76, in wrap_awaitable\n",
      "    return i, await f\n",
      "  File \"C:\\Users\\adria\\AppData\\Local\\Temp\\ipykernel_27608\\3299729886.py\", line 22, in checker\n",
      "    async with session.get(url, allow_redirects=True, ssl=False, raise_for_status=True, timeout=100, headers=headers) as r:\n",
      "  File \"c:\\users\\adria\\miniconda3\\envs\\scraper\\lib\\site-packages\\aiohttp\\client.py\", line 1141, in __aenter__\n",
      "    self._resp = await self._coro\n",
      "  File \"c:\\users\\adria\\miniconda3\\envs\\scraper\\lib\\site-packages\\aiohttp\\client.py\", line 536, in _request\n",
      "    conn = await self._connector.connect(\n",
      "  File \"c:\\users\\adria\\miniconda3\\envs\\scraper\\lib\\site-packages\\aiohttp\\connector.py\", line 543, in connect\n",
      "    raise ClientConnectionError(\"Connector is closed.\")\n",
      "aiohttp.client_exceptions.ClientConnectionError: Connector is closed.\n",
      "Task exception was never retrieved\n",
      "future: <Task finished name='Task-30127' coro=<tqdm_asyncio.gather.<locals>.wrap_awaitable() done, defined at c:\\users\\adria\\miniconda3\\envs\\scraper\\lib\\site-packages\\tqdm\\asyncio.py:75> exception=ClientConnectionError('Connector is closed.')>\n",
      "Traceback (most recent call last):\n",
      "  File \"c:\\users\\adria\\miniconda3\\envs\\scraper\\lib\\site-packages\\tqdm\\asyncio.py\", line 76, in wrap_awaitable\n",
      "    return i, await f\n",
      "  File \"C:\\Users\\adria\\AppData\\Local\\Temp\\ipykernel_27608\\3299729886.py\", line 22, in checker\n",
      "    async with session.get(url, allow_redirects=True, ssl=False, raise_for_status=True, timeout=100, headers=headers) as r:\n",
      "  File \"c:\\users\\adria\\miniconda3\\envs\\scraper\\lib\\site-packages\\aiohttp\\client.py\", line 1141, in __aenter__\n",
      "    self._resp = await self._coro\n",
      "  File \"c:\\users\\adria\\miniconda3\\envs\\scraper\\lib\\site-packages\\aiohttp\\client.py\", line 536, in _request\n",
      "    conn = await self._connector.connect(\n",
      "  File \"c:\\users\\adria\\miniconda3\\envs\\scraper\\lib\\site-packages\\aiohttp\\connector.py\", line 543, in connect\n",
      "    raise ClientConnectionError(\"Connector is closed.\")\n",
      "aiohttp.client_exceptions.ClientConnectionError: Connector is closed.\n",
      "Task exception was never retrieved\n",
      "future: <Task finished name='Task-27711' coro=<tqdm_asyncio.gather.<locals>.wrap_awaitable() done, defined at c:\\users\\adria\\miniconda3\\envs\\scraper\\lib\\site-packages\\tqdm\\asyncio.py:75> exception=ClientConnectionError('Connector is closed.')>\n",
      "Traceback (most recent call last):\n",
      "  File \"c:\\users\\adria\\miniconda3\\envs\\scraper\\lib\\site-packages\\tqdm\\asyncio.py\", line 76, in wrap_awaitable\n",
      "    return i, await f\n",
      "  File \"C:\\Users\\adria\\AppData\\Local\\Temp\\ipykernel_27608\\3299729886.py\", line 22, in checker\n",
      "    async with session.get(url, allow_redirects=True, ssl=False, raise_for_status=True, timeout=100, headers=headers) as r:\n",
      "  File \"c:\\users\\adria\\miniconda3\\envs\\scraper\\lib\\site-packages\\aiohttp\\client.py\", line 1141, in __aenter__\n",
      "    self._resp = await self._coro\n",
      "  File \"c:\\users\\adria\\miniconda3\\envs\\scraper\\lib\\site-packages\\aiohttp\\client.py\", line 536, in _request\n",
      "    conn = await self._connector.connect(\n",
      "  File \"c:\\users\\adria\\miniconda3\\envs\\scraper\\lib\\site-packages\\aiohttp\\connector.py\", line 543, in connect\n",
      "    raise ClientConnectionError(\"Connector is closed.\")\n",
      "aiohttp.client_exceptions.ClientConnectionError: Connector is closed.\n",
      "Task exception was never retrieved\n",
      "future: <Task finished name='Task-27397' coro=<tqdm_asyncio.gather.<locals>.wrap_awaitable() done, defined at c:\\users\\adria\\miniconda3\\envs\\scraper\\lib\\site-packages\\tqdm\\asyncio.py:75> exception=ClientConnectionError('Connector is closed.')>\n",
      "Traceback (most recent call last):\n",
      "  File \"c:\\users\\adria\\miniconda3\\envs\\scraper\\lib\\site-packages\\tqdm\\asyncio.py\", line 76, in wrap_awaitable\n",
      "    return i, await f\n",
      "  File \"C:\\Users\\adria\\AppData\\Local\\Temp\\ipykernel_27608\\3299729886.py\", line 22, in checker\n",
      "    async with session.get(url, allow_redirects=True, ssl=False, raise_for_status=True, timeout=100, headers=headers) as r:\n",
      "  File \"c:\\users\\adria\\miniconda3\\envs\\scraper\\lib\\site-packages\\aiohttp\\client.py\", line 1141, in __aenter__\n",
      "    self._resp = await self._coro\n",
      "  File \"c:\\users\\adria\\miniconda3\\envs\\scraper\\lib\\site-packages\\aiohttp\\client.py\", line 536, in _request\n",
      "    conn = await self._connector.connect(\n",
      "  File \"c:\\users\\adria\\miniconda3\\envs\\scraper\\lib\\site-packages\\aiohttp\\connector.py\", line 543, in connect\n",
      "    raise ClientConnectionError(\"Connector is closed.\")\n",
      "aiohttp.client_exceptions.ClientConnectionError: Connector is closed.\n",
      "Task exception was never retrieved\n",
      "future: <Task finished name='Task-27678' coro=<tqdm_asyncio.gather.<locals>.wrap_awaitable() done, defined at c:\\users\\adria\\miniconda3\\envs\\scraper\\lib\\site-packages\\tqdm\\asyncio.py:75> exception=ClientConnectionError('Connector is closed.')>\n",
      "Traceback (most recent call last):\n",
      "  File \"c:\\users\\adria\\miniconda3\\envs\\scraper\\lib\\site-packages\\tqdm\\asyncio.py\", line 76, in wrap_awaitable\n",
      "    return i, await f\n",
      "  File \"C:\\Users\\adria\\AppData\\Local\\Temp\\ipykernel_27608\\3299729886.py\", line 22, in checker\n",
      "    async with session.get(url, allow_redirects=True, ssl=False, raise_for_status=True, timeout=100, headers=headers) as r:\n",
      "  File \"c:\\users\\adria\\miniconda3\\envs\\scraper\\lib\\site-packages\\aiohttp\\client.py\", line 1141, in __aenter__\n",
      "    self._resp = await self._coro\n",
      "  File \"c:\\users\\adria\\miniconda3\\envs\\scraper\\lib\\site-packages\\aiohttp\\client.py\", line 536, in _request\n",
      "    conn = await self._connector.connect(\n",
      "  File \"c:\\users\\adria\\miniconda3\\envs\\scraper\\lib\\site-packages\\aiohttp\\connector.py\", line 543, in connect\n",
      "    raise ClientConnectionError(\"Connector is closed.\")\n",
      "aiohttp.client_exceptions.ClientConnectionError: Connector is closed.\n"
     ]
    },
    {
     "name": "stderr",
     "output_type": "stream",
     "text": [
      "Task exception was never retrieved\n",
      "future: <Task finished name='Task-28923' coro=<tqdm_asyncio.gather.<locals>.wrap_awaitable() done, defined at c:\\users\\adria\\miniconda3\\envs\\scraper\\lib\\site-packages\\tqdm\\asyncio.py:75> exception=ClientConnectionError('Connector is closed.')>\n",
      "Traceback (most recent call last):\n",
      "  File \"c:\\users\\adria\\miniconda3\\envs\\scraper\\lib\\site-packages\\tqdm\\asyncio.py\", line 76, in wrap_awaitable\n",
      "    return i, await f\n",
      "  File \"C:\\Users\\adria\\AppData\\Local\\Temp\\ipykernel_27608\\3299729886.py\", line 22, in checker\n",
      "    async with session.get(url, allow_redirects=True, ssl=False, raise_for_status=True, timeout=100, headers=headers) as r:\n",
      "  File \"c:\\users\\adria\\miniconda3\\envs\\scraper\\lib\\site-packages\\aiohttp\\client.py\", line 1141, in __aenter__\n",
      "    self._resp = await self._coro\n",
      "  File \"c:\\users\\adria\\miniconda3\\envs\\scraper\\lib\\site-packages\\aiohttp\\client.py\", line 536, in _request\n",
      "    conn = await self._connector.connect(\n",
      "  File \"c:\\users\\adria\\miniconda3\\envs\\scraper\\lib\\site-packages\\aiohttp\\connector.py\", line 543, in connect\n",
      "    raise ClientConnectionError(\"Connector is closed.\")\n",
      "aiohttp.client_exceptions.ClientConnectionError: Connector is closed.\n",
      "Task exception was never retrieved\n",
      "future: <Task finished name='Task-28063' coro=<tqdm_asyncio.gather.<locals>.wrap_awaitable() done, defined at c:\\users\\adria\\miniconda3\\envs\\scraper\\lib\\site-packages\\tqdm\\asyncio.py:75> exception=ClientConnectionError('Connector is closed.')>\n",
      "Traceback (most recent call last):\n",
      "  File \"c:\\users\\adria\\miniconda3\\envs\\scraper\\lib\\site-packages\\tqdm\\asyncio.py\", line 76, in wrap_awaitable\n",
      "    return i, await f\n",
      "  File \"C:\\Users\\adria\\AppData\\Local\\Temp\\ipykernel_27608\\3299729886.py\", line 22, in checker\n",
      "    async with session.get(url, allow_redirects=True, ssl=False, raise_for_status=True, timeout=100, headers=headers) as r:\n",
      "  File \"c:\\users\\adria\\miniconda3\\envs\\scraper\\lib\\site-packages\\aiohttp\\client.py\", line 1141, in __aenter__\n",
      "    self._resp = await self._coro\n",
      "  File \"c:\\users\\adria\\miniconda3\\envs\\scraper\\lib\\site-packages\\aiohttp\\client.py\", line 536, in _request\n",
      "    conn = await self._connector.connect(\n",
      "  File \"c:\\users\\adria\\miniconda3\\envs\\scraper\\lib\\site-packages\\aiohttp\\connector.py\", line 543, in connect\n",
      "    raise ClientConnectionError(\"Connector is closed.\")\n",
      "aiohttp.client_exceptions.ClientConnectionError: Connector is closed.\n",
      "Task exception was never retrieved\n",
      "future: <Task finished name='Task-30529' coro=<tqdm_asyncio.gather.<locals>.wrap_awaitable() done, defined at c:\\users\\adria\\miniconda3\\envs\\scraper\\lib\\site-packages\\tqdm\\asyncio.py:75> exception=ClientOSError(1, '[SSL: APPLICATION_DATA_AFTER_CLOSE_NOTIFY] application data after close notify (_ssl.c:2747)')>\n",
      "Traceback (most recent call last):\n",
      "  File \"c:\\users\\adria\\miniconda3\\envs\\scraper\\lib\\site-packages\\tqdm\\asyncio.py\", line 76, in wrap_awaitable\n",
      "    return i, await f\n",
      "  File \"C:\\Users\\adria\\AppData\\Local\\Temp\\ipykernel_27608\\3299729886.py\", line 22, in checker\n",
      "    async with session.get(url, allow_redirects=True, ssl=False, raise_for_status=True, timeout=100, headers=headers) as r:\n",
      "  File \"c:\\users\\adria\\miniconda3\\envs\\scraper\\lib\\site-packages\\aiohttp\\client.py\", line 1141, in __aenter__\n",
      "    self._resp = await self._coro\n",
      "  File \"c:\\users\\adria\\miniconda3\\envs\\scraper\\lib\\site-packages\\aiohttp\\client.py\", line 560, in _request\n",
      "    await resp.start(conn)\n",
      "  File \"c:\\users\\adria\\miniconda3\\envs\\scraper\\lib\\site-packages\\aiohttp\\client_reqrep.py\", line 899, in start\n",
      "    message, payload = await protocol.read()  # type: ignore[union-attr]\n",
      "  File \"c:\\users\\adria\\miniconda3\\envs\\scraper\\lib\\site-packages\\aiohttp\\streams.py\", line 616, in read\n",
      "    await self._waiter\n",
      "aiohttp.client_exceptions.ClientOSError: [Errno 1] [SSL: APPLICATION_DATA_AFTER_CLOSE_NOTIFY] application data after close notify (_ssl.c:2747)\n",
      "Task exception was never retrieved\n",
      "future: <Task finished name='Task-29695' coro=<tqdm_asyncio.gather.<locals>.wrap_awaitable() done, defined at c:\\users\\adria\\miniconda3\\envs\\scraper\\lib\\site-packages\\tqdm\\asyncio.py:75> exception=ClientConnectionError('Connector is closed.')>\n",
      "Traceback (most recent call last):\n",
      "  File \"c:\\users\\adria\\miniconda3\\envs\\scraper\\lib\\site-packages\\tqdm\\asyncio.py\", line 76, in wrap_awaitable\n",
      "    return i, await f\n",
      "  File \"C:\\Users\\adria\\AppData\\Local\\Temp\\ipykernel_27608\\3299729886.py\", line 22, in checker\n",
      "    async with session.get(url, allow_redirects=True, ssl=False, raise_for_status=True, timeout=100, headers=headers) as r:\n",
      "  File \"c:\\users\\adria\\miniconda3\\envs\\scraper\\lib\\site-packages\\aiohttp\\client.py\", line 1141, in __aenter__\n",
      "    self._resp = await self._coro\n",
      "  File \"c:\\users\\adria\\miniconda3\\envs\\scraper\\lib\\site-packages\\aiohttp\\client.py\", line 536, in _request\n",
      "    conn = await self._connector.connect(\n",
      "  File \"c:\\users\\adria\\miniconda3\\envs\\scraper\\lib\\site-packages\\aiohttp\\connector.py\", line 543, in connect\n",
      "    raise ClientConnectionError(\"Connector is closed.\")\n",
      "aiohttp.client_exceptions.ClientConnectionError: Connector is closed.\n",
      "Task exception was never retrieved\n",
      "future: <Task finished name='Task-29191' coro=<tqdm_asyncio.gather.<locals>.wrap_awaitable() done, defined at c:\\users\\adria\\miniconda3\\envs\\scraper\\lib\\site-packages\\tqdm\\asyncio.py:75> exception=ClientConnectionError('Connector is closed.')>\n",
      "Traceback (most recent call last):\n",
      "  File \"c:\\users\\adria\\miniconda3\\envs\\scraper\\lib\\site-packages\\tqdm\\asyncio.py\", line 76, in wrap_awaitable\n",
      "    return i, await f\n",
      "  File \"C:\\Users\\adria\\AppData\\Local\\Temp\\ipykernel_27608\\3299729886.py\", line 22, in checker\n",
      "    async with session.get(url, allow_redirects=True, ssl=False, raise_for_status=True, timeout=100, headers=headers) as r:\n",
      "  File \"c:\\users\\adria\\miniconda3\\envs\\scraper\\lib\\site-packages\\aiohttp\\client.py\", line 1141, in __aenter__\n",
      "    self._resp = await self._coro\n",
      "  File \"c:\\users\\adria\\miniconda3\\envs\\scraper\\lib\\site-packages\\aiohttp\\client.py\", line 536, in _request\n",
      "    conn = await self._connector.connect(\n",
      "  File \"c:\\users\\adria\\miniconda3\\envs\\scraper\\lib\\site-packages\\aiohttp\\connector.py\", line 543, in connect\n",
      "    raise ClientConnectionError(\"Connector is closed.\")\n",
      "aiohttp.client_exceptions.ClientConnectionError: Connector is closed.\n",
      "Task exception was never retrieved\n",
      "future: <Task finished name='Task-26744' coro=<tqdm_asyncio.gather.<locals>.wrap_awaitable() done, defined at c:\\users\\adria\\miniconda3\\envs\\scraper\\lib\\site-packages\\tqdm\\asyncio.py:75> exception=ClientConnectionError('Connector is closed.')>\n",
      "Traceback (most recent call last):\n",
      "  File \"c:\\users\\adria\\miniconda3\\envs\\scraper\\lib\\site-packages\\tqdm\\asyncio.py\", line 76, in wrap_awaitable\n",
      "    return i, await f\n",
      "  File \"C:\\Users\\adria\\AppData\\Local\\Temp\\ipykernel_27608\\3299729886.py\", line 22, in checker\n",
      "    async with session.get(url, allow_redirects=True, ssl=False, raise_for_status=True, timeout=100, headers=headers) as r:\n",
      "  File \"c:\\users\\adria\\miniconda3\\envs\\scraper\\lib\\site-packages\\aiohttp\\client.py\", line 1141, in __aenter__\n",
      "    self._resp = await self._coro\n",
      "  File \"c:\\users\\adria\\miniconda3\\envs\\scraper\\lib\\site-packages\\aiohttp\\client.py\", line 536, in _request\n",
      "    conn = await self._connector.connect(\n",
      "  File \"c:\\users\\adria\\miniconda3\\envs\\scraper\\lib\\site-packages\\aiohttp\\connector.py\", line 543, in connect\n",
      "    raise ClientConnectionError(\"Connector is closed.\")\n",
      "aiohttp.client_exceptions.ClientConnectionError: Connector is closed.\n",
      "Task exception was never retrieved\n",
      "future: <Task finished name='Task-29508' coro=<tqdm_asyncio.gather.<locals>.wrap_awaitable() done, defined at c:\\users\\adria\\miniconda3\\envs\\scraper\\lib\\site-packages\\tqdm\\asyncio.py:75> exception=ClientConnectionError('Connector is closed.')>\n",
      "Traceback (most recent call last):\n",
      "  File \"c:\\users\\adria\\miniconda3\\envs\\scraper\\lib\\site-packages\\tqdm\\asyncio.py\", line 76, in wrap_awaitable\n",
      "    return i, await f\n",
      "  File \"C:\\Users\\adria\\AppData\\Local\\Temp\\ipykernel_27608\\3299729886.py\", line 22, in checker\n",
      "    async with session.get(url, allow_redirects=True, ssl=False, raise_for_status=True, timeout=100, headers=headers) as r:\n",
      "  File \"c:\\users\\adria\\miniconda3\\envs\\scraper\\lib\\site-packages\\aiohttp\\client.py\", line 1141, in __aenter__\n",
      "    self._resp = await self._coro\n",
      "  File \"c:\\users\\adria\\miniconda3\\envs\\scraper\\lib\\site-packages\\aiohttp\\client.py\", line 536, in _request\n",
      "    conn = await self._connector.connect(\n",
      "  File \"c:\\users\\adria\\miniconda3\\envs\\scraper\\lib\\site-packages\\aiohttp\\connector.py\", line 543, in connect\n",
      "    raise ClientConnectionError(\"Connector is closed.\")\n",
      "aiohttp.client_exceptions.ClientConnectionError: Connector is closed.\n"
     ]
    },
    {
     "name": "stderr",
     "output_type": "stream",
     "text": [
      "Task exception was never retrieved\n",
      "future: <Task finished name='Task-28752' coro=<tqdm_asyncio.gather.<locals>.wrap_awaitable() done, defined at c:\\users\\adria\\miniconda3\\envs\\scraper\\lib\\site-packages\\tqdm\\asyncio.py:75> exception=ClientConnectionError('Connector is closed.')>\n",
      "Traceback (most recent call last):\n",
      "  File \"c:\\users\\adria\\miniconda3\\envs\\scraper\\lib\\site-packages\\tqdm\\asyncio.py\", line 76, in wrap_awaitable\n",
      "    return i, await f\n",
      "  File \"C:\\Users\\adria\\AppData\\Local\\Temp\\ipykernel_27608\\3299729886.py\", line 22, in checker\n",
      "    async with session.get(url, allow_redirects=True, ssl=False, raise_for_status=True, timeout=100, headers=headers) as r:\n",
      "  File \"c:\\users\\adria\\miniconda3\\envs\\scraper\\lib\\site-packages\\aiohttp\\client.py\", line 1141, in __aenter__\n",
      "    self._resp = await self._coro\n",
      "  File \"c:\\users\\adria\\miniconda3\\envs\\scraper\\lib\\site-packages\\aiohttp\\client.py\", line 536, in _request\n",
      "    conn = await self._connector.connect(\n",
      "  File \"c:\\users\\adria\\miniconda3\\envs\\scraper\\lib\\site-packages\\aiohttp\\connector.py\", line 543, in connect\n",
      "    raise ClientConnectionError(\"Connector is closed.\")\n",
      "aiohttp.client_exceptions.ClientConnectionError: Connector is closed.\n",
      "Task exception was never retrieved\n",
      "future: <Task finished name='Task-30414' coro=<tqdm_asyncio.gather.<locals>.wrap_awaitable() done, defined at c:\\users\\adria\\miniconda3\\envs\\scraper\\lib\\site-packages\\tqdm\\asyncio.py:75> exception=ClientConnectionError('Connector is closed.')>\n",
      "Traceback (most recent call last):\n",
      "  File \"c:\\users\\adria\\miniconda3\\envs\\scraper\\lib\\site-packages\\tqdm\\asyncio.py\", line 76, in wrap_awaitable\n",
      "    return i, await f\n",
      "  File \"C:\\Users\\adria\\AppData\\Local\\Temp\\ipykernel_27608\\3299729886.py\", line 22, in checker\n",
      "    async with session.get(url, allow_redirects=True, ssl=False, raise_for_status=True, timeout=100, headers=headers) as r:\n",
      "  File \"c:\\users\\adria\\miniconda3\\envs\\scraper\\lib\\site-packages\\aiohttp\\client.py\", line 1141, in __aenter__\n",
      "    self._resp = await self._coro\n",
      "  File \"c:\\users\\adria\\miniconda3\\envs\\scraper\\lib\\site-packages\\aiohttp\\client.py\", line 536, in _request\n",
      "    conn = await self._connector.connect(\n",
      "  File \"c:\\users\\adria\\miniconda3\\envs\\scraper\\lib\\site-packages\\aiohttp\\connector.py\", line 543, in connect\n",
      "    raise ClientConnectionError(\"Connector is closed.\")\n",
      "aiohttp.client_exceptions.ClientConnectionError: Connector is closed.\n",
      "Task exception was never retrieved\n",
      "future: <Task finished name='Task-31139' coro=<tqdm_asyncio.gather.<locals>.wrap_awaitable() done, defined at c:\\users\\adria\\miniconda3\\envs\\scraper\\lib\\site-packages\\tqdm\\asyncio.py:75> exception=ClientConnectionError('Connector is closed.')>\n",
      "Traceback (most recent call last):\n",
      "  File \"c:\\users\\adria\\miniconda3\\envs\\scraper\\lib\\site-packages\\tqdm\\asyncio.py\", line 76, in wrap_awaitable\n",
      "    return i, await f\n",
      "  File \"C:\\Users\\adria\\AppData\\Local\\Temp\\ipykernel_27608\\3299729886.py\", line 22, in checker\n",
      "    async with session.get(url, allow_redirects=True, ssl=False, raise_for_status=True, timeout=100, headers=headers) as r:\n",
      "  File \"c:\\users\\adria\\miniconda3\\envs\\scraper\\lib\\site-packages\\aiohttp\\client.py\", line 1141, in __aenter__\n",
      "    self._resp = await self._coro\n",
      "  File \"c:\\users\\adria\\miniconda3\\envs\\scraper\\lib\\site-packages\\aiohttp\\client.py\", line 536, in _request\n",
      "    conn = await self._connector.connect(\n",
      "  File \"c:\\users\\adria\\miniconda3\\envs\\scraper\\lib\\site-packages\\aiohttp\\connector.py\", line 543, in connect\n",
      "    raise ClientConnectionError(\"Connector is closed.\")\n",
      "aiohttp.client_exceptions.ClientConnectionError: Connector is closed.\n",
      "Task exception was never retrieved\n",
      "future: <Task finished name='Task-27752' coro=<tqdm_asyncio.gather.<locals>.wrap_awaitable() done, defined at c:\\users\\adria\\miniconda3\\envs\\scraper\\lib\\site-packages\\tqdm\\asyncio.py:75> exception=ClientConnectionError('Connector is closed.')>\n",
      "Traceback (most recent call last):\n",
      "  File \"c:\\users\\adria\\miniconda3\\envs\\scraper\\lib\\site-packages\\tqdm\\asyncio.py\", line 76, in wrap_awaitable\n",
      "    return i, await f\n",
      "  File \"C:\\Users\\adria\\AppData\\Local\\Temp\\ipykernel_27608\\3299729886.py\", line 22, in checker\n",
      "    async with session.get(url, allow_redirects=True, ssl=False, raise_for_status=True, timeout=100, headers=headers) as r:\n",
      "  File \"c:\\users\\adria\\miniconda3\\envs\\scraper\\lib\\site-packages\\aiohttp\\client.py\", line 1141, in __aenter__\n",
      "    self._resp = await self._coro\n",
      "  File \"c:\\users\\adria\\miniconda3\\envs\\scraper\\lib\\site-packages\\aiohttp\\client.py\", line 536, in _request\n",
      "    conn = await self._connector.connect(\n",
      "  File \"c:\\users\\adria\\miniconda3\\envs\\scraper\\lib\\site-packages\\aiohttp\\connector.py\", line 543, in connect\n",
      "    raise ClientConnectionError(\"Connector is closed.\")\n",
      "aiohttp.client_exceptions.ClientConnectionError: Connector is closed.\n",
      "Task exception was never retrieved\n",
      "future: <Task finished name='Task-26521' coro=<tqdm_asyncio.gather.<locals>.wrap_awaitable() done, defined at c:\\users\\adria\\miniconda3\\envs\\scraper\\lib\\site-packages\\tqdm\\asyncio.py:75> exception=ClientConnectionError('Connector is closed.')>\n",
      "Traceback (most recent call last):\n",
      "  File \"c:\\users\\adria\\miniconda3\\envs\\scraper\\lib\\site-packages\\tqdm\\asyncio.py\", line 76, in wrap_awaitable\n",
      "    return i, await f\n",
      "  File \"C:\\Users\\adria\\AppData\\Local\\Temp\\ipykernel_27608\\3299729886.py\", line 22, in checker\n",
      "    async with session.get(url, allow_redirects=True, ssl=False, raise_for_status=True, timeout=100, headers=headers) as r:\n",
      "  File \"c:\\users\\adria\\miniconda3\\envs\\scraper\\lib\\site-packages\\aiohttp\\client.py\", line 1141, in __aenter__\n",
      "    self._resp = await self._coro\n",
      "  File \"c:\\users\\adria\\miniconda3\\envs\\scraper\\lib\\site-packages\\aiohttp\\client.py\", line 536, in _request\n",
      "    conn = await self._connector.connect(\n",
      "  File \"c:\\users\\adria\\miniconda3\\envs\\scraper\\lib\\site-packages\\aiohttp\\connector.py\", line 543, in connect\n",
      "    raise ClientConnectionError(\"Connector is closed.\")\n",
      "aiohttp.client_exceptions.ClientConnectionError: Connector is closed.\n",
      "Task exception was never retrieved\n",
      "future: <Task finished name='Task-26795' coro=<tqdm_asyncio.gather.<locals>.wrap_awaitable() done, defined at c:\\users\\adria\\miniconda3\\envs\\scraper\\lib\\site-packages\\tqdm\\asyncio.py:75> exception=ClientConnectionError('Connector is closed.')>\n",
      "Traceback (most recent call last):\n",
      "  File \"c:\\users\\adria\\miniconda3\\envs\\scraper\\lib\\site-packages\\tqdm\\asyncio.py\", line 76, in wrap_awaitable\n",
      "    return i, await f\n",
      "  File \"C:\\Users\\adria\\AppData\\Local\\Temp\\ipykernel_27608\\3299729886.py\", line 22, in checker\n",
      "    async with session.get(url, allow_redirects=True, ssl=False, raise_for_status=True, timeout=100, headers=headers) as r:\n",
      "  File \"c:\\users\\adria\\miniconda3\\envs\\scraper\\lib\\site-packages\\aiohttp\\client.py\", line 1141, in __aenter__\n",
      "    self._resp = await self._coro\n",
      "  File \"c:\\users\\adria\\miniconda3\\envs\\scraper\\lib\\site-packages\\aiohttp\\client.py\", line 536, in _request\n",
      "    conn = await self._connector.connect(\n",
      "  File \"c:\\users\\adria\\miniconda3\\envs\\scraper\\lib\\site-packages\\aiohttp\\connector.py\", line 543, in connect\n",
      "    raise ClientConnectionError(\"Connector is closed.\")\n",
      "aiohttp.client_exceptions.ClientConnectionError: Connector is closed.\n",
      "Task exception was never retrieved\n",
      "future: <Task finished name='Task-27958' coro=<tqdm_asyncio.gather.<locals>.wrap_awaitable() done, defined at c:\\users\\adria\\miniconda3\\envs\\scraper\\lib\\site-packages\\tqdm\\asyncio.py:75> exception=ClientConnectionError('Connector is closed.')>\n",
      "Traceback (most recent call last):\n",
      "  File \"c:\\users\\adria\\miniconda3\\envs\\scraper\\lib\\site-packages\\tqdm\\asyncio.py\", line 76, in wrap_awaitable\n",
      "    return i, await f\n",
      "  File \"C:\\Users\\adria\\AppData\\Local\\Temp\\ipykernel_27608\\3299729886.py\", line 22, in checker\n",
      "    async with session.get(url, allow_redirects=True, ssl=False, raise_for_status=True, timeout=100, headers=headers) as r:\n",
      "  File \"c:\\users\\adria\\miniconda3\\envs\\scraper\\lib\\site-packages\\aiohttp\\client.py\", line 1141, in __aenter__\n",
      "    self._resp = await self._coro\n",
      "  File \"c:\\users\\adria\\miniconda3\\envs\\scraper\\lib\\site-packages\\aiohttp\\client.py\", line 536, in _request\n",
      "    conn = await self._connector.connect(\n",
      "  File \"c:\\users\\adria\\miniconda3\\envs\\scraper\\lib\\site-packages\\aiohttp\\connector.py\", line 543, in connect\n",
      "    raise ClientConnectionError(\"Connector is closed.\")\n",
      "aiohttp.client_exceptions.ClientConnectionError: Connector is closed.\n"
     ]
    },
    {
     "name": "stderr",
     "output_type": "stream",
     "text": [
      "Task exception was never retrieved\n",
      "future: <Task finished name='Task-29099' coro=<tqdm_asyncio.gather.<locals>.wrap_awaitable() done, defined at c:\\users\\adria\\miniconda3\\envs\\scraper\\lib\\site-packages\\tqdm\\asyncio.py:75> exception=ClientConnectionError('Connector is closed.')>\n",
      "Traceback (most recent call last):\n",
      "  File \"c:\\users\\adria\\miniconda3\\envs\\scraper\\lib\\site-packages\\tqdm\\asyncio.py\", line 76, in wrap_awaitable\n",
      "    return i, await f\n",
      "  File \"C:\\Users\\adria\\AppData\\Local\\Temp\\ipykernel_27608\\3299729886.py\", line 22, in checker\n",
      "    async with session.get(url, allow_redirects=True, ssl=False, raise_for_status=True, timeout=100, headers=headers) as r:\n",
      "  File \"c:\\users\\adria\\miniconda3\\envs\\scraper\\lib\\site-packages\\aiohttp\\client.py\", line 1141, in __aenter__\n",
      "    self._resp = await self._coro\n",
      "  File \"c:\\users\\adria\\miniconda3\\envs\\scraper\\lib\\site-packages\\aiohttp\\client.py\", line 536, in _request\n",
      "    conn = await self._connector.connect(\n",
      "  File \"c:\\users\\adria\\miniconda3\\envs\\scraper\\lib\\site-packages\\aiohttp\\connector.py\", line 543, in connect\n",
      "    raise ClientConnectionError(\"Connector is closed.\")\n",
      "aiohttp.client_exceptions.ClientConnectionError: Connector is closed.\n",
      "Task exception was never retrieved\n",
      "future: <Task finished name='Task-26740' coro=<tqdm_asyncio.gather.<locals>.wrap_awaitable() done, defined at c:\\users\\adria\\miniconda3\\envs\\scraper\\lib\\site-packages\\tqdm\\asyncio.py:75> exception=ClientConnectionError('Connector is closed.')>\n",
      "Traceback (most recent call last):\n",
      "  File \"c:\\users\\adria\\miniconda3\\envs\\scraper\\lib\\site-packages\\tqdm\\asyncio.py\", line 76, in wrap_awaitable\n",
      "    return i, await f\n",
      "  File \"C:\\Users\\adria\\AppData\\Local\\Temp\\ipykernel_27608\\3299729886.py\", line 22, in checker\n",
      "    async with session.get(url, allow_redirects=True, ssl=False, raise_for_status=True, timeout=100, headers=headers) as r:\n",
      "  File \"c:\\users\\adria\\miniconda3\\envs\\scraper\\lib\\site-packages\\aiohttp\\client.py\", line 1141, in __aenter__\n",
      "    self._resp = await self._coro\n",
      "  File \"c:\\users\\adria\\miniconda3\\envs\\scraper\\lib\\site-packages\\aiohttp\\client.py\", line 536, in _request\n",
      "    conn = await self._connector.connect(\n",
      "  File \"c:\\users\\adria\\miniconda3\\envs\\scraper\\lib\\site-packages\\aiohttp\\connector.py\", line 543, in connect\n",
      "    raise ClientConnectionError(\"Connector is closed.\")\n",
      "aiohttp.client_exceptions.ClientConnectionError: Connector is closed.\n",
      "Task exception was never retrieved\n",
      "future: <Task finished name='Task-27413' coro=<tqdm_asyncio.gather.<locals>.wrap_awaitable() done, defined at c:\\users\\adria\\miniconda3\\envs\\scraper\\lib\\site-packages\\tqdm\\asyncio.py:75> exception=ClientConnectionError('Connector is closed.')>\n",
      "Traceback (most recent call last):\n",
      "  File \"c:\\users\\adria\\miniconda3\\envs\\scraper\\lib\\site-packages\\tqdm\\asyncio.py\", line 76, in wrap_awaitable\n",
      "    return i, await f\n",
      "  File \"C:\\Users\\adria\\AppData\\Local\\Temp\\ipykernel_27608\\3299729886.py\", line 22, in checker\n",
      "    async with session.get(url, allow_redirects=True, ssl=False, raise_for_status=True, timeout=100, headers=headers) as r:\n",
      "  File \"c:\\users\\adria\\miniconda3\\envs\\scraper\\lib\\site-packages\\aiohttp\\client.py\", line 1141, in __aenter__\n",
      "    self._resp = await self._coro\n",
      "  File \"c:\\users\\adria\\miniconda3\\envs\\scraper\\lib\\site-packages\\aiohttp\\client.py\", line 536, in _request\n",
      "    conn = await self._connector.connect(\n",
      "  File \"c:\\users\\adria\\miniconda3\\envs\\scraper\\lib\\site-packages\\aiohttp\\connector.py\", line 543, in connect\n",
      "    raise ClientConnectionError(\"Connector is closed.\")\n",
      "aiohttp.client_exceptions.ClientConnectionError: Connector is closed.\n",
      "Task exception was never retrieved\n",
      "future: <Task finished name='Task-30363' coro=<tqdm_asyncio.gather.<locals>.wrap_awaitable() done, defined at c:\\users\\adria\\miniconda3\\envs\\scraper\\lib\\site-packages\\tqdm\\asyncio.py:75> exception=ClientConnectionError('Connector is closed.')>\n",
      "Traceback (most recent call last):\n",
      "  File \"c:\\users\\adria\\miniconda3\\envs\\scraper\\lib\\site-packages\\tqdm\\asyncio.py\", line 76, in wrap_awaitable\n",
      "    return i, await f\n",
      "  File \"C:\\Users\\adria\\AppData\\Local\\Temp\\ipykernel_27608\\3299729886.py\", line 22, in checker\n",
      "    async with session.get(url, allow_redirects=True, ssl=False, raise_for_status=True, timeout=100, headers=headers) as r:\n",
      "  File \"c:\\users\\adria\\miniconda3\\envs\\scraper\\lib\\site-packages\\aiohttp\\client.py\", line 1141, in __aenter__\n",
      "    self._resp = await self._coro\n",
      "  File \"c:\\users\\adria\\miniconda3\\envs\\scraper\\lib\\site-packages\\aiohttp\\client.py\", line 536, in _request\n",
      "    conn = await self._connector.connect(\n",
      "  File \"c:\\users\\adria\\miniconda3\\envs\\scraper\\lib\\site-packages\\aiohttp\\connector.py\", line 543, in connect\n",
      "    raise ClientConnectionError(\"Connector is closed.\")\n",
      "aiohttp.client_exceptions.ClientConnectionError: Connector is closed.\n",
      "Task exception was never retrieved\n",
      "future: <Task finished name='Task-29889' coro=<tqdm_asyncio.gather.<locals>.wrap_awaitable() done, defined at c:\\users\\adria\\miniconda3\\envs\\scraper\\lib\\site-packages\\tqdm\\asyncio.py:75> exception=ClientConnectionError('Connector is closed.')>\n",
      "Traceback (most recent call last):\n",
      "  File \"c:\\users\\adria\\miniconda3\\envs\\scraper\\lib\\site-packages\\tqdm\\asyncio.py\", line 76, in wrap_awaitable\n",
      "    return i, await f\n",
      "  File \"C:\\Users\\adria\\AppData\\Local\\Temp\\ipykernel_27608\\3299729886.py\", line 22, in checker\n",
      "    async with session.get(url, allow_redirects=True, ssl=False, raise_for_status=True, timeout=100, headers=headers) as r:\n",
      "  File \"c:\\users\\adria\\miniconda3\\envs\\scraper\\lib\\site-packages\\aiohttp\\client.py\", line 1141, in __aenter__\n",
      "    self._resp = await self._coro\n",
      "  File \"c:\\users\\adria\\miniconda3\\envs\\scraper\\lib\\site-packages\\aiohttp\\client.py\", line 536, in _request\n",
      "    conn = await self._connector.connect(\n",
      "  File \"c:\\users\\adria\\miniconda3\\envs\\scraper\\lib\\site-packages\\aiohttp\\connector.py\", line 543, in connect\n",
      "    raise ClientConnectionError(\"Connector is closed.\")\n",
      "aiohttp.client_exceptions.ClientConnectionError: Connector is closed.\n",
      "Task exception was never retrieved\n",
      "future: <Task finished name='Task-26758' coro=<tqdm_asyncio.gather.<locals>.wrap_awaitable() done, defined at c:\\users\\adria\\miniconda3\\envs\\scraper\\lib\\site-packages\\tqdm\\asyncio.py:75> exception=ClientConnectionError('Connector is closed.')>\n",
      "Traceback (most recent call last):\n",
      "  File \"c:\\users\\adria\\miniconda3\\envs\\scraper\\lib\\site-packages\\tqdm\\asyncio.py\", line 76, in wrap_awaitable\n",
      "    return i, await f\n",
      "  File \"C:\\Users\\adria\\AppData\\Local\\Temp\\ipykernel_27608\\3299729886.py\", line 22, in checker\n",
      "    async with session.get(url, allow_redirects=True, ssl=False, raise_for_status=True, timeout=100, headers=headers) as r:\n",
      "  File \"c:\\users\\adria\\miniconda3\\envs\\scraper\\lib\\site-packages\\aiohttp\\client.py\", line 1141, in __aenter__\n",
      "    self._resp = await self._coro\n",
      "  File \"c:\\users\\adria\\miniconda3\\envs\\scraper\\lib\\site-packages\\aiohttp\\client.py\", line 536, in _request\n",
      "    conn = await self._connector.connect(\n",
      "  File \"c:\\users\\adria\\miniconda3\\envs\\scraper\\lib\\site-packages\\aiohttp\\connector.py\", line 543, in connect\n",
      "    raise ClientConnectionError(\"Connector is closed.\")\n",
      "aiohttp.client_exceptions.ClientConnectionError: Connector is closed.\n",
      "Task exception was never retrieved\n",
      "future: <Task finished name='Task-30066' coro=<tqdm_asyncio.gather.<locals>.wrap_awaitable() done, defined at c:\\users\\adria\\miniconda3\\envs\\scraper\\lib\\site-packages\\tqdm\\asyncio.py:75> exception=ClientConnectionError('Connector is closed.')>\n",
      "Traceback (most recent call last):\n",
      "  File \"c:\\users\\adria\\miniconda3\\envs\\scraper\\lib\\site-packages\\tqdm\\asyncio.py\", line 76, in wrap_awaitable\n",
      "    return i, await f\n",
      "  File \"C:\\Users\\adria\\AppData\\Local\\Temp\\ipykernel_27608\\3299729886.py\", line 22, in checker\n",
      "    async with session.get(url, allow_redirects=True, ssl=False, raise_for_status=True, timeout=100, headers=headers) as r:\n",
      "  File \"c:\\users\\adria\\miniconda3\\envs\\scraper\\lib\\site-packages\\aiohttp\\client.py\", line 1141, in __aenter__\n",
      "    self._resp = await self._coro\n",
      "  File \"c:\\users\\adria\\miniconda3\\envs\\scraper\\lib\\site-packages\\aiohttp\\client.py\", line 536, in _request\n",
      "    conn = await self._connector.connect(\n",
      "  File \"c:\\users\\adria\\miniconda3\\envs\\scraper\\lib\\site-packages\\aiohttp\\connector.py\", line 543, in connect\n",
      "    raise ClientConnectionError(\"Connector is closed.\")\n",
      "aiohttp.client_exceptions.ClientConnectionError: Connector is closed.\n"
     ]
    },
    {
     "name": "stderr",
     "output_type": "stream",
     "text": [
      "Task exception was never retrieved\n",
      "future: <Task finished name='Task-27786' coro=<tqdm_asyncio.gather.<locals>.wrap_awaitable() done, defined at c:\\users\\adria\\miniconda3\\envs\\scraper\\lib\\site-packages\\tqdm\\asyncio.py:75> exception=ClientConnectionError('Connector is closed.')>\n",
      "Traceback (most recent call last):\n",
      "  File \"c:\\users\\adria\\miniconda3\\envs\\scraper\\lib\\site-packages\\tqdm\\asyncio.py\", line 76, in wrap_awaitable\n",
      "    return i, await f\n",
      "  File \"C:\\Users\\adria\\AppData\\Local\\Temp\\ipykernel_27608\\3299729886.py\", line 22, in checker\n",
      "    async with session.get(url, allow_redirects=True, ssl=False, raise_for_status=True, timeout=100, headers=headers) as r:\n",
      "  File \"c:\\users\\adria\\miniconda3\\envs\\scraper\\lib\\site-packages\\aiohttp\\client.py\", line 1141, in __aenter__\n",
      "    self._resp = await self._coro\n",
      "  File \"c:\\users\\adria\\miniconda3\\envs\\scraper\\lib\\site-packages\\aiohttp\\client.py\", line 536, in _request\n",
      "    conn = await self._connector.connect(\n",
      "  File \"c:\\users\\adria\\miniconda3\\envs\\scraper\\lib\\site-packages\\aiohttp\\connector.py\", line 543, in connect\n",
      "    raise ClientConnectionError(\"Connector is closed.\")\n",
      "aiohttp.client_exceptions.ClientConnectionError: Connector is closed.\n",
      "Task exception was never retrieved\n",
      "future: <Task finished name='Task-31275' coro=<tqdm_asyncio.gather.<locals>.wrap_awaitable() done, defined at c:\\users\\adria\\miniconda3\\envs\\scraper\\lib\\site-packages\\tqdm\\asyncio.py:75> exception=ClientConnectionError('Connector is closed.')>\n",
      "Traceback (most recent call last):\n",
      "  File \"c:\\users\\adria\\miniconda3\\envs\\scraper\\lib\\site-packages\\tqdm\\asyncio.py\", line 76, in wrap_awaitable\n",
      "    return i, await f\n",
      "  File \"C:\\Users\\adria\\AppData\\Local\\Temp\\ipykernel_27608\\3299729886.py\", line 22, in checker\n",
      "    async with session.get(url, allow_redirects=True, ssl=False, raise_for_status=True, timeout=100, headers=headers) as r:\n",
      "  File \"c:\\users\\adria\\miniconda3\\envs\\scraper\\lib\\site-packages\\aiohttp\\client.py\", line 1141, in __aenter__\n",
      "    self._resp = await self._coro\n",
      "  File \"c:\\users\\adria\\miniconda3\\envs\\scraper\\lib\\site-packages\\aiohttp\\client.py\", line 536, in _request\n",
      "    conn = await self._connector.connect(\n",
      "  File \"c:\\users\\adria\\miniconda3\\envs\\scraper\\lib\\site-packages\\aiohttp\\connector.py\", line 543, in connect\n",
      "    raise ClientConnectionError(\"Connector is closed.\")\n",
      "aiohttp.client_exceptions.ClientConnectionError: Connector is closed.\n",
      "Task exception was never retrieved\n",
      "future: <Task finished name='Task-27838' coro=<tqdm_asyncio.gather.<locals>.wrap_awaitable() done, defined at c:\\users\\adria\\miniconda3\\envs\\scraper\\lib\\site-packages\\tqdm\\asyncio.py:75> exception=ClientConnectionError('Connector is closed.')>\n",
      "Traceback (most recent call last):\n",
      "  File \"c:\\users\\adria\\miniconda3\\envs\\scraper\\lib\\site-packages\\tqdm\\asyncio.py\", line 76, in wrap_awaitable\n",
      "    return i, await f\n",
      "  File \"C:\\Users\\adria\\AppData\\Local\\Temp\\ipykernel_27608\\3299729886.py\", line 22, in checker\n",
      "    async with session.get(url, allow_redirects=True, ssl=False, raise_for_status=True, timeout=100, headers=headers) as r:\n",
      "  File \"c:\\users\\adria\\miniconda3\\envs\\scraper\\lib\\site-packages\\aiohttp\\client.py\", line 1141, in __aenter__\n",
      "    self._resp = await self._coro\n",
      "  File \"c:\\users\\adria\\miniconda3\\envs\\scraper\\lib\\site-packages\\aiohttp\\client.py\", line 536, in _request\n",
      "    conn = await self._connector.connect(\n",
      "  File \"c:\\users\\adria\\miniconda3\\envs\\scraper\\lib\\site-packages\\aiohttp\\connector.py\", line 543, in connect\n",
      "    raise ClientConnectionError(\"Connector is closed.\")\n",
      "aiohttp.client_exceptions.ClientConnectionError: Connector is closed.\n",
      "Task exception was never retrieved\n",
      "future: <Task finished name='Task-29415' coro=<tqdm_asyncio.gather.<locals>.wrap_awaitable() done, defined at c:\\users\\adria\\miniconda3\\envs\\scraper\\lib\\site-packages\\tqdm\\asyncio.py:75> exception=ClientConnectionError('Connector is closed.')>\n",
      "Traceback (most recent call last):\n",
      "  File \"c:\\users\\adria\\miniconda3\\envs\\scraper\\lib\\site-packages\\tqdm\\asyncio.py\", line 76, in wrap_awaitable\n",
      "    return i, await f\n",
      "  File \"C:\\Users\\adria\\AppData\\Local\\Temp\\ipykernel_27608\\3299729886.py\", line 22, in checker\n",
      "    async with session.get(url, allow_redirects=True, ssl=False, raise_for_status=True, timeout=100, headers=headers) as r:\n",
      "  File \"c:\\users\\adria\\miniconda3\\envs\\scraper\\lib\\site-packages\\aiohttp\\client.py\", line 1141, in __aenter__\n",
      "    self._resp = await self._coro\n",
      "  File \"c:\\users\\adria\\miniconda3\\envs\\scraper\\lib\\site-packages\\aiohttp\\client.py\", line 536, in _request\n",
      "    conn = await self._connector.connect(\n",
      "  File \"c:\\users\\adria\\miniconda3\\envs\\scraper\\lib\\site-packages\\aiohttp\\connector.py\", line 543, in connect\n",
      "    raise ClientConnectionError(\"Connector is closed.\")\n",
      "aiohttp.client_exceptions.ClientConnectionError: Connector is closed.\n",
      "Task exception was never retrieved\n",
      "future: <Task finished name='Task-28479' coro=<tqdm_asyncio.gather.<locals>.wrap_awaitable() done, defined at c:\\users\\adria\\miniconda3\\envs\\scraper\\lib\\site-packages\\tqdm\\asyncio.py:75> exception=ClientConnectionError('Connector is closed.')>\n",
      "Traceback (most recent call last):\n",
      "  File \"c:\\users\\adria\\miniconda3\\envs\\scraper\\lib\\site-packages\\tqdm\\asyncio.py\", line 76, in wrap_awaitable\n",
      "    return i, await f\n",
      "  File \"C:\\Users\\adria\\AppData\\Local\\Temp\\ipykernel_27608\\3299729886.py\", line 22, in checker\n",
      "    async with session.get(url, allow_redirects=True, ssl=False, raise_for_status=True, timeout=100, headers=headers) as r:\n",
      "  File \"c:\\users\\adria\\miniconda3\\envs\\scraper\\lib\\site-packages\\aiohttp\\client.py\", line 1141, in __aenter__\n",
      "    self._resp = await self._coro\n",
      "  File \"c:\\users\\adria\\miniconda3\\envs\\scraper\\lib\\site-packages\\aiohttp\\client.py\", line 536, in _request\n",
      "    conn = await self._connector.connect(\n",
      "  File \"c:\\users\\adria\\miniconda3\\envs\\scraper\\lib\\site-packages\\aiohttp\\connector.py\", line 543, in connect\n",
      "    raise ClientConnectionError(\"Connector is closed.\")\n",
      "aiohttp.client_exceptions.ClientConnectionError: Connector is closed.\n",
      "Task exception was never retrieved\n",
      "future: <Task finished name='Task-26722' coro=<tqdm_asyncio.gather.<locals>.wrap_awaitable() done, defined at c:\\users\\adria\\miniconda3\\envs\\scraper\\lib\\site-packages\\tqdm\\asyncio.py:75> exception=ClientConnectionError('Connector is closed.')>\n",
      "Traceback (most recent call last):\n",
      "  File \"c:\\users\\adria\\miniconda3\\envs\\scraper\\lib\\site-packages\\tqdm\\asyncio.py\", line 76, in wrap_awaitable\n",
      "    return i, await f\n",
      "  File \"C:\\Users\\adria\\AppData\\Local\\Temp\\ipykernel_27608\\3299729886.py\", line 22, in checker\n",
      "    async with session.get(url, allow_redirects=True, ssl=False, raise_for_status=True, timeout=100, headers=headers) as r:\n",
      "  File \"c:\\users\\adria\\miniconda3\\envs\\scraper\\lib\\site-packages\\aiohttp\\client.py\", line 1141, in __aenter__\n",
      "    self._resp = await self._coro\n",
      "  File \"c:\\users\\adria\\miniconda3\\envs\\scraper\\lib\\site-packages\\aiohttp\\client.py\", line 536, in _request\n",
      "    conn = await self._connector.connect(\n",
      "  File \"c:\\users\\adria\\miniconda3\\envs\\scraper\\lib\\site-packages\\aiohttp\\connector.py\", line 543, in connect\n",
      "    raise ClientConnectionError(\"Connector is closed.\")\n",
      "aiohttp.client_exceptions.ClientConnectionError: Connector is closed.\n",
      "Task exception was never retrieved\n",
      "future: <Task finished name='Task-27427' coro=<tqdm_asyncio.gather.<locals>.wrap_awaitable() done, defined at c:\\users\\adria\\miniconda3\\envs\\scraper\\lib\\site-packages\\tqdm\\asyncio.py:75> exception=ClientConnectionError('Connector is closed.')>\n",
      "Traceback (most recent call last):\n",
      "  File \"c:\\users\\adria\\miniconda3\\envs\\scraper\\lib\\site-packages\\tqdm\\asyncio.py\", line 76, in wrap_awaitable\n",
      "    return i, await f\n",
      "  File \"C:\\Users\\adria\\AppData\\Local\\Temp\\ipykernel_27608\\3299729886.py\", line 22, in checker\n",
      "    async with session.get(url, allow_redirects=True, ssl=False, raise_for_status=True, timeout=100, headers=headers) as r:\n",
      "  File \"c:\\users\\adria\\miniconda3\\envs\\scraper\\lib\\site-packages\\aiohttp\\client.py\", line 1141, in __aenter__\n",
      "    self._resp = await self._coro\n",
      "  File \"c:\\users\\adria\\miniconda3\\envs\\scraper\\lib\\site-packages\\aiohttp\\client.py\", line 536, in _request\n",
      "    conn = await self._connector.connect(\n",
      "  File \"c:\\users\\adria\\miniconda3\\envs\\scraper\\lib\\site-packages\\aiohttp\\connector.py\", line 543, in connect\n",
      "    raise ClientConnectionError(\"Connector is closed.\")\n",
      "aiohttp.client_exceptions.ClientConnectionError: Connector is closed.\n"
     ]
    },
    {
     "name": "stderr",
     "output_type": "stream",
     "text": [
      "Task exception was never retrieved\n",
      "future: <Task finished name='Task-29539' coro=<tqdm_asyncio.gather.<locals>.wrap_awaitable() done, defined at c:\\users\\adria\\miniconda3\\envs\\scraper\\lib\\site-packages\\tqdm\\asyncio.py:75> exception=ClientConnectionError('Connector is closed.')>\n",
      "Traceback (most recent call last):\n",
      "  File \"c:\\users\\adria\\miniconda3\\envs\\scraper\\lib\\site-packages\\tqdm\\asyncio.py\", line 76, in wrap_awaitable\n",
      "    return i, await f\n",
      "  File \"C:\\Users\\adria\\AppData\\Local\\Temp\\ipykernel_27608\\3299729886.py\", line 22, in checker\n",
      "    async with session.get(url, allow_redirects=True, ssl=False, raise_for_status=True, timeout=100, headers=headers) as r:\n",
      "  File \"c:\\users\\adria\\miniconda3\\envs\\scraper\\lib\\site-packages\\aiohttp\\client.py\", line 1141, in __aenter__\n",
      "    self._resp = await self._coro\n",
      "  File \"c:\\users\\adria\\miniconda3\\envs\\scraper\\lib\\site-packages\\aiohttp\\client.py\", line 536, in _request\n",
      "    conn = await self._connector.connect(\n",
      "  File \"c:\\users\\adria\\miniconda3\\envs\\scraper\\lib\\site-packages\\aiohttp\\connector.py\", line 543, in connect\n",
      "    raise ClientConnectionError(\"Connector is closed.\")\n",
      "aiohttp.client_exceptions.ClientConnectionError: Connector is closed.\n",
      "Task exception was never retrieved\n",
      "future: <Task finished name='Task-27103' coro=<tqdm_asyncio.gather.<locals>.wrap_awaitable() done, defined at c:\\users\\adria\\miniconda3\\envs\\scraper\\lib\\site-packages\\tqdm\\asyncio.py:75> exception=ClientConnectionError('Connector is closed.')>\n",
      "Traceback (most recent call last):\n",
      "  File \"c:\\users\\adria\\miniconda3\\envs\\scraper\\lib\\site-packages\\tqdm\\asyncio.py\", line 76, in wrap_awaitable\n",
      "    return i, await f\n",
      "  File \"C:\\Users\\adria\\AppData\\Local\\Temp\\ipykernel_27608\\3299729886.py\", line 22, in checker\n",
      "    async with session.get(url, allow_redirects=True, ssl=False, raise_for_status=True, timeout=100, headers=headers) as r:\n",
      "  File \"c:\\users\\adria\\miniconda3\\envs\\scraper\\lib\\site-packages\\aiohttp\\client.py\", line 1141, in __aenter__\n",
      "    self._resp = await self._coro\n",
      "  File \"c:\\users\\adria\\miniconda3\\envs\\scraper\\lib\\site-packages\\aiohttp\\client.py\", line 536, in _request\n",
      "    conn = await self._connector.connect(\n",
      "  File \"c:\\users\\adria\\miniconda3\\envs\\scraper\\lib\\site-packages\\aiohttp\\connector.py\", line 543, in connect\n",
      "    raise ClientConnectionError(\"Connector is closed.\")\n",
      "aiohttp.client_exceptions.ClientConnectionError: Connector is closed.\n",
      "  6%|███████████████████                                                                                                                                                                                                                                                                                            | 308/4892 [00:34<04:33, 16.75it/s]"
     ]
    }
   ],
   "source": [
    "import aiohttp\n",
    "import asyncio\n",
    "import re\n",
    "import cgi\n",
    "from pathlib import Path\n",
    "from urllib.parse import urlparse"
   ]
  },
  {
   "cell_type": "code",
   "execution_count": 6,
   "metadata": {
    "id": "mjOXyChH8lQK",
    "scrolled": true
   },
   "outputs": [],
   "source": [
    "def is_url(url):\n",
    "    try:\n",
    "        a = urlparse(url)\n",
    "        return all([a.scheme, a.netloc])\n",
    "    except ValueError:\n",
    "        return False"
   ]
  },
  {
   "cell_type": "code",
   "execution_count": 53,
   "metadata": {
    "id": "-s1TVWxsxEJR",
    "scrolled": true
   },
   "outputs": [],
   "source": [
    "async def checker(session, url):\n",
    "    if pd.isna(url):\n",
    "        return pd.NA\n",
    "    \n",
    "    if \"/../\" in url or \"|\" in url: # aiohttp is kinda not smart\n",
    "        return url\n",
    "\n",
    "    \n",
    "    headers= {\n",
    "    \"User-Agent\": \"Mozilla/5.0 (Windows NT 10.0; Win64; x64; rv:98.0) Gecko/20100101 Firefox/98.0\",\n",
    "    \"Accept\": \"text/html,application/xhtml+xml,application/xml;q=0.9,image/avif,image/webp,*/*;q=0.8\",\n",
    "    \"Accept-Language\": \"en-US,en;q=0.5\",\n",
    "    \"Accept-Encoding\": \"gzip, deflate\",\n",
    "    \"Connection\": \"keep-alive\",\n",
    "    \"Upgrade-Insecure-Requests\": \"1\",\n",
    "    \"Sec-Fetch-Dest\": \"document\",\n",
    "    \"Sec-Fetch-Mode\": \"navigate\",\n",
    "    \"Sec-Fetch-Site\": \"none\",\n",
    "    \"Sec-Fetch-User\": \"?1\",\n",
    "    \"Cache-Control\": \"max-age=0\",\n",
    "    \"Host\": urlparse(url).netloc,\n",
    "    \"Referer\": urlparse(url).netloc\n",
    "    }\n",
    "    try:\n",
    "        async with session.get(url, allow_redirects=True, ssl=False, raise_for_status=True, timeout=100, headers=headers) as r:\n",
    "            if r.status == 200:\n",
    "                return url\n",
    "            elif r.status == 404:\n",
    "                return pd.NA\n",
    "            elif r.status == 301 or r.status == 302:\n",
    "                new_loc = r.headers.get('location')\n",
    "                if is_url(new_loc):\n",
    "                    return new_loc\n",
    "                else:\n",
    "                    return pd.NA\n",
    "            elif r.status != 200 and r.status != 404:\n",
    "#                 print(f\"\\nUnkknown code: {r.status} {url}\")\n",
    "                return url\n",
    "\n",
    "    except aiohttp.ClientResponseError as e:\n",
    "#         print(\"ERROR\", e, url)\n",
    "        return url\n",
    "\n",
    "    except asyncio.TimeoutError:\n",
    "        return url\n",
    "\n",
    "    except aiohttp.ClientConnectionError:\n",
    "        return url    \n",
    "    \n",
    "    except KeyboardInterrupt:\n",
    "        import os; os.exit()\n",
    "    except Exception:\n",
    "        return url"
   ]
  },
  {
   "cell_type": "code",
   "execution_count": 38,
   "metadata": {
    "id": "Jla4P4ikxIGH",
    "scrolled": true
   },
   "outputs": [],
   "source": [
    "from tqdm.asyncio import tqdm\n",
    "\n",
    "async def main():\n",
    "    async with aiohttp.ClientSession(raise_for_status = True) as session:\n",
    "        cols = [\"cdm_url\", \"homepage\", \"cdm_indirect_url\"]\n",
    "        for col in cols:\n",
    "            df[col] = await tqdm.gather(*(checker(session, url) for url in df[col]), leave=True, position=0)\n",
    "        return df"
   ]
  },
  {
   "cell_type": "code",
   "execution_count": 54,
   "metadata": {
    "colab": {
     "base_uri": "https://localhost:8080/",
     "height": 1000
    },
    "id": "0jzfvZn8xN9-",
    "outputId": "d42d8f61-a106-48c8-cd2d-8cf4f8730ae0",
    "scrolled": true
   },
   "outputs": [
    {
     "name": "stderr",
     "output_type": "stream",
     "text": [
      " 16%|███████████████████████████████████████████████▍                                                                                                                                                                                                                                                               | 766/4892 [02:51<15:25,  4.46it/s]\n",
      "100%|██████████████████████████████████████████████████████████████████████████████████████████████████████████████████████████████████████████████████████████████████████████████████████████████████████████████████████████████████████████████████████████████████████████████████████████████████████████████| 4892/4892 [01:41<00:00, 48.14it/s]\n",
      "100%|██████████████████████████████████████████████████████████████████████████████████████████████████████████████████████████████████████████████████████████████████████████████████████████████████████████████████████████████████████████████████████████████████████████████████████████████████████████████| 4892/4892 [01:49<00:00, 44.51it/s]\n",
      "100%|██████████████████████████████████████████████████████████████████████████████████████████████████████████████████████████████████████████████████████████████████████████████████████████████████████████████████████████████████████████████████████████████████████████████████████████████████████████████| 4892/4892 [02:30<00:00, 32.52it/s]\n"
     ]
    }
   ],
   "source": [
    "t = await main()"
   ]
  },
  {
   "cell_type": "code",
   "execution_count": 55,
   "metadata": {
    "colab": {
     "base_uri": "https://localhost:8080/",
     "height": 424
    },
    "id": "7XiiZGZJxO8-",
    "outputId": "63403263-0072-4c12-c2cd-6f4628b9af80",
    "scrolled": false
   },
   "outputs": [
    {
     "data": {
      "text/html": [
       "<div>\n",
       "<style scoped>\n",
       "    .dataframe tbody tr th:only-of-type {\n",
       "        vertical-align: middle;\n",
       "    }\n",
       "\n",
       "    .dataframe tbody tr th {\n",
       "        vertical-align: top;\n",
       "    }\n",
       "\n",
       "    .dataframe thead th {\n",
       "        text-align: right;\n",
       "    }\n",
       "</style>\n",
       "<table border=\"1\" class=\"dataframe\">\n",
       "  <thead>\n",
       "    <tr style=\"text-align: right;\">\n",
       "      <th></th>\n",
       "      <th>ccn</th>\n",
       "      <th>name</th>\n",
       "      <th>state</th>\n",
       "      <th>city</th>\n",
       "      <th>homepage</th>\n",
       "      <th>cdm_indirect_url</th>\n",
       "      <th>cdm_url</th>\n",
       "    </tr>\n",
       "  </thead>\n",
       "  <tbody>\n",
       "    <tr>\n",
       "      <th>0</th>\n",
       "      <td>050054</td>\n",
       "      <td>SAN GORGONIO MEMORIAL HOSPITAL</td>\n",
       "      <td>CA</td>\n",
       "      <td>BANNING</td>\n",
       "      <td>https://sgmh.org/</td>\n",
       "      <td>https://sgmh.org/</td>\n",
       "      <td>https://www.cdmpricing.com/8488f242c158e777c19...</td>\n",
       "    </tr>\n",
       "    <tr>\n",
       "      <th>1</th>\n",
       "      <td>140062</td>\n",
       "      <td>PALOS COMMUNITY HOSPITAL</td>\n",
       "      <td>IL</td>\n",
       "      <td>PALOS HEIGHTS</td>\n",
       "      <td>https://www.nm.org/</td>\n",
       "      <td>https://www.nm.org/patients-and-visitors/billi...</td>\n",
       "      <td>https://www.nm.org/-/media/northwestern/resour...</td>\n",
       "    </tr>\n",
       "    <tr>\n",
       "      <th>2</th>\n",
       "      <td>050055</td>\n",
       "      <td>CALIFORNIA PACIFIC MEDICAL CENTER - MISSION BE...</td>\n",
       "      <td>CA</td>\n",
       "      <td>SAN FRANCISCO</td>\n",
       "      <td>https://www.sutterhealth.org/</td>\n",
       "      <td>https://www.sutterhealth.org/for-patients/heal...</td>\n",
       "      <td>https://www.sutterhealth.org/pdf/chargemaster/...</td>\n",
       "    </tr>\n",
       "    <tr>\n",
       "      <th>3</th>\n",
       "      <td>140063</td>\n",
       "      <td>RUSH OAK PARK HOSPITAL</td>\n",
       "      <td>IL</td>\n",
       "      <td>OAK PARK</td>\n",
       "      <td>https://www.rush.edu/</td>\n",
       "      <td>https://www.rush.edu/patients-visitors/billing...</td>\n",
       "      <td>https://www.allegiancecosttransparency.com/202...</td>\n",
       "    </tr>\n",
       "    <tr>\n",
       "      <th>4</th>\n",
       "      <td>050056</td>\n",
       "      <td>ANTELOPE VALLEY HOSPITAL</td>\n",
       "      <td>CA</td>\n",
       "      <td>LANCASTER</td>\n",
       "      <td>https://www.avmc.org/</td>\n",
       "      <td>https://www.avmc.org/patients/billing-insuranc...</td>\n",
       "      <td>https://www.cdmpricing.com/f961a5b495c6b41f2fc...</td>\n",
       "    </tr>\n",
       "    <tr>\n",
       "      <th>...</th>\n",
       "      <td>...</td>\n",
       "      <td>...</td>\n",
       "      <td>...</td>\n",
       "      <td>...</td>\n",
       "      <td>...</td>\n",
       "      <td>...</td>\n",
       "      <td>...</td>\n",
       "    </tr>\n",
       "    <tr>\n",
       "      <th>4887</th>\n",
       "      <td>450351</td>\n",
       "      <td>TEXAS HEALTH HARRIS METHODIST HOSPITAL STEPHEN...</td>\n",
       "      <td>TX</td>\n",
       "      <td>STEPHENVILLE</td>\n",
       "      <td>https://www.texashealth.org/</td>\n",
       "      <td>https://www.texashealth.org/Costs-and-Billing/...</td>\n",
       "      <td>https://www.texashealth.org/-/media/Project/TH...</td>\n",
       "    </tr>\n",
       "    <tr>\n",
       "      <th>4888</th>\n",
       "      <td>520019</td>\n",
       "      <td>ASPIRUS RHINELANDER HOSPITAL</td>\n",
       "      <td>WI</td>\n",
       "      <td>RHINELANDER</td>\n",
       "      <td>https://www.aspirus.org/</td>\n",
       "      <td>https://www.aspirus.org/price-estimate</td>\n",
       "      <td>https://healthcare.ascension.org/-/media/proje...</td>\n",
       "    </tr>\n",
       "    <tr>\n",
       "      <th>4889</th>\n",
       "      <td>450352</td>\n",
       "      <td>HUNT REGIONAL HEALTHCARE</td>\n",
       "      <td>TX</td>\n",
       "      <td>GREENVILLE</td>\n",
       "      <td>https://www.huntregional.org/</td>\n",
       "      <td>https://www.huntregional.org/price-transparency</td>\n",
       "      <td>https://www.huntregional.org/Content/Uploads/h...</td>\n",
       "    </tr>\n",
       "    <tr>\n",
       "      <th>4890</th>\n",
       "      <td>450358</td>\n",
       "      <td>HOUSTON METHODIST HOSPITAL</td>\n",
       "      <td>TX</td>\n",
       "      <td>HOUSTON</td>\n",
       "      <td>https://www.houstonmethodist.org/</td>\n",
       "      <td>https://www.houstonmethodist.org/for-patients/...</td>\n",
       "      <td>https://www.houstonmethodist.org/-/media/files...</td>\n",
       "    </tr>\n",
       "    <tr>\n",
       "      <th>4891</th>\n",
       "      <td>520021</td>\n",
       "      <td>FROEDTERT SOUTH - FROEDTERT KENOSHA HOSPITAL</td>\n",
       "      <td>WI</td>\n",
       "      <td>KENOSHA</td>\n",
       "      <td>https://www.froedtert.com/</td>\n",
       "      <td>https://www.froedtert.com/price-transparency</td>\n",
       "      <td>https://search.hospitalpriceindex.com/hpi2/hos...</td>\n",
       "    </tr>\n",
       "  </tbody>\n",
       "</table>\n",
       "<p>4892 rows × 7 columns</p>\n",
       "</div>"
      ],
      "text/plain": [
       "         ccn                                               name state  \\\n",
       "0     050054                     SAN GORGONIO MEMORIAL HOSPITAL    CA   \n",
       "1     140062                           PALOS COMMUNITY HOSPITAL    IL   \n",
       "2     050055  CALIFORNIA PACIFIC MEDICAL CENTER - MISSION BE...    CA   \n",
       "3     140063                             RUSH OAK PARK HOSPITAL    IL   \n",
       "4     050056                           ANTELOPE VALLEY HOSPITAL    CA   \n",
       "...      ...                                                ...   ...   \n",
       "4887  450351  TEXAS HEALTH HARRIS METHODIST HOSPITAL STEPHEN...    TX   \n",
       "4888  520019                       ASPIRUS RHINELANDER HOSPITAL    WI   \n",
       "4889  450352                           HUNT REGIONAL HEALTHCARE    TX   \n",
       "4890  450358                         HOUSTON METHODIST HOSPITAL    TX   \n",
       "4891  520021       FROEDTERT SOUTH - FROEDTERT KENOSHA HOSPITAL    WI   \n",
       "\n",
       "               city                           homepage  \\\n",
       "0           BANNING                  https://sgmh.org/   \n",
       "1     PALOS HEIGHTS                https://www.nm.org/   \n",
       "2     SAN FRANCISCO      https://www.sutterhealth.org/   \n",
       "3          OAK PARK              https://www.rush.edu/   \n",
       "4         LANCASTER              https://www.avmc.org/   \n",
       "...             ...                                ...   \n",
       "4887   STEPHENVILLE       https://www.texashealth.org/   \n",
       "4888    RHINELANDER           https://www.aspirus.org/   \n",
       "4889     GREENVILLE      https://www.huntregional.org/   \n",
       "4890        HOUSTON  https://www.houstonmethodist.org/   \n",
       "4891        KENOSHA         https://www.froedtert.com/   \n",
       "\n",
       "                                       cdm_indirect_url  \\\n",
       "0                                     https://sgmh.org/   \n",
       "1     https://www.nm.org/patients-and-visitors/billi...   \n",
       "2     https://www.sutterhealth.org/for-patients/heal...   \n",
       "3     https://www.rush.edu/patients-visitors/billing...   \n",
       "4     https://www.avmc.org/patients/billing-insuranc...   \n",
       "...                                                 ...   \n",
       "4887  https://www.texashealth.org/Costs-and-Billing/...   \n",
       "4888             https://www.aspirus.org/price-estimate   \n",
       "4889    https://www.huntregional.org/price-transparency   \n",
       "4890  https://www.houstonmethodist.org/for-patients/...   \n",
       "4891       https://www.froedtert.com/price-transparency   \n",
       "\n",
       "                                                cdm_url  \n",
       "0     https://www.cdmpricing.com/8488f242c158e777c19...  \n",
       "1     https://www.nm.org/-/media/northwestern/resour...  \n",
       "2     https://www.sutterhealth.org/pdf/chargemaster/...  \n",
       "3     https://www.allegiancecosttransparency.com/202...  \n",
       "4     https://www.cdmpricing.com/f961a5b495c6b41f2fc...  \n",
       "...                                                 ...  \n",
       "4887  https://www.texashealth.org/-/media/Project/TH...  \n",
       "4888  https://healthcare.ascension.org/-/media/proje...  \n",
       "4889  https://www.huntregional.org/Content/Uploads/h...  \n",
       "4890  https://www.houstonmethodist.org/-/media/files...  \n",
       "4891  https://search.hospitalpriceindex.com/hpi2/hos...  \n",
       "\n",
       "[4892 rows x 7 columns]"
      ]
     },
     "execution_count": 55,
     "metadata": {},
     "output_type": "execute_result"
    }
   ],
   "source": [
    "t.to_csv(\"checked_u\")"
   ]
  },
  {
   "cell_type": "code",
   "execution_count": null,
   "metadata": {
    "id": "kiWDfsNKx0K3",
    "scrolled": true
   },
   "outputs": [],
   "source": []
  }
 ],
 "metadata": {
  "colab": {
   "provenance": []
  },
  "kernelspec": {
   "display_name": "Python 3 (ipykernel)",
   "language": "python",
   "name": "python3"
  },
  "language_info": {
   "codemirror_mode": {
    "name": "ipython",
    "version": 3
   },
   "file_extension": ".py",
   "mimetype": "text/x-python",
   "name": "python",
   "nbconvert_exporter": "python",
   "pygments_lexer": "ipython3",
   "version": "3.8.8"
  }
 },
 "nbformat": 4,
 "nbformat_minor": 1
}
