{
 "cells": [
  {
   "cell_type": "code",
   "execution_count": 1,
   "metadata": {
    "id": "M-2nabK6Nb3w",
    "scrolled": true
   },
   "outputs": [],
   "source": [
    "%%capture\n",
    "!sudo curl -L https://github.com/dolthub/dolt/releases/latest/download/install.sh | sudo bash\n",
    "!pip install pymysql\n",
    "!dolt clone onefact/paylesshealth\n",
    "  "
   ]
  },
  {
   "cell_type": "code",
   "execution_count": 2,
   "metadata": {
    "id": "Q1E9MzzDvNmN",
    "scrolled": true
   },
   "outputs": [],
   "source": [
    "!cd paylesshealth/ && dolt sql -q \"select * from hospitals where cdm_url is not null;\" -r csv > hospitals.csv"
   ]
  },
  {
   "cell_type": "code",
   "execution_count": 48,
   "metadata": {
    "colab": {
     "base_uri": "https://localhost:8080/",
     "height": 409
    },
    "id": "t2eHYzw1vUKt",
    "outputId": "329c8be5-416b-4688-8de9-a268262b72eb",
    "scrolled": true
   },
   "outputs": [],
   "source": [
    "import pandas as pd\n",
    "# df = pd.read_csv('paylesshealth/hospitals.csv')\n",
    "df = pd.read_csv('non-null.csv')\n",
    "# df = df.head()"
   ]
  },
  {
   "cell_type": "code",
   "execution_count": 31,
   "metadata": {
    "id": "UVOkJyDov5ek",
    "scrolled": false
   },
   "outputs": [
    {
     "name": "stderr",
     "output_type": "stream",
     "text": [
      "Task exception was never retrieved\n",
      "future: <Task finished name='Task-28894' coro=<tqdm_asyncio.gather.<locals>.wrap_awaitable() done, defined at c:\\users\\adria\\miniconda3\\envs\\scraper\\lib\\site-packages\\tqdm\\asyncio.py:75> exception=ServerDisconnectedError('Server disconnected')>\n",
      "Traceback (most recent call last):\n",
      "  File \"c:\\users\\adria\\miniconda3\\envs\\scraper\\lib\\site-packages\\tqdm\\asyncio.py\", line 76, in wrap_awaitable\n",
      "    return i, await f\n",
      "  File \"C:\\Users\\adria\\AppData\\Local\\Temp\\ipykernel_27608\\3299729886.py\", line 22, in checker\n",
      "    async with session.get(url, allow_redirects=True, ssl=False, raise_for_status=True, timeout=100, headers=headers) as r:\n",
      "  File \"c:\\users\\adria\\miniconda3\\envs\\scraper\\lib\\site-packages\\aiohttp\\client.py\", line 1141, in __aenter__\n",
      "    self._resp = await self._coro\n",
      "  File \"c:\\users\\adria\\miniconda3\\envs\\scraper\\lib\\site-packages\\aiohttp\\client.py\", line 560, in _request\n",
      "    await resp.start(conn)\n",
      "  File \"c:\\users\\adria\\miniconda3\\envs\\scraper\\lib\\site-packages\\aiohttp\\client_reqrep.py\", line 899, in start\n",
      "    message, payload = await protocol.read()  # type: ignore[union-attr]\n",
      "  File \"c:\\users\\adria\\miniconda3\\envs\\scraper\\lib\\site-packages\\aiohttp\\streams.py\", line 616, in read\n",
      "    await self._waiter\n",
      "aiohttp.client_exceptions.ServerDisconnectedError: Server disconnected\n",
      "Task exception was never retrieved\n",
      "future: <Task finished name='Task-27390' coro=<tqdm_asyncio.gather.<locals>.wrap_awaitable() done, defined at c:\\users\\adria\\miniconda3\\envs\\scraper\\lib\\site-packages\\tqdm\\asyncio.py:75> exception=ServerDisconnectedError('Server disconnected')>\n",
      "Traceback (most recent call last):\n",
      "  File \"c:\\users\\adria\\miniconda3\\envs\\scraper\\lib\\site-packages\\tqdm\\asyncio.py\", line 76, in wrap_awaitable\n",
      "    return i, await f\n",
      "  File \"C:\\Users\\adria\\AppData\\Local\\Temp\\ipykernel_27608\\3299729886.py\", line 22, in checker\n",
      "    async with session.get(url, allow_redirects=True, ssl=False, raise_for_status=True, timeout=100, headers=headers) as r:\n",
      "  File \"c:\\users\\adria\\miniconda3\\envs\\scraper\\lib\\site-packages\\aiohttp\\client.py\", line 1141, in __aenter__\n",
      "    self._resp = await self._coro\n",
      "  File \"c:\\users\\adria\\miniconda3\\envs\\scraper\\lib\\site-packages\\aiohttp\\client.py\", line 560, in _request\n",
      "    await resp.start(conn)\n",
      "  File \"c:\\users\\adria\\miniconda3\\envs\\scraper\\lib\\site-packages\\aiohttp\\client_reqrep.py\", line 899, in start\n",
      "    message, payload = await protocol.read()  # type: ignore[union-attr]\n",
      "  File \"c:\\users\\adria\\miniconda3\\envs\\scraper\\lib\\site-packages\\aiohttp\\streams.py\", line 616, in read\n",
      "    await self._waiter\n",
      "aiohttp.client_exceptions.ServerDisconnectedError: Server disconnected\n",
      "Task exception was never retrieved\n",
      "future: <Task finished name='Task-30516' coro=<tqdm_asyncio.gather.<locals>.wrap_awaitable() done, defined at c:\\users\\adria\\miniconda3\\envs\\scraper\\lib\\site-packages\\tqdm\\asyncio.py:75> exception=ServerDisconnectedError('Server disconnected')>\n",
      "Traceback (most recent call last):\n",
      "  File \"c:\\users\\adria\\miniconda3\\envs\\scraper\\lib\\site-packages\\tqdm\\asyncio.py\", line 76, in wrap_awaitable\n",
      "    return i, await f\n",
      "  File \"C:\\Users\\adria\\AppData\\Local\\Temp\\ipykernel_27608\\3299729886.py\", line 22, in checker\n",
      "    async with session.get(url, allow_redirects=True, ssl=False, raise_for_status=True, timeout=100, headers=headers) as r:\n",
      "  File \"c:\\users\\adria\\miniconda3\\envs\\scraper\\lib\\site-packages\\aiohttp\\client.py\", line 1141, in __aenter__\n",
      "    self._resp = await self._coro\n",
      "  File \"c:\\users\\adria\\miniconda3\\envs\\scraper\\lib\\site-packages\\aiohttp\\client.py\", line 560, in _request\n",
      "    await resp.start(conn)\n",
      "  File \"c:\\users\\adria\\miniconda3\\envs\\scraper\\lib\\site-packages\\aiohttp\\client_reqrep.py\", line 899, in start\n",
      "    message, payload = await protocol.read()  # type: ignore[union-attr]\n",
      "  File \"c:\\users\\adria\\miniconda3\\envs\\scraper\\lib\\site-packages\\aiohttp\\streams.py\", line 616, in read\n",
      "    await self._waiter\n",
      "aiohttp.client_exceptions.ServerDisconnectedError: Server disconnected\n",
      "Task exception was never retrieved\n",
      "future: <Task finished name='Task-26887' coro=<tqdm_asyncio.gather.<locals>.wrap_awaitable() done, defined at c:\\users\\adria\\miniconda3\\envs\\scraper\\lib\\site-packages\\tqdm\\asyncio.py:75> exception=ClientConnectionError('Connector is closed.')>\n",
      "Traceback (most recent call last):\n",
      "  File \"c:\\users\\adria\\miniconda3\\envs\\scraper\\lib\\site-packages\\tqdm\\asyncio.py\", line 76, in wrap_awaitable\n",
      "    return i, await f\n",
      "  File \"C:\\Users\\adria\\AppData\\Local\\Temp\\ipykernel_27608\\3299729886.py\", line 22, in checker\n",
      "    async with session.get(url, allow_redirects=True, ssl=False, raise_for_status=True, timeout=100, headers=headers) as r:\n",
      "  File \"c:\\users\\adria\\miniconda3\\envs\\scraper\\lib\\site-packages\\aiohttp\\client.py\", line 1141, in __aenter__\n",
      "    self._resp = await self._coro\n",
      "  File \"c:\\users\\adria\\miniconda3\\envs\\scraper\\lib\\site-packages\\aiohttp\\client.py\", line 536, in _request\n",
      "    conn = await self._connector.connect(\n",
      "  File \"c:\\users\\adria\\miniconda3\\envs\\scraper\\lib\\site-packages\\aiohttp\\connector.py\", line 543, in connect\n",
      "    raise ClientConnectionError(\"Connector is closed.\")\n",
      "aiohttp.client_exceptions.ClientConnectionError: Connector is closed.\n",
      "Task exception was never retrieved\n",
      "future: <Task finished name='Task-30826' coro=<tqdm_asyncio.gather.<locals>.wrap_awaitable() done, defined at c:\\users\\adria\\miniconda3\\envs\\scraper\\lib\\site-packages\\tqdm\\asyncio.py:75> exception=ClientConnectionError('Connector is closed.')>\n",
      "Traceback (most recent call last):\n",
      "  File \"c:\\users\\adria\\miniconda3\\envs\\scraper\\lib\\site-packages\\tqdm\\asyncio.py\", line 76, in wrap_awaitable\n",
      "    return i, await f\n",
      "  File \"C:\\Users\\adria\\AppData\\Local\\Temp\\ipykernel_27608\\3299729886.py\", line 22, in checker\n",
      "    async with session.get(url, allow_redirects=True, ssl=False, raise_for_status=True, timeout=100, headers=headers) as r:\n",
      "  File \"c:\\users\\adria\\miniconda3\\envs\\scraper\\lib\\site-packages\\aiohttp\\client.py\", line 1141, in __aenter__\n",
      "    self._resp = await self._coro\n",
      "  File \"c:\\users\\adria\\miniconda3\\envs\\scraper\\lib\\site-packages\\aiohttp\\client.py\", line 536, in _request\n",
      "    conn = await self._connector.connect(\n",
      "  File \"c:\\users\\adria\\miniconda3\\envs\\scraper\\lib\\site-packages\\aiohttp\\connector.py\", line 543, in connect\n",
      "    raise ClientConnectionError(\"Connector is closed.\")\n",
      "aiohttp.client_exceptions.ClientConnectionError: Connector is closed.\n",
      "Task exception was never retrieved\n",
      "future: <Task finished name='Task-30458' coro=<tqdm_asyncio.gather.<locals>.wrap_awaitable() done, defined at c:\\users\\adria\\miniconda3\\envs\\scraper\\lib\\site-packages\\tqdm\\asyncio.py:75> exception=ClientConnectionError('Connector is closed.')>\n",
      "Traceback (most recent call last):\n",
      "  File \"c:\\users\\adria\\miniconda3\\envs\\scraper\\lib\\site-packages\\tqdm\\asyncio.py\", line 76, in wrap_awaitable\n",
      "    return i, await f\n",
      "  File \"C:\\Users\\adria\\AppData\\Local\\Temp\\ipykernel_27608\\3299729886.py\", line 22, in checker\n",
      "    async with session.get(url, allow_redirects=True, ssl=False, raise_for_status=True, timeout=100, headers=headers) as r:\n",
      "  File \"c:\\users\\adria\\miniconda3\\envs\\scraper\\lib\\site-packages\\aiohttp\\client.py\", line 1141, in __aenter__\n",
      "    self._resp = await self._coro\n",
      "  File \"c:\\users\\adria\\miniconda3\\envs\\scraper\\lib\\site-packages\\aiohttp\\client.py\", line 536, in _request\n",
      "    conn = await self._connector.connect(\n",
      "  File \"c:\\users\\adria\\miniconda3\\envs\\scraper\\lib\\site-packages\\aiohttp\\connector.py\", line 543, in connect\n",
      "    raise ClientConnectionError(\"Connector is closed.\")\n",
      "aiohttp.client_exceptions.ClientConnectionError: Connector is closed.\n",
      "Task exception was never retrieved\n",
      "future: <Task finished name='Task-27149' coro=<tqdm_asyncio.gather.<locals>.wrap_awaitable() done, defined at c:\\users\\adria\\miniconda3\\envs\\scraper\\lib\\site-packages\\tqdm\\asyncio.py:75> exception=ClientConnectionError('Connector is closed.')>\n",
      "Traceback (most recent call last):\n",
      "  File \"c:\\users\\adria\\miniconda3\\envs\\scraper\\lib\\site-packages\\tqdm\\asyncio.py\", line 76, in wrap_awaitable\n",
      "    return i, await f\n",
      "  File \"C:\\Users\\adria\\AppData\\Local\\Temp\\ipykernel_27608\\3299729886.py\", line 22, in checker\n",
      "    async with session.get(url, allow_redirects=True, ssl=False, raise_for_status=True, timeout=100, headers=headers) as r:\n",
      "  File \"c:\\users\\adria\\miniconda3\\envs\\scraper\\lib\\site-packages\\aiohttp\\client.py\", line 1141, in __aenter__\n",
      "    self._resp = await self._coro\n",
      "  File \"c:\\users\\adria\\miniconda3\\envs\\scraper\\lib\\site-packages\\aiohttp\\client.py\", line 536, in _request\n",
      "    conn = await self._connector.connect(\n",
      "  File \"c:\\users\\adria\\miniconda3\\envs\\scraper\\lib\\site-packages\\aiohttp\\connector.py\", line 543, in connect\n",
      "    raise ClientConnectionError(\"Connector is closed.\")\n",
      "aiohttp.client_exceptions.ClientConnectionError: Connector is closed.\n"
     ]
    },
    {
     "name": "stderr",
     "output_type": "stream",
     "text": [
      "Task exception was never retrieved\n",
      "future: <Task finished name='Task-29862' coro=<tqdm_asyncio.gather.<locals>.wrap_awaitable() done, defined at c:\\users\\adria\\miniconda3\\envs\\scraper\\lib\\site-packages\\tqdm\\asyncio.py:75> exception=ClientConnectionError('Connector is closed.')>\n",
      "Traceback (most recent call last):\n",
      "  File \"c:\\users\\adria\\miniconda3\\envs\\scraper\\lib\\site-packages\\tqdm\\asyncio.py\", line 76, in wrap_awaitable\n",
      "    return i, await f\n",
      "  File \"C:\\Users\\adria\\AppData\\Local\\Temp\\ipykernel_27608\\3299729886.py\", line 22, in checker\n",
      "    async with session.get(url, allow_redirects=True, ssl=False, raise_for_status=True, timeout=100, headers=headers) as r:\n",
      "  File \"c:\\users\\adria\\miniconda3\\envs\\scraper\\lib\\site-packages\\aiohttp\\client.py\", line 1141, in __aenter__\n",
      "    self._resp = await self._coro\n",
      "  File \"c:\\users\\adria\\miniconda3\\envs\\scraper\\lib\\site-packages\\aiohttp\\client.py\", line 536, in _request\n",
      "    conn = await self._connector.connect(\n",
      "  File \"c:\\users\\adria\\miniconda3\\envs\\scraper\\lib\\site-packages\\aiohttp\\connector.py\", line 543, in connect\n",
      "    raise ClientConnectionError(\"Connector is closed.\")\n",
      "aiohttp.client_exceptions.ClientConnectionError: Connector is closed.\n",
      "Task exception was never retrieved\n",
      "future: <Task finished name='Task-31207' coro=<tqdm_asyncio.gather.<locals>.wrap_awaitable() done, defined at c:\\users\\adria\\miniconda3\\envs\\scraper\\lib\\site-packages\\tqdm\\asyncio.py:75> exception=ClientConnectionError('Connector is closed.')>\n",
      "Traceback (most recent call last):\n",
      "  File \"c:\\users\\adria\\miniconda3\\envs\\scraper\\lib\\site-packages\\tqdm\\asyncio.py\", line 76, in wrap_awaitable\n",
      "    return i, await f\n",
      "  File \"C:\\Users\\adria\\AppData\\Local\\Temp\\ipykernel_27608\\3299729886.py\", line 22, in checker\n",
      "    async with session.get(url, allow_redirects=True, ssl=False, raise_for_status=True, timeout=100, headers=headers) as r:\n",
      "  File \"c:\\users\\adria\\miniconda3\\envs\\scraper\\lib\\site-packages\\aiohttp\\client.py\", line 1141, in __aenter__\n",
      "    self._resp = await self._coro\n",
      "  File \"c:\\users\\adria\\miniconda3\\envs\\scraper\\lib\\site-packages\\aiohttp\\client.py\", line 536, in _request\n",
      "    conn = await self._connector.connect(\n",
      "  File \"c:\\users\\adria\\miniconda3\\envs\\scraper\\lib\\site-packages\\aiohttp\\connector.py\", line 543, in connect\n",
      "    raise ClientConnectionError(\"Connector is closed.\")\n",
      "aiohttp.client_exceptions.ClientConnectionError: Connector is closed.\n",
      "Task exception was never retrieved\n",
      "future: <Task finished name='Task-31206' coro=<tqdm_asyncio.gather.<locals>.wrap_awaitable() done, defined at c:\\users\\adria\\miniconda3\\envs\\scraper\\lib\\site-packages\\tqdm\\asyncio.py:75> exception=ClientConnectionError('Connector is closed.')>\n",
      "Traceback (most recent call last):\n",
      "  File \"c:\\users\\adria\\miniconda3\\envs\\scraper\\lib\\site-packages\\tqdm\\asyncio.py\", line 76, in wrap_awaitable\n",
      "    return i, await f\n",
      "  File \"C:\\Users\\adria\\AppData\\Local\\Temp\\ipykernel_27608\\3299729886.py\", line 22, in checker\n",
      "    async with session.get(url, allow_redirects=True, ssl=False, raise_for_status=True, timeout=100, headers=headers) as r:\n",
      "  File \"c:\\users\\adria\\miniconda3\\envs\\scraper\\lib\\site-packages\\aiohttp\\client.py\", line 1141, in __aenter__\n",
      "    self._resp = await self._coro\n",
      "  File \"c:\\users\\adria\\miniconda3\\envs\\scraper\\lib\\site-packages\\aiohttp\\client.py\", line 536, in _request\n",
      "    conn = await self._connector.connect(\n",
      "  File \"c:\\users\\adria\\miniconda3\\envs\\scraper\\lib\\site-packages\\aiohttp\\connector.py\", line 543, in connect\n",
      "    raise ClientConnectionError(\"Connector is closed.\")\n",
      "aiohttp.client_exceptions.ClientConnectionError: Connector is closed.\n",
      "Task exception was never retrieved\n",
      "future: <Task finished name='Task-29454' coro=<tqdm_asyncio.gather.<locals>.wrap_awaitable() done, defined at c:\\users\\adria\\miniconda3\\envs\\scraper\\lib\\site-packages\\tqdm\\asyncio.py:75> exception=ClientConnectionError('Connector is closed.')>\n",
      "Traceback (most recent call last):\n",
      "  File \"c:\\users\\adria\\miniconda3\\envs\\scraper\\lib\\site-packages\\tqdm\\asyncio.py\", line 76, in wrap_awaitable\n",
      "    return i, await f\n",
      "  File \"C:\\Users\\adria\\AppData\\Local\\Temp\\ipykernel_27608\\3299729886.py\", line 22, in checker\n",
      "    async with session.get(url, allow_redirects=True, ssl=False, raise_for_status=True, timeout=100, headers=headers) as r:\n",
      "  File \"c:\\users\\adria\\miniconda3\\envs\\scraper\\lib\\site-packages\\aiohttp\\client.py\", line 1141, in __aenter__\n",
      "    self._resp = await self._coro\n",
      "  File \"c:\\users\\adria\\miniconda3\\envs\\scraper\\lib\\site-packages\\aiohttp\\client.py\", line 536, in _request\n",
      "    conn = await self._connector.connect(\n",
      "  File \"c:\\users\\adria\\miniconda3\\envs\\scraper\\lib\\site-packages\\aiohttp\\connector.py\", line 543, in connect\n",
      "    raise ClientConnectionError(\"Connector is closed.\")\n",
      "aiohttp.client_exceptions.ClientConnectionError: Connector is closed.\n",
      "Task exception was never retrieved\n",
      "future: <Task finished name='Task-27260' coro=<tqdm_asyncio.gather.<locals>.wrap_awaitable() done, defined at c:\\users\\adria\\miniconda3\\envs\\scraper\\lib\\site-packages\\tqdm\\asyncio.py:75> exception=ClientConnectionError('Connector is closed.')>\n",
      "Traceback (most recent call last):\n",
      "  File \"c:\\users\\adria\\miniconda3\\envs\\scraper\\lib\\site-packages\\tqdm\\asyncio.py\", line 76, in wrap_awaitable\n",
      "    return i, await f\n",
      "  File \"C:\\Users\\adria\\AppData\\Local\\Temp\\ipykernel_27608\\3299729886.py\", line 22, in checker\n",
      "    async with session.get(url, allow_redirects=True, ssl=False, raise_for_status=True, timeout=100, headers=headers) as r:\n",
      "  File \"c:\\users\\adria\\miniconda3\\envs\\scraper\\lib\\site-packages\\aiohttp\\client.py\", line 1141, in __aenter__\n",
      "    self._resp = await self._coro\n",
      "  File \"c:\\users\\adria\\miniconda3\\envs\\scraper\\lib\\site-packages\\aiohttp\\client.py\", line 536, in _request\n",
      "    conn = await self._connector.connect(\n",
      "  File \"c:\\users\\adria\\miniconda3\\envs\\scraper\\lib\\site-packages\\aiohttp\\connector.py\", line 543, in connect\n",
      "    raise ClientConnectionError(\"Connector is closed.\")\n",
      "aiohttp.client_exceptions.ClientConnectionError: Connector is closed.\n",
      "Task exception was never retrieved\n",
      "future: <Task finished name='Task-30835' coro=<tqdm_asyncio.gather.<locals>.wrap_awaitable() done, defined at c:\\users\\adria\\miniconda3\\envs\\scraper\\lib\\site-packages\\tqdm\\asyncio.py:75> exception=ClientConnectionError('Connector is closed.')>\n",
      "Traceback (most recent call last):\n",
      "  File \"c:\\users\\adria\\miniconda3\\envs\\scraper\\lib\\site-packages\\tqdm\\asyncio.py\", line 76, in wrap_awaitable\n",
      "    return i, await f\n",
      "  File \"C:\\Users\\adria\\AppData\\Local\\Temp\\ipykernel_27608\\3299729886.py\", line 22, in checker\n",
      "    async with session.get(url, allow_redirects=True, ssl=False, raise_for_status=True, timeout=100, headers=headers) as r:\n",
      "  File \"c:\\users\\adria\\miniconda3\\envs\\scraper\\lib\\site-packages\\aiohttp\\client.py\", line 1141, in __aenter__\n",
      "    self._resp = await self._coro\n",
      "  File \"c:\\users\\adria\\miniconda3\\envs\\scraper\\lib\\site-packages\\aiohttp\\client.py\", line 536, in _request\n",
      "    conn = await self._connector.connect(\n",
      "  File \"c:\\users\\adria\\miniconda3\\envs\\scraper\\lib\\site-packages\\aiohttp\\connector.py\", line 543, in connect\n",
      "    raise ClientConnectionError(\"Connector is closed.\")\n",
      "aiohttp.client_exceptions.ClientConnectionError: Connector is closed.\n",
      "Task exception was never retrieved\n",
      "future: <Task finished name='Task-29218' coro=<tqdm_asyncio.gather.<locals>.wrap_awaitable() done, defined at c:\\users\\adria\\miniconda3\\envs\\scraper\\lib\\site-packages\\tqdm\\asyncio.py:75> exception=ClientConnectionError('Connector is closed.')>\n",
      "Traceback (most recent call last):\n",
      "  File \"c:\\users\\adria\\miniconda3\\envs\\scraper\\lib\\site-packages\\tqdm\\asyncio.py\", line 76, in wrap_awaitable\n",
      "    return i, await f\n",
      "  File \"C:\\Users\\adria\\AppData\\Local\\Temp\\ipykernel_27608\\3299729886.py\", line 22, in checker\n",
      "    async with session.get(url, allow_redirects=True, ssl=False, raise_for_status=True, timeout=100, headers=headers) as r:\n",
      "  File \"c:\\users\\adria\\miniconda3\\envs\\scraper\\lib\\site-packages\\aiohttp\\client.py\", line 1141, in __aenter__\n",
      "    self._resp = await self._coro\n",
      "  File \"c:\\users\\adria\\miniconda3\\envs\\scraper\\lib\\site-packages\\aiohttp\\client.py\", line 536, in _request\n",
      "    conn = await self._connector.connect(\n",
      "  File \"c:\\users\\adria\\miniconda3\\envs\\scraper\\lib\\site-packages\\aiohttp\\connector.py\", line 543, in connect\n",
      "    raise ClientConnectionError(\"Connector is closed.\")\n",
      "aiohttp.client_exceptions.ClientConnectionError: Connector is closed.\n"
     ]
    },
    {
     "name": "stderr",
     "output_type": "stream",
     "text": [
      "Task exception was never retrieved\n",
      "future: <Task finished name='Task-31172' coro=<tqdm_asyncio.gather.<locals>.wrap_awaitable() done, defined at c:\\users\\adria\\miniconda3\\envs\\scraper\\lib\\site-packages\\tqdm\\asyncio.py:75> exception=ClientConnectionError('Connector is closed.')>\n",
      "Traceback (most recent call last):\n",
      "  File \"c:\\users\\adria\\miniconda3\\envs\\scraper\\lib\\site-packages\\tqdm\\asyncio.py\", line 76, in wrap_awaitable\n",
      "    return i, await f\n",
      "  File \"C:\\Users\\adria\\AppData\\Local\\Temp\\ipykernel_27608\\3299729886.py\", line 22, in checker\n",
      "    async with session.get(url, allow_redirects=True, ssl=False, raise_for_status=True, timeout=100, headers=headers) as r:\n",
      "  File \"c:\\users\\adria\\miniconda3\\envs\\scraper\\lib\\site-packages\\aiohttp\\client.py\", line 1141, in __aenter__\n",
      "    self._resp = await self._coro\n",
      "  File \"c:\\users\\adria\\miniconda3\\envs\\scraper\\lib\\site-packages\\aiohttp\\client.py\", line 536, in _request\n",
      "    conn = await self._connector.connect(\n",
      "  File \"c:\\users\\adria\\miniconda3\\envs\\scraper\\lib\\site-packages\\aiohttp\\connector.py\", line 543, in connect\n",
      "    raise ClientConnectionError(\"Connector is closed.\")\n",
      "aiohttp.client_exceptions.ClientConnectionError: Connector is closed.\n",
      "Task exception was never retrieved\n",
      "future: <Task finished name='Task-28515' coro=<tqdm_asyncio.gather.<locals>.wrap_awaitable() done, defined at c:\\users\\adria\\miniconda3\\envs\\scraper\\lib\\site-packages\\tqdm\\asyncio.py:75> exception=ClientConnectionError('Connector is closed.')>\n",
      "Traceback (most recent call last):\n",
      "  File \"c:\\users\\adria\\miniconda3\\envs\\scraper\\lib\\site-packages\\tqdm\\asyncio.py\", line 76, in wrap_awaitable\n",
      "    return i, await f\n",
      "  File \"C:\\Users\\adria\\AppData\\Local\\Temp\\ipykernel_27608\\3299729886.py\", line 22, in checker\n",
      "    async with session.get(url, allow_redirects=True, ssl=False, raise_for_status=True, timeout=100, headers=headers) as r:\n",
      "  File \"c:\\users\\adria\\miniconda3\\envs\\scraper\\lib\\site-packages\\aiohttp\\client.py\", line 1141, in __aenter__\n",
      "    self._resp = await self._coro\n",
      "  File \"c:\\users\\adria\\miniconda3\\envs\\scraper\\lib\\site-packages\\aiohttp\\client.py\", line 536, in _request\n",
      "    conn = await self._connector.connect(\n",
      "  File \"c:\\users\\adria\\miniconda3\\envs\\scraper\\lib\\site-packages\\aiohttp\\connector.py\", line 543, in connect\n",
      "    raise ClientConnectionError(\"Connector is closed.\")\n",
      "aiohttp.client_exceptions.ClientConnectionError: Connector is closed.\n",
      "Task exception was never retrieved\n",
      "future: <Task finished name='Task-30121' coro=<tqdm_asyncio.gather.<locals>.wrap_awaitable() done, defined at c:\\users\\adria\\miniconda3\\envs\\scraper\\lib\\site-packages\\tqdm\\asyncio.py:75> exception=ClientConnectionError('Connector is closed.')>\n",
      "Traceback (most recent call last):\n",
      "  File \"c:\\users\\adria\\miniconda3\\envs\\scraper\\lib\\site-packages\\tqdm\\asyncio.py\", line 76, in wrap_awaitable\n",
      "    return i, await f\n",
      "  File \"C:\\Users\\adria\\AppData\\Local\\Temp\\ipykernel_27608\\3299729886.py\", line 22, in checker\n",
      "    async with session.get(url, allow_redirects=True, ssl=False, raise_for_status=True, timeout=100, headers=headers) as r:\n",
      "  File \"c:\\users\\adria\\miniconda3\\envs\\scraper\\lib\\site-packages\\aiohttp\\client.py\", line 1141, in __aenter__\n",
      "    self._resp = await self._coro\n",
      "  File \"c:\\users\\adria\\miniconda3\\envs\\scraper\\lib\\site-packages\\aiohttp\\client.py\", line 536, in _request\n",
      "    conn = await self._connector.connect(\n",
      "  File \"c:\\users\\adria\\miniconda3\\envs\\scraper\\lib\\site-packages\\aiohttp\\connector.py\", line 543, in connect\n",
      "    raise ClientConnectionError(\"Connector is closed.\")\n",
      "aiohttp.client_exceptions.ClientConnectionError: Connector is closed.\n",
      "Task exception was never retrieved\n",
      "future: <Task finished name='Task-26568' coro=<tqdm_asyncio.gather.<locals>.wrap_awaitable() done, defined at c:\\users\\adria\\miniconda3\\envs\\scraper\\lib\\site-packages\\tqdm\\asyncio.py:75> exception=ClientConnectionError('Connector is closed.')>\n",
      "Traceback (most recent call last):\n",
      "  File \"c:\\users\\adria\\miniconda3\\envs\\scraper\\lib\\site-packages\\tqdm\\asyncio.py\", line 76, in wrap_awaitable\n",
      "    return i, await f\n",
      "  File \"C:\\Users\\adria\\AppData\\Local\\Temp\\ipykernel_27608\\3299729886.py\", line 22, in checker\n",
      "    async with session.get(url, allow_redirects=True, ssl=False, raise_for_status=True, timeout=100, headers=headers) as r:\n",
      "  File \"c:\\users\\adria\\miniconda3\\envs\\scraper\\lib\\site-packages\\aiohttp\\client.py\", line 1141, in __aenter__\n",
      "    self._resp = await self._coro\n",
      "  File \"c:\\users\\adria\\miniconda3\\envs\\scraper\\lib\\site-packages\\aiohttp\\client.py\", line 536, in _request\n",
      "    conn = await self._connector.connect(\n",
      "  File \"c:\\users\\adria\\miniconda3\\envs\\scraper\\lib\\site-packages\\aiohttp\\connector.py\", line 543, in connect\n",
      "    raise ClientConnectionError(\"Connector is closed.\")\n",
      "aiohttp.client_exceptions.ClientConnectionError: Connector is closed.\n",
      "Task exception was never retrieved\n",
      "future: <Task finished name='Task-30336' coro=<tqdm_asyncio.gather.<locals>.wrap_awaitable() done, defined at c:\\users\\adria\\miniconda3\\envs\\scraper\\lib\\site-packages\\tqdm\\asyncio.py:75> exception=ClientConnectionError('Connector is closed.')>\n",
      "Traceback (most recent call last):\n",
      "  File \"c:\\users\\adria\\miniconda3\\envs\\scraper\\lib\\site-packages\\tqdm\\asyncio.py\", line 76, in wrap_awaitable\n",
      "    return i, await f\n",
      "  File \"C:\\Users\\adria\\AppData\\Local\\Temp\\ipykernel_27608\\3299729886.py\", line 22, in checker\n",
      "    async with session.get(url, allow_redirects=True, ssl=False, raise_for_status=True, timeout=100, headers=headers) as r:\n",
      "  File \"c:\\users\\adria\\miniconda3\\envs\\scraper\\lib\\site-packages\\aiohttp\\client.py\", line 1141, in __aenter__\n",
      "    self._resp = await self._coro\n",
      "  File \"c:\\users\\adria\\miniconda3\\envs\\scraper\\lib\\site-packages\\aiohttp\\client.py\", line 536, in _request\n",
      "    conn = await self._connector.connect(\n",
      "  File \"c:\\users\\adria\\miniconda3\\envs\\scraper\\lib\\site-packages\\aiohttp\\connector.py\", line 543, in connect\n",
      "    raise ClientConnectionError(\"Connector is closed.\")\n",
      "aiohttp.client_exceptions.ClientConnectionError: Connector is closed.\n",
      "Task exception was never retrieved\n",
      "future: <Task finished name='Task-28969' coro=<tqdm_asyncio.gather.<locals>.wrap_awaitable() done, defined at c:\\users\\adria\\miniconda3\\envs\\scraper\\lib\\site-packages\\tqdm\\asyncio.py:75> exception=ClientConnectionError('Connector is closed.')>\n",
      "Traceback (most recent call last):\n",
      "  File \"c:\\users\\adria\\miniconda3\\envs\\scraper\\lib\\site-packages\\tqdm\\asyncio.py\", line 76, in wrap_awaitable\n",
      "    return i, await f\n",
      "  File \"C:\\Users\\adria\\AppData\\Local\\Temp\\ipykernel_27608\\3299729886.py\", line 22, in checker\n",
      "    async with session.get(url, allow_redirects=True, ssl=False, raise_for_status=True, timeout=100, headers=headers) as r:\n",
      "  File \"c:\\users\\adria\\miniconda3\\envs\\scraper\\lib\\site-packages\\aiohttp\\client.py\", line 1141, in __aenter__\n",
      "    self._resp = await self._coro\n",
      "  File \"c:\\users\\adria\\miniconda3\\envs\\scraper\\lib\\site-packages\\aiohttp\\client.py\", line 536, in _request\n",
      "    conn = await self._connector.connect(\n",
      "  File \"c:\\users\\adria\\miniconda3\\envs\\scraper\\lib\\site-packages\\aiohttp\\connector.py\", line 543, in connect\n",
      "    raise ClientConnectionError(\"Connector is closed.\")\n",
      "aiohttp.client_exceptions.ClientConnectionError: Connector is closed.\n",
      "Task exception was never retrieved\n",
      "future: <Task finished name='Task-30579' coro=<tqdm_asyncio.gather.<locals>.wrap_awaitable() done, defined at c:\\users\\adria\\miniconda3\\envs\\scraper\\lib\\site-packages\\tqdm\\asyncio.py:75> exception=ClientConnectionError('Connector is closed.')>\n",
      "Traceback (most recent call last):\n",
      "  File \"c:\\users\\adria\\miniconda3\\envs\\scraper\\lib\\site-packages\\tqdm\\asyncio.py\", line 76, in wrap_awaitable\n",
      "    return i, await f\n",
      "  File \"C:\\Users\\adria\\AppData\\Local\\Temp\\ipykernel_27608\\3299729886.py\", line 22, in checker\n",
      "    async with session.get(url, allow_redirects=True, ssl=False, raise_for_status=True, timeout=100, headers=headers) as r:\n",
      "  File \"c:\\users\\adria\\miniconda3\\envs\\scraper\\lib\\site-packages\\aiohttp\\client.py\", line 1141, in __aenter__\n",
      "    self._resp = await self._coro\n",
      "  File \"c:\\users\\adria\\miniconda3\\envs\\scraper\\lib\\site-packages\\aiohttp\\client.py\", line 536, in _request\n",
      "    conn = await self._connector.connect(\n",
      "  File \"c:\\users\\adria\\miniconda3\\envs\\scraper\\lib\\site-packages\\aiohttp\\connector.py\", line 543, in connect\n",
      "    raise ClientConnectionError(\"Connector is closed.\")\n",
      "aiohttp.client_exceptions.ClientConnectionError: Connector is closed.\n"
     ]
    },
    {
     "name": "stderr",
     "output_type": "stream",
     "text": [
      "Task exception was never retrieved\n",
      "future: <Task finished name='Task-28845' coro=<tqdm_asyncio.gather.<locals>.wrap_awaitable() done, defined at c:\\users\\adria\\miniconda3\\envs\\scraper\\lib\\site-packages\\tqdm\\asyncio.py:75> exception=ClientConnectionError('Connector is closed.')>\n",
      "Traceback (most recent call last):\n",
      "  File \"c:\\users\\adria\\miniconda3\\envs\\scraper\\lib\\site-packages\\tqdm\\asyncio.py\", line 76, in wrap_awaitable\n",
      "    return i, await f\n",
      "  File \"C:\\Users\\adria\\AppData\\Local\\Temp\\ipykernel_27608\\3299729886.py\", line 22, in checker\n",
      "    async with session.get(url, allow_redirects=True, ssl=False, raise_for_status=True, timeout=100, headers=headers) as r:\n",
      "  File \"c:\\users\\adria\\miniconda3\\envs\\scraper\\lib\\site-packages\\aiohttp\\client.py\", line 1141, in __aenter__\n",
      "    self._resp = await self._coro\n",
      "  File \"c:\\users\\adria\\miniconda3\\envs\\scraper\\lib\\site-packages\\aiohttp\\client.py\", line 536, in _request\n",
      "    conn = await self._connector.connect(\n",
      "  File \"c:\\users\\adria\\miniconda3\\envs\\scraper\\lib\\site-packages\\aiohttp\\connector.py\", line 543, in connect\n",
      "    raise ClientConnectionError(\"Connector is closed.\")\n",
      "aiohttp.client_exceptions.ClientConnectionError: Connector is closed.\n",
      "Task exception was never retrieved\n",
      "future: <Task finished name='Task-30150' coro=<tqdm_asyncio.gather.<locals>.wrap_awaitable() done, defined at c:\\users\\adria\\miniconda3\\envs\\scraper\\lib\\site-packages\\tqdm\\asyncio.py:75> exception=ClientConnectionError('Connector is closed.')>\n",
      "Traceback (most recent call last):\n",
      "  File \"c:\\users\\adria\\miniconda3\\envs\\scraper\\lib\\site-packages\\tqdm\\asyncio.py\", line 76, in wrap_awaitable\n",
      "    return i, await f\n",
      "  File \"C:\\Users\\adria\\AppData\\Local\\Temp\\ipykernel_27608\\3299729886.py\", line 22, in checker\n",
      "    async with session.get(url, allow_redirects=True, ssl=False, raise_for_status=True, timeout=100, headers=headers) as r:\n",
      "  File \"c:\\users\\adria\\miniconda3\\envs\\scraper\\lib\\site-packages\\aiohttp\\client.py\", line 1141, in __aenter__\n",
      "    self._resp = await self._coro\n",
      "  File \"c:\\users\\adria\\miniconda3\\envs\\scraper\\lib\\site-packages\\aiohttp\\client.py\", line 536, in _request\n",
      "    conn = await self._connector.connect(\n",
      "  File \"c:\\users\\adria\\miniconda3\\envs\\scraper\\lib\\site-packages\\aiohttp\\connector.py\", line 543, in connect\n",
      "    raise ClientConnectionError(\"Connector is closed.\")\n",
      "aiohttp.client_exceptions.ClientConnectionError: Connector is closed.\n",
      "Task exception was never retrieved\n",
      "future: <Task finished name='Task-31106' coro=<tqdm_asyncio.gather.<locals>.wrap_awaitable() done, defined at c:\\users\\adria\\miniconda3\\envs\\scraper\\lib\\site-packages\\tqdm\\asyncio.py:75> exception=ClientConnectionError('Connector is closed.')>\n",
      "Traceback (most recent call last):\n",
      "  File \"c:\\users\\adria\\miniconda3\\envs\\scraper\\lib\\site-packages\\tqdm\\asyncio.py\", line 76, in wrap_awaitable\n",
      "    return i, await f\n",
      "  File \"C:\\Users\\adria\\AppData\\Local\\Temp\\ipykernel_27608\\3299729886.py\", line 22, in checker\n",
      "    async with session.get(url, allow_redirects=True, ssl=False, raise_for_status=True, timeout=100, headers=headers) as r:\n",
      "  File \"c:\\users\\adria\\miniconda3\\envs\\scraper\\lib\\site-packages\\aiohttp\\client.py\", line 1141, in __aenter__\n",
      "    self._resp = await self._coro\n",
      "  File \"c:\\users\\adria\\miniconda3\\envs\\scraper\\lib\\site-packages\\aiohttp\\client.py\", line 536, in _request\n",
      "    conn = await self._connector.connect(\n",
      "  File \"c:\\users\\adria\\miniconda3\\envs\\scraper\\lib\\site-packages\\aiohttp\\connector.py\", line 543, in connect\n",
      "    raise ClientConnectionError(\"Connector is closed.\")\n",
      "aiohttp.client_exceptions.ClientConnectionError: Connector is closed.\n",
      "Task exception was never retrieved\n",
      "future: <Task finished name='Task-26629' coro=<tqdm_asyncio.gather.<locals>.wrap_awaitable() done, defined at c:\\users\\adria\\miniconda3\\envs\\scraper\\lib\\site-packages\\tqdm\\asyncio.py:75> exception=ClientConnectionError('Connector is closed.')>\n",
      "Traceback (most recent call last):\n",
      "  File \"c:\\users\\adria\\miniconda3\\envs\\scraper\\lib\\site-packages\\tqdm\\asyncio.py\", line 76, in wrap_awaitable\n",
      "    return i, await f\n",
      "  File \"C:\\Users\\adria\\AppData\\Local\\Temp\\ipykernel_27608\\3299729886.py\", line 22, in checker\n",
      "    async with session.get(url, allow_redirects=True, ssl=False, raise_for_status=True, timeout=100, headers=headers) as r:\n",
      "  File \"c:\\users\\adria\\miniconda3\\envs\\scraper\\lib\\site-packages\\aiohttp\\client.py\", line 1141, in __aenter__\n",
      "    self._resp = await self._coro\n",
      "  File \"c:\\users\\adria\\miniconda3\\envs\\scraper\\lib\\site-packages\\aiohttp\\client.py\", line 536, in _request\n",
      "    conn = await self._connector.connect(\n",
      "  File \"c:\\users\\adria\\miniconda3\\envs\\scraper\\lib\\site-packages\\aiohttp\\connector.py\", line 543, in connect\n",
      "    raise ClientConnectionError(\"Connector is closed.\")\n",
      "aiohttp.client_exceptions.ClientConnectionError: Connector is closed.\n",
      "Task exception was never retrieved\n",
      "future: <Task finished name='Task-28497' coro=<tqdm_asyncio.gather.<locals>.wrap_awaitable() done, defined at c:\\users\\adria\\miniconda3\\envs\\scraper\\lib\\site-packages\\tqdm\\asyncio.py:75> exception=ClientConnectionError('Connector is closed.')>\n",
      "Traceback (most recent call last):\n",
      "  File \"c:\\users\\adria\\miniconda3\\envs\\scraper\\lib\\site-packages\\tqdm\\asyncio.py\", line 76, in wrap_awaitable\n",
      "    return i, await f\n",
      "  File \"C:\\Users\\adria\\AppData\\Local\\Temp\\ipykernel_27608\\3299729886.py\", line 22, in checker\n",
      "    async with session.get(url, allow_redirects=True, ssl=False, raise_for_status=True, timeout=100, headers=headers) as r:\n",
      "  File \"c:\\users\\adria\\miniconda3\\envs\\scraper\\lib\\site-packages\\aiohttp\\client.py\", line 1141, in __aenter__\n",
      "    self._resp = await self._coro\n",
      "  File \"c:\\users\\adria\\miniconda3\\envs\\scraper\\lib\\site-packages\\aiohttp\\client.py\", line 536, in _request\n",
      "    conn = await self._connector.connect(\n",
      "  File \"c:\\users\\adria\\miniconda3\\envs\\scraper\\lib\\site-packages\\aiohttp\\connector.py\", line 543, in connect\n",
      "    raise ClientConnectionError(\"Connector is closed.\")\n",
      "aiohttp.client_exceptions.ClientConnectionError: Connector is closed.\n",
      "Task exception was never retrieved\n",
      "future: <Task finished name='Task-26870' coro=<tqdm_asyncio.gather.<locals>.wrap_awaitable() done, defined at c:\\users\\adria\\miniconda3\\envs\\scraper\\lib\\site-packages\\tqdm\\asyncio.py:75> exception=ClientConnectionError('Connector is closed.')>\n",
      "Traceback (most recent call last):\n",
      "  File \"c:\\users\\adria\\miniconda3\\envs\\scraper\\lib\\site-packages\\tqdm\\asyncio.py\", line 76, in wrap_awaitable\n",
      "    return i, await f\n",
      "  File \"C:\\Users\\adria\\AppData\\Local\\Temp\\ipykernel_27608\\3299729886.py\", line 22, in checker\n",
      "    async with session.get(url, allow_redirects=True, ssl=False, raise_for_status=True, timeout=100, headers=headers) as r:\n",
      "  File \"c:\\users\\adria\\miniconda3\\envs\\scraper\\lib\\site-packages\\aiohttp\\client.py\", line 1141, in __aenter__\n",
      "    self._resp = await self._coro\n",
      "  File \"c:\\users\\adria\\miniconda3\\envs\\scraper\\lib\\site-packages\\aiohttp\\client.py\", line 536, in _request\n",
      "    conn = await self._connector.connect(\n",
      "  File \"c:\\users\\adria\\miniconda3\\envs\\scraper\\lib\\site-packages\\aiohttp\\connector.py\", line 543, in connect\n",
      "    raise ClientConnectionError(\"Connector is closed.\")\n",
      "aiohttp.client_exceptions.ClientConnectionError: Connector is closed.\n",
      "Task exception was never retrieved\n",
      "future: <Task finished name='Task-29219' coro=<tqdm_asyncio.gather.<locals>.wrap_awaitable() done, defined at c:\\users\\adria\\miniconda3\\envs\\scraper\\lib\\site-packages\\tqdm\\asyncio.py:75> exception=ClientConnectionError('Connector is closed.')>\n",
      "Traceback (most recent call last):\n",
      "  File \"c:\\users\\adria\\miniconda3\\envs\\scraper\\lib\\site-packages\\tqdm\\asyncio.py\", line 76, in wrap_awaitable\n",
      "    return i, await f\n",
      "  File \"C:\\Users\\adria\\AppData\\Local\\Temp\\ipykernel_27608\\3299729886.py\", line 22, in checker\n",
      "    async with session.get(url, allow_redirects=True, ssl=False, raise_for_status=True, timeout=100, headers=headers) as r:\n",
      "  File \"c:\\users\\adria\\miniconda3\\envs\\scraper\\lib\\site-packages\\aiohttp\\client.py\", line 1141, in __aenter__\n",
      "    self._resp = await self._coro\n",
      "  File \"c:\\users\\adria\\miniconda3\\envs\\scraper\\lib\\site-packages\\aiohttp\\client.py\", line 536, in _request\n",
      "    conn = await self._connector.connect(\n",
      "  File \"c:\\users\\adria\\miniconda3\\envs\\scraper\\lib\\site-packages\\aiohttp\\connector.py\", line 543, in connect\n",
      "    raise ClientConnectionError(\"Connector is closed.\")\n",
      "aiohttp.client_exceptions.ClientConnectionError: Connector is closed.\n"
     ]
    },
    {
     "name": "stderr",
     "output_type": "stream",
     "text": [
      "Task exception was never retrieved\n",
      "future: <Task finished name='Task-26953' coro=<tqdm_asyncio.gather.<locals>.wrap_awaitable() done, defined at c:\\users\\adria\\miniconda3\\envs\\scraper\\lib\\site-packages\\tqdm\\asyncio.py:75> exception=ClientConnectionError('Connector is closed.')>\n",
      "Traceback (most recent call last):\n",
      "  File \"c:\\users\\adria\\miniconda3\\envs\\scraper\\lib\\site-packages\\tqdm\\asyncio.py\", line 76, in wrap_awaitable\n",
      "    return i, await f\n",
      "  File \"C:\\Users\\adria\\AppData\\Local\\Temp\\ipykernel_27608\\3299729886.py\", line 22, in checker\n",
      "    async with session.get(url, allow_redirects=True, ssl=False, raise_for_status=True, timeout=100, headers=headers) as r:\n",
      "  File \"c:\\users\\adria\\miniconda3\\envs\\scraper\\lib\\site-packages\\aiohttp\\client.py\", line 1141, in __aenter__\n",
      "    self._resp = await self._coro\n",
      "  File \"c:\\users\\adria\\miniconda3\\envs\\scraper\\lib\\site-packages\\aiohttp\\client.py\", line 536, in _request\n",
      "    conn = await self._connector.connect(\n",
      "  File \"c:\\users\\adria\\miniconda3\\envs\\scraper\\lib\\site-packages\\aiohttp\\connector.py\", line 543, in connect\n",
      "    raise ClientConnectionError(\"Connector is closed.\")\n",
      "aiohttp.client_exceptions.ClientConnectionError: Connector is closed.\n",
      "Task exception was never retrieved\n",
      "future: <Task finished name='Task-26835' coro=<tqdm_asyncio.gather.<locals>.wrap_awaitable() done, defined at c:\\users\\adria\\miniconda3\\envs\\scraper\\lib\\site-packages\\tqdm\\asyncio.py:75> exception=ClientConnectionError('Connector is closed.')>\n",
      "Traceback (most recent call last):\n",
      "  File \"c:\\users\\adria\\miniconda3\\envs\\scraper\\lib\\site-packages\\tqdm\\asyncio.py\", line 76, in wrap_awaitable\n",
      "    return i, await f\n",
      "  File \"C:\\Users\\adria\\AppData\\Local\\Temp\\ipykernel_27608\\3299729886.py\", line 22, in checker\n",
      "    async with session.get(url, allow_redirects=True, ssl=False, raise_for_status=True, timeout=100, headers=headers) as r:\n",
      "  File \"c:\\users\\adria\\miniconda3\\envs\\scraper\\lib\\site-packages\\aiohttp\\client.py\", line 1141, in __aenter__\n",
      "    self._resp = await self._coro\n",
      "  File \"c:\\users\\adria\\miniconda3\\envs\\scraper\\lib\\site-packages\\aiohttp\\client.py\", line 536, in _request\n",
      "    conn = await self._connector.connect(\n",
      "  File \"c:\\users\\adria\\miniconda3\\envs\\scraper\\lib\\site-packages\\aiohttp\\connector.py\", line 543, in connect\n",
      "    raise ClientConnectionError(\"Connector is closed.\")\n",
      "aiohttp.client_exceptions.ClientConnectionError: Connector is closed.\n",
      "Task exception was never retrieved\n",
      "future: <Task finished name='Task-28369' coro=<tqdm_asyncio.gather.<locals>.wrap_awaitable() done, defined at c:\\users\\adria\\miniconda3\\envs\\scraper\\lib\\site-packages\\tqdm\\asyncio.py:75> exception=ClientConnectionError('Connector is closed.')>\n",
      "Traceback (most recent call last):\n",
      "  File \"c:\\users\\adria\\miniconda3\\envs\\scraper\\lib\\site-packages\\tqdm\\asyncio.py\", line 76, in wrap_awaitable\n",
      "    return i, await f\n",
      "  File \"C:\\Users\\adria\\AppData\\Local\\Temp\\ipykernel_27608\\3299729886.py\", line 22, in checker\n",
      "    async with session.get(url, allow_redirects=True, ssl=False, raise_for_status=True, timeout=100, headers=headers) as r:\n",
      "  File \"c:\\users\\adria\\miniconda3\\envs\\scraper\\lib\\site-packages\\aiohttp\\client.py\", line 1141, in __aenter__\n",
      "    self._resp = await self._coro\n",
      "  File \"c:\\users\\adria\\miniconda3\\envs\\scraper\\lib\\site-packages\\aiohttp\\client.py\", line 536, in _request\n",
      "    conn = await self._connector.connect(\n",
      "  File \"c:\\users\\adria\\miniconda3\\envs\\scraper\\lib\\site-packages\\aiohttp\\connector.py\", line 543, in connect\n",
      "    raise ClientConnectionError(\"Connector is closed.\")\n",
      "aiohttp.client_exceptions.ClientConnectionError: Connector is closed.\n",
      "Task exception was never retrieved\n",
      "future: <Task finished name='Task-30594' coro=<tqdm_asyncio.gather.<locals>.wrap_awaitable() done, defined at c:\\users\\adria\\miniconda3\\envs\\scraper\\lib\\site-packages\\tqdm\\asyncio.py:75> exception=ClientConnectionError('Connector is closed.')>\n",
      "Traceback (most recent call last):\n",
      "  File \"c:\\users\\adria\\miniconda3\\envs\\scraper\\lib\\site-packages\\tqdm\\asyncio.py\", line 76, in wrap_awaitable\n",
      "    return i, await f\n",
      "  File \"C:\\Users\\adria\\AppData\\Local\\Temp\\ipykernel_27608\\3299729886.py\", line 22, in checker\n",
      "    async with session.get(url, allow_redirects=True, ssl=False, raise_for_status=True, timeout=100, headers=headers) as r:\n",
      "  File \"c:\\users\\adria\\miniconda3\\envs\\scraper\\lib\\site-packages\\aiohttp\\client.py\", line 1141, in __aenter__\n",
      "    self._resp = await self._coro\n",
      "  File \"c:\\users\\adria\\miniconda3\\envs\\scraper\\lib\\site-packages\\aiohttp\\client.py\", line 536, in _request\n",
      "    conn = await self._connector.connect(\n",
      "  File \"c:\\users\\adria\\miniconda3\\envs\\scraper\\lib\\site-packages\\aiohttp\\connector.py\", line 543, in connect\n",
      "    raise ClientConnectionError(\"Connector is closed.\")\n",
      "aiohttp.client_exceptions.ClientConnectionError: Connector is closed.\n",
      "Task exception was never retrieved\n",
      "future: <Task finished name='Task-29683' coro=<tqdm_asyncio.gather.<locals>.wrap_awaitable() done, defined at c:\\users\\adria\\miniconda3\\envs\\scraper\\lib\\site-packages\\tqdm\\asyncio.py:75> exception=ClientConnectionError('Connector is closed.')>\n",
      "Traceback (most recent call last):\n",
      "  File \"c:\\users\\adria\\miniconda3\\envs\\scraper\\lib\\site-packages\\tqdm\\asyncio.py\", line 76, in wrap_awaitable\n",
      "    return i, await f\n",
      "  File \"C:\\Users\\adria\\AppData\\Local\\Temp\\ipykernel_27608\\3299729886.py\", line 22, in checker\n",
      "    async with session.get(url, allow_redirects=True, ssl=False, raise_for_status=True, timeout=100, headers=headers) as r:\n",
      "  File \"c:\\users\\adria\\miniconda3\\envs\\scraper\\lib\\site-packages\\aiohttp\\client.py\", line 1141, in __aenter__\n",
      "    self._resp = await self._coro\n",
      "  File \"c:\\users\\adria\\miniconda3\\envs\\scraper\\lib\\site-packages\\aiohttp\\client.py\", line 536, in _request\n",
      "    conn = await self._connector.connect(\n",
      "  File \"c:\\users\\adria\\miniconda3\\envs\\scraper\\lib\\site-packages\\aiohttp\\connector.py\", line 543, in connect\n",
      "    raise ClientConnectionError(\"Connector is closed.\")\n",
      "aiohttp.client_exceptions.ClientConnectionError: Connector is closed.\n",
      "Task exception was never retrieved\n",
      "future: <Task finished name='Task-26542' coro=<tqdm_asyncio.gather.<locals>.wrap_awaitable() done, defined at c:\\users\\adria\\miniconda3\\envs\\scraper\\lib\\site-packages\\tqdm\\asyncio.py:75> exception=ClientConnectionError('Connector is closed.')>\n",
      "Traceback (most recent call last):\n",
      "  File \"c:\\users\\adria\\miniconda3\\envs\\scraper\\lib\\site-packages\\tqdm\\asyncio.py\", line 76, in wrap_awaitable\n",
      "    return i, await f\n",
      "  File \"C:\\Users\\adria\\AppData\\Local\\Temp\\ipykernel_27608\\3299729886.py\", line 22, in checker\n",
      "    async with session.get(url, allow_redirects=True, ssl=False, raise_for_status=True, timeout=100, headers=headers) as r:\n",
      "  File \"c:\\users\\adria\\miniconda3\\envs\\scraper\\lib\\site-packages\\aiohttp\\client.py\", line 1141, in __aenter__\n",
      "    self._resp = await self._coro\n",
      "  File \"c:\\users\\adria\\miniconda3\\envs\\scraper\\lib\\site-packages\\aiohttp\\client.py\", line 536, in _request\n",
      "    conn = await self._connector.connect(\n",
      "  File \"c:\\users\\adria\\miniconda3\\envs\\scraper\\lib\\site-packages\\aiohttp\\connector.py\", line 543, in connect\n",
      "    raise ClientConnectionError(\"Connector is closed.\")\n",
      "aiohttp.client_exceptions.ClientConnectionError: Connector is closed.\n",
      "Task exception was never retrieved\n",
      "future: <Task finished name='Task-27473' coro=<tqdm_asyncio.gather.<locals>.wrap_awaitable() done, defined at c:\\users\\adria\\miniconda3\\envs\\scraper\\lib\\site-packages\\tqdm\\asyncio.py:75> exception=ClientConnectionError('Connector is closed.')>\n",
      "Traceback (most recent call last):\n",
      "  File \"c:\\users\\adria\\miniconda3\\envs\\scraper\\lib\\site-packages\\tqdm\\asyncio.py\", line 76, in wrap_awaitable\n",
      "    return i, await f\n",
      "  File \"C:\\Users\\adria\\AppData\\Local\\Temp\\ipykernel_27608\\3299729886.py\", line 22, in checker\n",
      "    async with session.get(url, allow_redirects=True, ssl=False, raise_for_status=True, timeout=100, headers=headers) as r:\n",
      "  File \"c:\\users\\adria\\miniconda3\\envs\\scraper\\lib\\site-packages\\aiohttp\\client.py\", line 1141, in __aenter__\n",
      "    self._resp = await self._coro\n",
      "  File \"c:\\users\\adria\\miniconda3\\envs\\scraper\\lib\\site-packages\\aiohttp\\client.py\", line 536, in _request\n",
      "    conn = await self._connector.connect(\n",
      "  File \"c:\\users\\adria\\miniconda3\\envs\\scraper\\lib\\site-packages\\aiohttp\\connector.py\", line 543, in connect\n",
      "    raise ClientConnectionError(\"Connector is closed.\")\n",
      "aiohttp.client_exceptions.ClientConnectionError: Connector is closed.\n"
     ]
    },
    {
     "name": "stderr",
     "output_type": "stream",
     "text": [
      "Task exception was never retrieved\n",
      "future: <Task finished name='Task-30244' coro=<tqdm_asyncio.gather.<locals>.wrap_awaitable() done, defined at c:\\users\\adria\\miniconda3\\envs\\scraper\\lib\\site-packages\\tqdm\\asyncio.py:75> exception=ClientConnectionError('Connector is closed.')>\n",
      "Traceback (most recent call last):\n",
      "  File \"c:\\users\\adria\\miniconda3\\envs\\scraper\\lib\\site-packages\\tqdm\\asyncio.py\", line 76, in wrap_awaitable\n",
      "    return i, await f\n",
      "  File \"C:\\Users\\adria\\AppData\\Local\\Temp\\ipykernel_27608\\3299729886.py\", line 22, in checker\n",
      "    async with session.get(url, allow_redirects=True, ssl=False, raise_for_status=True, timeout=100, headers=headers) as r:\n",
      "  File \"c:\\users\\adria\\miniconda3\\envs\\scraper\\lib\\site-packages\\aiohttp\\client.py\", line 1141, in __aenter__\n",
      "    self._resp = await self._coro\n",
      "  File \"c:\\users\\adria\\miniconda3\\envs\\scraper\\lib\\site-packages\\aiohttp\\client.py\", line 536, in _request\n",
      "    conn = await self._connector.connect(\n",
      "  File \"c:\\users\\adria\\miniconda3\\envs\\scraper\\lib\\site-packages\\aiohttp\\connector.py\", line 543, in connect\n",
      "    raise ClientConnectionError(\"Connector is closed.\")\n",
      "aiohttp.client_exceptions.ClientConnectionError: Connector is closed.\n",
      "Task exception was never retrieved\n",
      "future: <Task finished name='Task-29702' coro=<tqdm_asyncio.gather.<locals>.wrap_awaitable() done, defined at c:\\users\\adria\\miniconda3\\envs\\scraper\\lib\\site-packages\\tqdm\\asyncio.py:75> exception=ClientConnectionError('Connector is closed.')>\n",
      "Traceback (most recent call last):\n",
      "  File \"c:\\users\\adria\\miniconda3\\envs\\scraper\\lib\\site-packages\\tqdm\\asyncio.py\", line 76, in wrap_awaitable\n",
      "    return i, await f\n",
      "  File \"C:\\Users\\adria\\AppData\\Local\\Temp\\ipykernel_27608\\3299729886.py\", line 22, in checker\n",
      "    async with session.get(url, allow_redirects=True, ssl=False, raise_for_status=True, timeout=100, headers=headers) as r:\n",
      "  File \"c:\\users\\adria\\miniconda3\\envs\\scraper\\lib\\site-packages\\aiohttp\\client.py\", line 1141, in __aenter__\n",
      "    self._resp = await self._coro\n",
      "  File \"c:\\users\\adria\\miniconda3\\envs\\scraper\\lib\\site-packages\\aiohttp\\client.py\", line 536, in _request\n",
      "    conn = await self._connector.connect(\n",
      "  File \"c:\\users\\adria\\miniconda3\\envs\\scraper\\lib\\site-packages\\aiohttp\\connector.py\", line 543, in connect\n",
      "    raise ClientConnectionError(\"Connector is closed.\")\n",
      "aiohttp.client_exceptions.ClientConnectionError: Connector is closed.\n",
      "Task exception was never retrieved\n",
      "future: <Task finished name='Task-30805' coro=<tqdm_asyncio.gather.<locals>.wrap_awaitable() done, defined at c:\\users\\adria\\miniconda3\\envs\\scraper\\lib\\site-packages\\tqdm\\asyncio.py:75> exception=ClientConnectionError('Connector is closed.')>\n",
      "Traceback (most recent call last):\n",
      "  File \"c:\\users\\adria\\miniconda3\\envs\\scraper\\lib\\site-packages\\tqdm\\asyncio.py\", line 76, in wrap_awaitable\n",
      "    return i, await f\n",
      "  File \"C:\\Users\\adria\\AppData\\Local\\Temp\\ipykernel_27608\\3299729886.py\", line 22, in checker\n",
      "    async with session.get(url, allow_redirects=True, ssl=False, raise_for_status=True, timeout=100, headers=headers) as r:\n",
      "  File \"c:\\users\\adria\\miniconda3\\envs\\scraper\\lib\\site-packages\\aiohttp\\client.py\", line 1141, in __aenter__\n",
      "    self._resp = await self._coro\n",
      "  File \"c:\\users\\adria\\miniconda3\\envs\\scraper\\lib\\site-packages\\aiohttp\\client.py\", line 536, in _request\n",
      "    conn = await self._connector.connect(\n",
      "  File \"c:\\users\\adria\\miniconda3\\envs\\scraper\\lib\\site-packages\\aiohttp\\connector.py\", line 543, in connect\n",
      "    raise ClientConnectionError(\"Connector is closed.\")\n",
      "aiohttp.client_exceptions.ClientConnectionError: Connector is closed.\n",
      "Task exception was never retrieved\n",
      "future: <Task finished name='Task-30817' coro=<tqdm_asyncio.gather.<locals>.wrap_awaitable() done, defined at c:\\users\\adria\\miniconda3\\envs\\scraper\\lib\\site-packages\\tqdm\\asyncio.py:75> exception=ClientConnectionError('Connector is closed.')>\n",
      "Traceback (most recent call last):\n",
      "  File \"c:\\users\\adria\\miniconda3\\envs\\scraper\\lib\\site-packages\\tqdm\\asyncio.py\", line 76, in wrap_awaitable\n",
      "    return i, await f\n",
      "  File \"C:\\Users\\adria\\AppData\\Local\\Temp\\ipykernel_27608\\3299729886.py\", line 22, in checker\n",
      "    async with session.get(url, allow_redirects=True, ssl=False, raise_for_status=True, timeout=100, headers=headers) as r:\n",
      "  File \"c:\\users\\adria\\miniconda3\\envs\\scraper\\lib\\site-packages\\aiohttp\\client.py\", line 1141, in __aenter__\n",
      "    self._resp = await self._coro\n",
      "  File \"c:\\users\\adria\\miniconda3\\envs\\scraper\\lib\\site-packages\\aiohttp\\client.py\", line 536, in _request\n",
      "    conn = await self._connector.connect(\n",
      "  File \"c:\\users\\adria\\miniconda3\\envs\\scraper\\lib\\site-packages\\aiohttp\\connector.py\", line 543, in connect\n",
      "    raise ClientConnectionError(\"Connector is closed.\")\n",
      "aiohttp.client_exceptions.ClientConnectionError: Connector is closed.\n",
      "Task exception was never retrieved\n",
      "future: <Task finished name='Task-31287' coro=<tqdm_asyncio.gather.<locals>.wrap_awaitable() done, defined at c:\\users\\adria\\miniconda3\\envs\\scraper\\lib\\site-packages\\tqdm\\asyncio.py:75> exception=ClientConnectionError('Connector is closed.')>\n",
      "Traceback (most recent call last):\n",
      "  File \"c:\\users\\adria\\miniconda3\\envs\\scraper\\lib\\site-packages\\tqdm\\asyncio.py\", line 76, in wrap_awaitable\n",
      "    return i, await f\n",
      "  File \"C:\\Users\\adria\\AppData\\Local\\Temp\\ipykernel_27608\\3299729886.py\", line 22, in checker\n",
      "    async with session.get(url, allow_redirects=True, ssl=False, raise_for_status=True, timeout=100, headers=headers) as r:\n",
      "  File \"c:\\users\\adria\\miniconda3\\envs\\scraper\\lib\\site-packages\\aiohttp\\client.py\", line 1141, in __aenter__\n",
      "    self._resp = await self._coro\n",
      "  File \"c:\\users\\adria\\miniconda3\\envs\\scraper\\lib\\site-packages\\aiohttp\\client.py\", line 536, in _request\n",
      "    conn = await self._connector.connect(\n",
      "  File \"c:\\users\\adria\\miniconda3\\envs\\scraper\\lib\\site-packages\\aiohttp\\connector.py\", line 543, in connect\n",
      "    raise ClientConnectionError(\"Connector is closed.\")\n",
      "aiohttp.client_exceptions.ClientConnectionError: Connector is closed.\n",
      "Task exception was never retrieved\n",
      "future: <Task finished name='Task-26972' coro=<tqdm_asyncio.gather.<locals>.wrap_awaitable() done, defined at c:\\users\\adria\\miniconda3\\envs\\scraper\\lib\\site-packages\\tqdm\\asyncio.py:75> exception=ClientConnectionError('Connector is closed.')>\n",
      "Traceback (most recent call last):\n",
      "  File \"c:\\users\\adria\\miniconda3\\envs\\scraper\\lib\\site-packages\\tqdm\\asyncio.py\", line 76, in wrap_awaitable\n",
      "    return i, await f\n",
      "  File \"C:\\Users\\adria\\AppData\\Local\\Temp\\ipykernel_27608\\3299729886.py\", line 22, in checker\n",
      "    async with session.get(url, allow_redirects=True, ssl=False, raise_for_status=True, timeout=100, headers=headers) as r:\n",
      "  File \"c:\\users\\adria\\miniconda3\\envs\\scraper\\lib\\site-packages\\aiohttp\\client.py\", line 1141, in __aenter__\n",
      "    self._resp = await self._coro\n",
      "  File \"c:\\users\\adria\\miniconda3\\envs\\scraper\\lib\\site-packages\\aiohttp\\client.py\", line 536, in _request\n",
      "    conn = await self._connector.connect(\n",
      "  File \"c:\\users\\adria\\miniconda3\\envs\\scraper\\lib\\site-packages\\aiohttp\\connector.py\", line 543, in connect\n",
      "    raise ClientConnectionError(\"Connector is closed.\")\n",
      "aiohttp.client_exceptions.ClientConnectionError: Connector is closed.\n",
      "Task exception was never retrieved\n",
      "future: <Task finished name='Task-29732' coro=<tqdm_asyncio.gather.<locals>.wrap_awaitable() done, defined at c:\\users\\adria\\miniconda3\\envs\\scraper\\lib\\site-packages\\tqdm\\asyncio.py:75> exception=ClientConnectionError('Connector is closed.')>\n",
      "Traceback (most recent call last):\n",
      "  File \"c:\\users\\adria\\miniconda3\\envs\\scraper\\lib\\site-packages\\tqdm\\asyncio.py\", line 76, in wrap_awaitable\n",
      "    return i, await f\n",
      "  File \"C:\\Users\\adria\\AppData\\Local\\Temp\\ipykernel_27608\\3299729886.py\", line 22, in checker\n",
      "    async with session.get(url, allow_redirects=True, ssl=False, raise_for_status=True, timeout=100, headers=headers) as r:\n",
      "  File \"c:\\users\\adria\\miniconda3\\envs\\scraper\\lib\\site-packages\\aiohttp\\client.py\", line 1141, in __aenter__\n",
      "    self._resp = await self._coro\n",
      "  File \"c:\\users\\adria\\miniconda3\\envs\\scraper\\lib\\site-packages\\aiohttp\\client.py\", line 536, in _request\n",
      "    conn = await self._connector.connect(\n",
      "  File \"c:\\users\\adria\\miniconda3\\envs\\scraper\\lib\\site-packages\\aiohttp\\connector.py\", line 543, in connect\n",
      "    raise ClientConnectionError(\"Connector is closed.\")\n",
      "aiohttp.client_exceptions.ClientConnectionError: Connector is closed.\n"
     ]
    },
    {
     "name": "stderr",
     "output_type": "stream",
     "text": [
      "Task exception was never retrieved\n",
      "future: <Task finished name='Task-27361' coro=<tqdm_asyncio.gather.<locals>.wrap_awaitable() done, defined at c:\\users\\adria\\miniconda3\\envs\\scraper\\lib\\site-packages\\tqdm\\asyncio.py:75> exception=ClientConnectionError('Connector is closed.')>\n",
      "Traceback (most recent call last):\n",
      "  File \"c:\\users\\adria\\miniconda3\\envs\\scraper\\lib\\site-packages\\tqdm\\asyncio.py\", line 76, in wrap_awaitable\n",
      "    return i, await f\n",
      "  File \"C:\\Users\\adria\\AppData\\Local\\Temp\\ipykernel_27608\\3299729886.py\", line 22, in checker\n",
      "    async with session.get(url, allow_redirects=True, ssl=False, raise_for_status=True, timeout=100, headers=headers) as r:\n",
      "  File \"c:\\users\\adria\\miniconda3\\envs\\scraper\\lib\\site-packages\\aiohttp\\client.py\", line 1141, in __aenter__\n",
      "    self._resp = await self._coro\n",
      "  File \"c:\\users\\adria\\miniconda3\\envs\\scraper\\lib\\site-packages\\aiohttp\\client.py\", line 536, in _request\n",
      "    conn = await self._connector.connect(\n",
      "  File \"c:\\users\\adria\\miniconda3\\envs\\scraper\\lib\\site-packages\\aiohttp\\connector.py\", line 543, in connect\n",
      "    raise ClientConnectionError(\"Connector is closed.\")\n",
      "aiohttp.client_exceptions.ClientConnectionError: Connector is closed.\n",
      "Task exception was never retrieved\n",
      "future: <Task finished name='Task-26484' coro=<tqdm_asyncio.gather.<locals>.wrap_awaitable() done, defined at c:\\users\\adria\\miniconda3\\envs\\scraper\\lib\\site-packages\\tqdm\\asyncio.py:75> exception=ClientOSError(1, '[SSL: APPLICATION_DATA_AFTER_CLOSE_NOTIFY] application data after close notify (_ssl.c:2747)')>\n",
      "Traceback (most recent call last):\n",
      "  File \"c:\\users\\adria\\miniconda3\\envs\\scraper\\lib\\site-packages\\tqdm\\asyncio.py\", line 76, in wrap_awaitable\n",
      "    return i, await f\n",
      "  File \"C:\\Users\\adria\\AppData\\Local\\Temp\\ipykernel_27608\\3299729886.py\", line 22, in checker\n",
      "    async with session.get(url, allow_redirects=True, ssl=False, raise_for_status=True, timeout=100, headers=headers) as r:\n",
      "  File \"c:\\users\\adria\\miniconda3\\envs\\scraper\\lib\\site-packages\\aiohttp\\client.py\", line 1141, in __aenter__\n",
      "    self._resp = await self._coro\n",
      "  File \"c:\\users\\adria\\miniconda3\\envs\\scraper\\lib\\site-packages\\aiohttp\\client.py\", line 560, in _request\n",
      "    await resp.start(conn)\n",
      "  File \"c:\\users\\adria\\miniconda3\\envs\\scraper\\lib\\site-packages\\aiohttp\\client_reqrep.py\", line 899, in start\n",
      "    message, payload = await protocol.read()  # type: ignore[union-attr]\n",
      "  File \"c:\\users\\adria\\miniconda3\\envs\\scraper\\lib\\site-packages\\aiohttp\\streams.py\", line 616, in read\n",
      "    await self._waiter\n",
      "aiohttp.client_exceptions.ClientOSError: [Errno 1] [SSL: APPLICATION_DATA_AFTER_CLOSE_NOTIFY] application data after close notify (_ssl.c:2747)\n",
      "Task exception was never retrieved\n",
      "future: <Task finished name='Task-30733' coro=<tqdm_asyncio.gather.<locals>.wrap_awaitable() done, defined at c:\\users\\adria\\miniconda3\\envs\\scraper\\lib\\site-packages\\tqdm\\asyncio.py:75> exception=ClientConnectionError('Connector is closed.')>\n",
      "Traceback (most recent call last):\n",
      "  File \"c:\\users\\adria\\miniconda3\\envs\\scraper\\lib\\site-packages\\tqdm\\asyncio.py\", line 76, in wrap_awaitable\n",
      "    return i, await f\n",
      "  File \"C:\\Users\\adria\\AppData\\Local\\Temp\\ipykernel_27608\\3299729886.py\", line 22, in checker\n",
      "    async with session.get(url, allow_redirects=True, ssl=False, raise_for_status=True, timeout=100, headers=headers) as r:\n",
      "  File \"c:\\users\\adria\\miniconda3\\envs\\scraper\\lib\\site-packages\\aiohttp\\client.py\", line 1141, in __aenter__\n",
      "    self._resp = await self._coro\n",
      "  File \"c:\\users\\adria\\miniconda3\\envs\\scraper\\lib\\site-packages\\aiohttp\\client.py\", line 536, in _request\n",
      "    conn = await self._connector.connect(\n",
      "  File \"c:\\users\\adria\\miniconda3\\envs\\scraper\\lib\\site-packages\\aiohttp\\connector.py\", line 543, in connect\n",
      "    raise ClientConnectionError(\"Connector is closed.\")\n",
      "aiohttp.client_exceptions.ClientConnectionError: Connector is closed.\n",
      "Task exception was never retrieved\n",
      "future: <Task finished name='Task-27076' coro=<tqdm_asyncio.gather.<locals>.wrap_awaitable() done, defined at c:\\users\\adria\\miniconda3\\envs\\scraper\\lib\\site-packages\\tqdm\\asyncio.py:75> exception=ClientConnectionError('Connector is closed.')>\n",
      "Traceback (most recent call last):\n",
      "  File \"c:\\users\\adria\\miniconda3\\envs\\scraper\\lib\\site-packages\\tqdm\\asyncio.py\", line 76, in wrap_awaitable\n",
      "    return i, await f\n",
      "  File \"C:\\Users\\adria\\AppData\\Local\\Temp\\ipykernel_27608\\3299729886.py\", line 22, in checker\n",
      "    async with session.get(url, allow_redirects=True, ssl=False, raise_for_status=True, timeout=100, headers=headers) as r:\n",
      "  File \"c:\\users\\adria\\miniconda3\\envs\\scraper\\lib\\site-packages\\aiohttp\\client.py\", line 1141, in __aenter__\n",
      "    self._resp = await self._coro\n",
      "  File \"c:\\users\\adria\\miniconda3\\envs\\scraper\\lib\\site-packages\\aiohttp\\client.py\", line 536, in _request\n",
      "    conn = await self._connector.connect(\n",
      "  File \"c:\\users\\adria\\miniconda3\\envs\\scraper\\lib\\site-packages\\aiohttp\\connector.py\", line 543, in connect\n",
      "    raise ClientConnectionError(\"Connector is closed.\")\n",
      "aiohttp.client_exceptions.ClientConnectionError: Connector is closed.\n",
      "Task exception was never retrieved\n",
      "future: <Task finished name='Task-30631' coro=<tqdm_asyncio.gather.<locals>.wrap_awaitable() done, defined at c:\\users\\adria\\miniconda3\\envs\\scraper\\lib\\site-packages\\tqdm\\asyncio.py:75> exception=ClientConnectionError('Connector is closed.')>\n",
      "Traceback (most recent call last):\n",
      "  File \"c:\\users\\adria\\miniconda3\\envs\\scraper\\lib\\site-packages\\tqdm\\asyncio.py\", line 76, in wrap_awaitable\n",
      "    return i, await f\n",
      "  File \"C:\\Users\\adria\\AppData\\Local\\Temp\\ipykernel_27608\\3299729886.py\", line 22, in checker\n",
      "    async with session.get(url, allow_redirects=True, ssl=False, raise_for_status=True, timeout=100, headers=headers) as r:\n",
      "  File \"c:\\users\\adria\\miniconda3\\envs\\scraper\\lib\\site-packages\\aiohttp\\client.py\", line 1141, in __aenter__\n",
      "    self._resp = await self._coro\n",
      "  File \"c:\\users\\adria\\miniconda3\\envs\\scraper\\lib\\site-packages\\aiohttp\\client.py\", line 536, in _request\n",
      "    conn = await self._connector.connect(\n",
      "  File \"c:\\users\\adria\\miniconda3\\envs\\scraper\\lib\\site-packages\\aiohttp\\connector.py\", line 543, in connect\n",
      "    raise ClientConnectionError(\"Connector is closed.\")\n",
      "aiohttp.client_exceptions.ClientConnectionError: Connector is closed.\n",
      "Task exception was never retrieved\n",
      "future: <Task finished name='Task-30243' coro=<tqdm_asyncio.gather.<locals>.wrap_awaitable() done, defined at c:\\users\\adria\\miniconda3\\envs\\scraper\\lib\\site-packages\\tqdm\\asyncio.py:75> exception=ClientConnectionError('Connector is closed.')>\n",
      "Traceback (most recent call last):\n",
      "  File \"c:\\users\\adria\\miniconda3\\envs\\scraper\\lib\\site-packages\\tqdm\\asyncio.py\", line 76, in wrap_awaitable\n",
      "    return i, await f\n",
      "  File \"C:\\Users\\adria\\AppData\\Local\\Temp\\ipykernel_27608\\3299729886.py\", line 22, in checker\n",
      "    async with session.get(url, allow_redirects=True, ssl=False, raise_for_status=True, timeout=100, headers=headers) as r:\n",
      "  File \"c:\\users\\adria\\miniconda3\\envs\\scraper\\lib\\site-packages\\aiohttp\\client.py\", line 1141, in __aenter__\n",
      "    self._resp = await self._coro\n",
      "  File \"c:\\users\\adria\\miniconda3\\envs\\scraper\\lib\\site-packages\\aiohttp\\client.py\", line 536, in _request\n",
      "    conn = await self._connector.connect(\n",
      "  File \"c:\\users\\adria\\miniconda3\\envs\\scraper\\lib\\site-packages\\aiohttp\\connector.py\", line 543, in connect\n",
      "    raise ClientConnectionError(\"Connector is closed.\")\n",
      "aiohttp.client_exceptions.ClientConnectionError: Connector is closed.\n",
      "Task exception was never retrieved\n",
      "future: <Task finished name='Task-29947' coro=<tqdm_asyncio.gather.<locals>.wrap_awaitable() done, defined at c:\\users\\adria\\miniconda3\\envs\\scraper\\lib\\site-packages\\tqdm\\asyncio.py:75> exception=ClientConnectionError('Connector is closed.')>\n",
      "Traceback (most recent call last):\n",
      "  File \"c:\\users\\adria\\miniconda3\\envs\\scraper\\lib\\site-packages\\tqdm\\asyncio.py\", line 76, in wrap_awaitable\n",
      "    return i, await f\n",
      "  File \"C:\\Users\\adria\\AppData\\Local\\Temp\\ipykernel_27608\\3299729886.py\", line 22, in checker\n",
      "    async with session.get(url, allow_redirects=True, ssl=False, raise_for_status=True, timeout=100, headers=headers) as r:\n",
      "  File \"c:\\users\\adria\\miniconda3\\envs\\scraper\\lib\\site-packages\\aiohttp\\client.py\", line 1141, in __aenter__\n",
      "    self._resp = await self._coro\n",
      "  File \"c:\\users\\adria\\miniconda3\\envs\\scraper\\lib\\site-packages\\aiohttp\\client.py\", line 536, in _request\n",
      "    conn = await self._connector.connect(\n",
      "  File \"c:\\users\\adria\\miniconda3\\envs\\scraper\\lib\\site-packages\\aiohttp\\connector.py\", line 543, in connect\n",
      "    raise ClientConnectionError(\"Connector is closed.\")\n",
      "aiohttp.client_exceptions.ClientConnectionError: Connector is closed.\n"
     ]
    },
    {
     "name": "stderr",
     "output_type": "stream",
     "text": [
      "Task exception was never retrieved\n",
      "future: <Task finished name='Task-29279' coro=<tqdm_asyncio.gather.<locals>.wrap_awaitable() done, defined at c:\\users\\adria\\miniconda3\\envs\\scraper\\lib\\site-packages\\tqdm\\asyncio.py:75> exception=ClientConnectionError('Connector is closed.')>\n",
      "Traceback (most recent call last):\n",
      "  File \"c:\\users\\adria\\miniconda3\\envs\\scraper\\lib\\site-packages\\tqdm\\asyncio.py\", line 76, in wrap_awaitable\n",
      "    return i, await f\n",
      "  File \"C:\\Users\\adria\\AppData\\Local\\Temp\\ipykernel_27608\\3299729886.py\", line 22, in checker\n",
      "    async with session.get(url, allow_redirects=True, ssl=False, raise_for_status=True, timeout=100, headers=headers) as r:\n",
      "  File \"c:\\users\\adria\\miniconda3\\envs\\scraper\\lib\\site-packages\\aiohttp\\client.py\", line 1141, in __aenter__\n",
      "    self._resp = await self._coro\n",
      "  File \"c:\\users\\adria\\miniconda3\\envs\\scraper\\lib\\site-packages\\aiohttp\\client.py\", line 536, in _request\n",
      "    conn = await self._connector.connect(\n",
      "  File \"c:\\users\\adria\\miniconda3\\envs\\scraper\\lib\\site-packages\\aiohttp\\connector.py\", line 543, in connect\n",
      "    raise ClientConnectionError(\"Connector is closed.\")\n",
      "aiohttp.client_exceptions.ClientConnectionError: Connector is closed.\n",
      "Task exception was never retrieved\n",
      "future: <Task finished name='Task-26541' coro=<tqdm_asyncio.gather.<locals>.wrap_awaitable() done, defined at c:\\users\\adria\\miniconda3\\envs\\scraper\\lib\\site-packages\\tqdm\\asyncio.py:75> exception=ClientConnectionError('Connector is closed.')>\n",
      "Traceback (most recent call last):\n",
      "  File \"c:\\users\\adria\\miniconda3\\envs\\scraper\\lib\\site-packages\\tqdm\\asyncio.py\", line 76, in wrap_awaitable\n",
      "    return i, await f\n",
      "  File \"C:\\Users\\adria\\AppData\\Local\\Temp\\ipykernel_27608\\3299729886.py\", line 22, in checker\n",
      "    async with session.get(url, allow_redirects=True, ssl=False, raise_for_status=True, timeout=100, headers=headers) as r:\n",
      "  File \"c:\\users\\adria\\miniconda3\\envs\\scraper\\lib\\site-packages\\aiohttp\\client.py\", line 1141, in __aenter__\n",
      "    self._resp = await self._coro\n",
      "  File \"c:\\users\\adria\\miniconda3\\envs\\scraper\\lib\\site-packages\\aiohttp\\client.py\", line 536, in _request\n",
      "    conn = await self._connector.connect(\n",
      "  File \"c:\\users\\adria\\miniconda3\\envs\\scraper\\lib\\site-packages\\aiohttp\\connector.py\", line 543, in connect\n",
      "    raise ClientConnectionError(\"Connector is closed.\")\n",
      "aiohttp.client_exceptions.ClientConnectionError: Connector is closed.\n",
      "Task exception was never retrieved\n",
      "future: <Task finished name='Task-27346' coro=<tqdm_asyncio.gather.<locals>.wrap_awaitable() done, defined at c:\\users\\adria\\miniconda3\\envs\\scraper\\lib\\site-packages\\tqdm\\asyncio.py:75> exception=ClientConnectionError('Connector is closed.')>\n",
      "Traceback (most recent call last):\n",
      "  File \"c:\\users\\adria\\miniconda3\\envs\\scraper\\lib\\site-packages\\tqdm\\asyncio.py\", line 76, in wrap_awaitable\n",
      "    return i, await f\n",
      "  File \"C:\\Users\\adria\\AppData\\Local\\Temp\\ipykernel_27608\\3299729886.py\", line 22, in checker\n",
      "    async with session.get(url, allow_redirects=True, ssl=False, raise_for_status=True, timeout=100, headers=headers) as r:\n",
      "  File \"c:\\users\\adria\\miniconda3\\envs\\scraper\\lib\\site-packages\\aiohttp\\client.py\", line 1141, in __aenter__\n",
      "    self._resp = await self._coro\n",
      "  File \"c:\\users\\adria\\miniconda3\\envs\\scraper\\lib\\site-packages\\aiohttp\\client.py\", line 536, in _request\n",
      "    conn = await self._connector.connect(\n",
      "  File \"c:\\users\\adria\\miniconda3\\envs\\scraper\\lib\\site-packages\\aiohttp\\connector.py\", line 543, in connect\n",
      "    raise ClientConnectionError(\"Connector is closed.\")\n",
      "aiohttp.client_exceptions.ClientConnectionError: Connector is closed.\n",
      "Task exception was never retrieved\n",
      "future: <Task finished name='Task-31170' coro=<tqdm_asyncio.gather.<locals>.wrap_awaitable() done, defined at c:\\users\\adria\\miniconda3\\envs\\scraper\\lib\\site-packages\\tqdm\\asyncio.py:75> exception=ClientConnectionError('Connector is closed.')>\n",
      "Traceback (most recent call last):\n",
      "  File \"c:\\users\\adria\\miniconda3\\envs\\scraper\\lib\\site-packages\\tqdm\\asyncio.py\", line 76, in wrap_awaitable\n",
      "    return i, await f\n",
      "  File \"C:\\Users\\adria\\AppData\\Local\\Temp\\ipykernel_27608\\3299729886.py\", line 22, in checker\n",
      "    async with session.get(url, allow_redirects=True, ssl=False, raise_for_status=True, timeout=100, headers=headers) as r:\n",
      "  File \"c:\\users\\adria\\miniconda3\\envs\\scraper\\lib\\site-packages\\aiohttp\\client.py\", line 1141, in __aenter__\n",
      "    self._resp = await self._coro\n",
      "  File \"c:\\users\\adria\\miniconda3\\envs\\scraper\\lib\\site-packages\\aiohttp\\client.py\", line 536, in _request\n",
      "    conn = await self._connector.connect(\n",
      "  File \"c:\\users\\adria\\miniconda3\\envs\\scraper\\lib\\site-packages\\aiohttp\\connector.py\", line 543, in connect\n",
      "    raise ClientConnectionError(\"Connector is closed.\")\n",
      "aiohttp.client_exceptions.ClientConnectionError: Connector is closed.\n",
      "Task exception was never retrieved\n",
      "future: <Task finished name='Task-28622' coro=<tqdm_asyncio.gather.<locals>.wrap_awaitable() done, defined at c:\\users\\adria\\miniconda3\\envs\\scraper\\lib\\site-packages\\tqdm\\asyncio.py:75> exception=ClientConnectionError('Connector is closed.')>\n",
      "Traceback (most recent call last):\n",
      "  File \"c:\\users\\adria\\miniconda3\\envs\\scraper\\lib\\site-packages\\tqdm\\asyncio.py\", line 76, in wrap_awaitable\n",
      "    return i, await f\n",
      "  File \"C:\\Users\\adria\\AppData\\Local\\Temp\\ipykernel_27608\\3299729886.py\", line 22, in checker\n",
      "    async with session.get(url, allow_redirects=True, ssl=False, raise_for_status=True, timeout=100, headers=headers) as r:\n",
      "  File \"c:\\users\\adria\\miniconda3\\envs\\scraper\\lib\\site-packages\\aiohttp\\client.py\", line 1141, in __aenter__\n",
      "    self._resp = await self._coro\n",
      "  File \"c:\\users\\adria\\miniconda3\\envs\\scraper\\lib\\site-packages\\aiohttp\\client.py\", line 536, in _request\n",
      "    conn = await self._connector.connect(\n",
      "  File \"c:\\users\\adria\\miniconda3\\envs\\scraper\\lib\\site-packages\\aiohttp\\connector.py\", line 543, in connect\n",
      "    raise ClientConnectionError(\"Connector is closed.\")\n",
      "aiohttp.client_exceptions.ClientConnectionError: Connector is closed.\n",
      "Task exception was never retrieved\n",
      "future: <Task finished name='Task-28734' coro=<tqdm_asyncio.gather.<locals>.wrap_awaitable() done, defined at c:\\users\\adria\\miniconda3\\envs\\scraper\\lib\\site-packages\\tqdm\\asyncio.py:75> exception=ClientConnectionError('Connector is closed.')>\n",
      "Traceback (most recent call last):\n",
      "  File \"c:\\users\\adria\\miniconda3\\envs\\scraper\\lib\\site-packages\\tqdm\\asyncio.py\", line 76, in wrap_awaitable\n",
      "    return i, await f\n",
      "  File \"C:\\Users\\adria\\AppData\\Local\\Temp\\ipykernel_27608\\3299729886.py\", line 22, in checker\n",
      "    async with session.get(url, allow_redirects=True, ssl=False, raise_for_status=True, timeout=100, headers=headers) as r:\n",
      "  File \"c:\\users\\adria\\miniconda3\\envs\\scraper\\lib\\site-packages\\aiohttp\\client.py\", line 1141, in __aenter__\n",
      "    self._resp = await self._coro\n",
      "  File \"c:\\users\\adria\\miniconda3\\envs\\scraper\\lib\\site-packages\\aiohttp\\client.py\", line 536, in _request\n",
      "    conn = await self._connector.connect(\n",
      "  File \"c:\\users\\adria\\miniconda3\\envs\\scraper\\lib\\site-packages\\aiohttp\\connector.py\", line 543, in connect\n",
      "    raise ClientConnectionError(\"Connector is closed.\")\n",
      "aiohttp.client_exceptions.ClientConnectionError: Connector is closed.\n",
      "Task exception was never retrieved\n",
      "future: <Task finished name='Task-30680' coro=<tqdm_asyncio.gather.<locals>.wrap_awaitable() done, defined at c:\\users\\adria\\miniconda3\\envs\\scraper\\lib\\site-packages\\tqdm\\asyncio.py:75> exception=ClientConnectionError('Connector is closed.')>\n",
      "Traceback (most recent call last):\n",
      "  File \"c:\\users\\adria\\miniconda3\\envs\\scraper\\lib\\site-packages\\tqdm\\asyncio.py\", line 76, in wrap_awaitable\n",
      "    return i, await f\n",
      "  File \"C:\\Users\\adria\\AppData\\Local\\Temp\\ipykernel_27608\\3299729886.py\", line 22, in checker\n",
      "    async with session.get(url, allow_redirects=True, ssl=False, raise_for_status=True, timeout=100, headers=headers) as r:\n",
      "  File \"c:\\users\\adria\\miniconda3\\envs\\scraper\\lib\\site-packages\\aiohttp\\client.py\", line 1141, in __aenter__\n",
      "    self._resp = await self._coro\n",
      "  File \"c:\\users\\adria\\miniconda3\\envs\\scraper\\lib\\site-packages\\aiohttp\\client.py\", line 536, in _request\n",
      "    conn = await self._connector.connect(\n",
      "  File \"c:\\users\\adria\\miniconda3\\envs\\scraper\\lib\\site-packages\\aiohttp\\connector.py\", line 543, in connect\n",
      "    raise ClientConnectionError(\"Connector is closed.\")\n",
      "aiohttp.client_exceptions.ClientConnectionError: Connector is closed.\n"
     ]
    },
    {
     "name": "stderr",
     "output_type": "stream",
     "text": [
      "Task exception was never retrieved\n",
      "future: <Task finished name='Task-28529' coro=<tqdm_asyncio.gather.<locals>.wrap_awaitable() done, defined at c:\\users\\adria\\miniconda3\\envs\\scraper\\lib\\site-packages\\tqdm\\asyncio.py:75> exception=ClientConnectionError('Connector is closed.')>\n",
      "Traceback (most recent call last):\n",
      "  File \"c:\\users\\adria\\miniconda3\\envs\\scraper\\lib\\site-packages\\tqdm\\asyncio.py\", line 76, in wrap_awaitable\n",
      "    return i, await f\n",
      "  File \"C:\\Users\\adria\\AppData\\Local\\Temp\\ipykernel_27608\\3299729886.py\", line 22, in checker\n",
      "    async with session.get(url, allow_redirects=True, ssl=False, raise_for_status=True, timeout=100, headers=headers) as r:\n",
      "  File \"c:\\users\\adria\\miniconda3\\envs\\scraper\\lib\\site-packages\\aiohttp\\client.py\", line 1141, in __aenter__\n",
      "    self._resp = await self._coro\n",
      "  File \"c:\\users\\adria\\miniconda3\\envs\\scraper\\lib\\site-packages\\aiohttp\\client.py\", line 536, in _request\n",
      "    conn = await self._connector.connect(\n",
      "  File \"c:\\users\\adria\\miniconda3\\envs\\scraper\\lib\\site-packages\\aiohttp\\connector.py\", line 543, in connect\n",
      "    raise ClientConnectionError(\"Connector is closed.\")\n",
      "aiohttp.client_exceptions.ClientConnectionError: Connector is closed.\n",
      "Task exception was never retrieved\n",
      "future: <Task finished name='Task-28027' coro=<tqdm_asyncio.gather.<locals>.wrap_awaitable() done, defined at c:\\users\\adria\\miniconda3\\envs\\scraper\\lib\\site-packages\\tqdm\\asyncio.py:75> exception=ClientConnectionError('Connector is closed.')>\n",
      "Traceback (most recent call last):\n",
      "  File \"c:\\users\\adria\\miniconda3\\envs\\scraper\\lib\\site-packages\\tqdm\\asyncio.py\", line 76, in wrap_awaitable\n",
      "    return i, await f\n",
      "  File \"C:\\Users\\adria\\AppData\\Local\\Temp\\ipykernel_27608\\3299729886.py\", line 22, in checker\n",
      "    async with session.get(url, allow_redirects=True, ssl=False, raise_for_status=True, timeout=100, headers=headers) as r:\n",
      "  File \"c:\\users\\adria\\miniconda3\\envs\\scraper\\lib\\site-packages\\aiohttp\\client.py\", line 1141, in __aenter__\n",
      "    self._resp = await self._coro\n",
      "  File \"c:\\users\\adria\\miniconda3\\envs\\scraper\\lib\\site-packages\\aiohttp\\client.py\", line 536, in _request\n",
      "    conn = await self._connector.connect(\n",
      "  File \"c:\\users\\adria\\miniconda3\\envs\\scraper\\lib\\site-packages\\aiohttp\\connector.py\", line 543, in connect\n",
      "    raise ClientConnectionError(\"Connector is closed.\")\n",
      "aiohttp.client_exceptions.ClientConnectionError: Connector is closed.\n",
      "Task exception was never retrieved\n",
      "future: <Task finished name='Task-27841' coro=<tqdm_asyncio.gather.<locals>.wrap_awaitable() done, defined at c:\\users\\adria\\miniconda3\\envs\\scraper\\lib\\site-packages\\tqdm\\asyncio.py:75> exception=ClientConnectionError('Connector is closed.')>\n",
      "Traceback (most recent call last):\n",
      "  File \"c:\\users\\adria\\miniconda3\\envs\\scraper\\lib\\site-packages\\tqdm\\asyncio.py\", line 76, in wrap_awaitable\n",
      "    return i, await f\n",
      "  File \"C:\\Users\\adria\\AppData\\Local\\Temp\\ipykernel_27608\\3299729886.py\", line 22, in checker\n",
      "    async with session.get(url, allow_redirects=True, ssl=False, raise_for_status=True, timeout=100, headers=headers) as r:\n",
      "  File \"c:\\users\\adria\\miniconda3\\envs\\scraper\\lib\\site-packages\\aiohttp\\client.py\", line 1141, in __aenter__\n",
      "    self._resp = await self._coro\n",
      "  File \"c:\\users\\adria\\miniconda3\\envs\\scraper\\lib\\site-packages\\aiohttp\\client.py\", line 536, in _request\n",
      "    conn = await self._connector.connect(\n",
      "  File \"c:\\users\\adria\\miniconda3\\envs\\scraper\\lib\\site-packages\\aiohttp\\connector.py\", line 543, in connect\n",
      "    raise ClientConnectionError(\"Connector is closed.\")\n",
      "aiohttp.client_exceptions.ClientConnectionError: Connector is closed.\n",
      "Task exception was never retrieved\n",
      "future: <Task finished name='Task-28705' coro=<tqdm_asyncio.gather.<locals>.wrap_awaitable() done, defined at c:\\users\\adria\\miniconda3\\envs\\scraper\\lib\\site-packages\\tqdm\\asyncio.py:75> exception=ClientConnectionError('Connector is closed.')>\n",
      "Traceback (most recent call last):\n",
      "  File \"c:\\users\\adria\\miniconda3\\envs\\scraper\\lib\\site-packages\\tqdm\\asyncio.py\", line 76, in wrap_awaitable\n",
      "    return i, await f\n",
      "  File \"C:\\Users\\adria\\AppData\\Local\\Temp\\ipykernel_27608\\3299729886.py\", line 22, in checker\n",
      "    async with session.get(url, allow_redirects=True, ssl=False, raise_for_status=True, timeout=100, headers=headers) as r:\n",
      "  File \"c:\\users\\adria\\miniconda3\\envs\\scraper\\lib\\site-packages\\aiohttp\\client.py\", line 1141, in __aenter__\n",
      "    self._resp = await self._coro\n",
      "  File \"c:\\users\\adria\\miniconda3\\envs\\scraper\\lib\\site-packages\\aiohttp\\client.py\", line 536, in _request\n",
      "    conn = await self._connector.connect(\n",
      "  File \"c:\\users\\adria\\miniconda3\\envs\\scraper\\lib\\site-packages\\aiohttp\\connector.py\", line 543, in connect\n",
      "    raise ClientConnectionError(\"Connector is closed.\")\n",
      "aiohttp.client_exceptions.ClientConnectionError: Connector is closed.\n",
      "Task exception was never retrieved\n",
      "future: <Task finished name='Task-28541' coro=<tqdm_asyncio.gather.<locals>.wrap_awaitable() done, defined at c:\\users\\adria\\miniconda3\\envs\\scraper\\lib\\site-packages\\tqdm\\asyncio.py:75> exception=ClientConnectionError('Connector is closed.')>\n",
      "Traceback (most recent call last):\n",
      "  File \"c:\\users\\adria\\miniconda3\\envs\\scraper\\lib\\site-packages\\tqdm\\asyncio.py\", line 76, in wrap_awaitable\n",
      "    return i, await f\n",
      "  File \"C:\\Users\\adria\\AppData\\Local\\Temp\\ipykernel_27608\\3299729886.py\", line 22, in checker\n",
      "    async with session.get(url, allow_redirects=True, ssl=False, raise_for_status=True, timeout=100, headers=headers) as r:\n",
      "  File \"c:\\users\\adria\\miniconda3\\envs\\scraper\\lib\\site-packages\\aiohttp\\client.py\", line 1141, in __aenter__\n",
      "    self._resp = await self._coro\n",
      "  File \"c:\\users\\adria\\miniconda3\\envs\\scraper\\lib\\site-packages\\aiohttp\\client.py\", line 536, in _request\n",
      "    conn = await self._connector.connect(\n",
      "  File \"c:\\users\\adria\\miniconda3\\envs\\scraper\\lib\\site-packages\\aiohttp\\connector.py\", line 543, in connect\n",
      "    raise ClientConnectionError(\"Connector is closed.\")\n",
      "aiohttp.client_exceptions.ClientConnectionError: Connector is closed.\n",
      "Task exception was never retrieved\n",
      "future: <Task finished name='Task-29738' coro=<tqdm_asyncio.gather.<locals>.wrap_awaitable() done, defined at c:\\users\\adria\\miniconda3\\envs\\scraper\\lib\\site-packages\\tqdm\\asyncio.py:75> exception=ClientConnectionError('Connector is closed.')>\n",
      "Traceback (most recent call last):\n",
      "  File \"c:\\users\\adria\\miniconda3\\envs\\scraper\\lib\\site-packages\\tqdm\\asyncio.py\", line 76, in wrap_awaitable\n",
      "    return i, await f\n",
      "  File \"C:\\Users\\adria\\AppData\\Local\\Temp\\ipykernel_27608\\3299729886.py\", line 22, in checker\n",
      "    async with session.get(url, allow_redirects=True, ssl=False, raise_for_status=True, timeout=100, headers=headers) as r:\n",
      "  File \"c:\\users\\adria\\miniconda3\\envs\\scraper\\lib\\site-packages\\aiohttp\\client.py\", line 1141, in __aenter__\n",
      "    self._resp = await self._coro\n",
      "  File \"c:\\users\\adria\\miniconda3\\envs\\scraper\\lib\\site-packages\\aiohttp\\client.py\", line 536, in _request\n",
      "    conn = await self._connector.connect(\n",
      "  File \"c:\\users\\adria\\miniconda3\\envs\\scraper\\lib\\site-packages\\aiohttp\\connector.py\", line 543, in connect\n",
      "    raise ClientConnectionError(\"Connector is closed.\")\n",
      "aiohttp.client_exceptions.ClientConnectionError: Connector is closed.\n",
      "Task exception was never retrieved\n",
      "future: <Task finished name='Task-26522' coro=<tqdm_asyncio.gather.<locals>.wrap_awaitable() done, defined at c:\\users\\adria\\miniconda3\\envs\\scraper\\lib\\site-packages\\tqdm\\asyncio.py:75> exception=ClientConnectionError('Connector is closed.')>\n",
      "Traceback (most recent call last):\n",
      "  File \"c:\\users\\adria\\miniconda3\\envs\\scraper\\lib\\site-packages\\tqdm\\asyncio.py\", line 76, in wrap_awaitable\n",
      "    return i, await f\n",
      "  File \"C:\\Users\\adria\\AppData\\Local\\Temp\\ipykernel_27608\\3299729886.py\", line 22, in checker\n",
      "    async with session.get(url, allow_redirects=True, ssl=False, raise_for_status=True, timeout=100, headers=headers) as r:\n",
      "  File \"c:\\users\\adria\\miniconda3\\envs\\scraper\\lib\\site-packages\\aiohttp\\client.py\", line 1141, in __aenter__\n",
      "    self._resp = await self._coro\n",
      "  File \"c:\\users\\adria\\miniconda3\\envs\\scraper\\lib\\site-packages\\aiohttp\\client.py\", line 536, in _request\n",
      "    conn = await self._connector.connect(\n",
      "  File \"c:\\users\\adria\\miniconda3\\envs\\scraper\\lib\\site-packages\\aiohttp\\connector.py\", line 543, in connect\n",
      "    raise ClientConnectionError(\"Connector is closed.\")\n",
      "aiohttp.client_exceptions.ClientConnectionError: Connector is closed.\n"
     ]
    },
    {
     "name": "stderr",
     "output_type": "stream",
     "text": [
      "Task exception was never retrieved\n",
      "future: <Task finished name='Task-28064' coro=<tqdm_asyncio.gather.<locals>.wrap_awaitable() done, defined at c:\\users\\adria\\miniconda3\\envs\\scraper\\lib\\site-packages\\tqdm\\asyncio.py:75> exception=ClientConnectionError('Connector is closed.')>\n",
      "Traceback (most recent call last):\n",
      "  File \"c:\\users\\adria\\miniconda3\\envs\\scraper\\lib\\site-packages\\tqdm\\asyncio.py\", line 76, in wrap_awaitable\n",
      "    return i, await f\n",
      "  File \"C:\\Users\\adria\\AppData\\Local\\Temp\\ipykernel_27608\\3299729886.py\", line 22, in checker\n",
      "    async with session.get(url, allow_redirects=True, ssl=False, raise_for_status=True, timeout=100, headers=headers) as r:\n",
      "  File \"c:\\users\\adria\\miniconda3\\envs\\scraper\\lib\\site-packages\\aiohttp\\client.py\", line 1141, in __aenter__\n",
      "    self._resp = await self._coro\n",
      "  File \"c:\\users\\adria\\miniconda3\\envs\\scraper\\lib\\site-packages\\aiohttp\\client.py\", line 536, in _request\n",
      "    conn = await self._connector.connect(\n",
      "  File \"c:\\users\\adria\\miniconda3\\envs\\scraper\\lib\\site-packages\\aiohttp\\connector.py\", line 543, in connect\n",
      "    raise ClientConnectionError(\"Connector is closed.\")\n",
      "aiohttp.client_exceptions.ClientConnectionError: Connector is closed.\n",
      "Task exception was never retrieved\n",
      "future: <Task finished name='Task-30862' coro=<tqdm_asyncio.gather.<locals>.wrap_awaitable() done, defined at c:\\users\\adria\\miniconda3\\envs\\scraper\\lib\\site-packages\\tqdm\\asyncio.py:75> exception=ClientConnectionError('Connector is closed.')>\n",
      "Traceback (most recent call last):\n",
      "  File \"c:\\users\\adria\\miniconda3\\envs\\scraper\\lib\\site-packages\\tqdm\\asyncio.py\", line 76, in wrap_awaitable\n",
      "    return i, await f\n",
      "  File \"C:\\Users\\adria\\AppData\\Local\\Temp\\ipykernel_27608\\3299729886.py\", line 22, in checker\n",
      "    async with session.get(url, allow_redirects=True, ssl=False, raise_for_status=True, timeout=100, headers=headers) as r:\n",
      "  File \"c:\\users\\adria\\miniconda3\\envs\\scraper\\lib\\site-packages\\aiohttp\\client.py\", line 1141, in __aenter__\n",
      "    self._resp = await self._coro\n",
      "  File \"c:\\users\\adria\\miniconda3\\envs\\scraper\\lib\\site-packages\\aiohttp\\client.py\", line 536, in _request\n",
      "    conn = await self._connector.connect(\n",
      "  File \"c:\\users\\adria\\miniconda3\\envs\\scraper\\lib\\site-packages\\aiohttp\\connector.py\", line 543, in connect\n",
      "    raise ClientConnectionError(\"Connector is closed.\")\n",
      "aiohttp.client_exceptions.ClientConnectionError: Connector is closed.\n",
      "Task exception was never retrieved\n",
      "future: <Task finished name='Task-30208' coro=<tqdm_asyncio.gather.<locals>.wrap_awaitable() done, defined at c:\\users\\adria\\miniconda3\\envs\\scraper\\lib\\site-packages\\tqdm\\asyncio.py:75> exception=ClientConnectionError('Connector is closed.')>\n",
      "Traceback (most recent call last):\n",
      "  File \"c:\\users\\adria\\miniconda3\\envs\\scraper\\lib\\site-packages\\tqdm\\asyncio.py\", line 76, in wrap_awaitable\n",
      "    return i, await f\n",
      "  File \"C:\\Users\\adria\\AppData\\Local\\Temp\\ipykernel_27608\\3299729886.py\", line 22, in checker\n",
      "    async with session.get(url, allow_redirects=True, ssl=False, raise_for_status=True, timeout=100, headers=headers) as r:\n",
      "  File \"c:\\users\\adria\\miniconda3\\envs\\scraper\\lib\\site-packages\\aiohttp\\client.py\", line 1141, in __aenter__\n",
      "    self._resp = await self._coro\n",
      "  File \"c:\\users\\adria\\miniconda3\\envs\\scraper\\lib\\site-packages\\aiohttp\\client.py\", line 536, in _request\n",
      "    conn = await self._connector.connect(\n",
      "  File \"c:\\users\\adria\\miniconda3\\envs\\scraper\\lib\\site-packages\\aiohttp\\connector.py\", line 543, in connect\n",
      "    raise ClientConnectionError(\"Connector is closed.\")\n",
      "aiohttp.client_exceptions.ClientConnectionError: Connector is closed.\n",
      "Task exception was never retrieved\n",
      "future: <Task finished name='Task-30127' coro=<tqdm_asyncio.gather.<locals>.wrap_awaitable() done, defined at c:\\users\\adria\\miniconda3\\envs\\scraper\\lib\\site-packages\\tqdm\\asyncio.py:75> exception=ClientConnectionError('Connector is closed.')>\n",
      "Traceback (most recent call last):\n",
      "  File \"c:\\users\\adria\\miniconda3\\envs\\scraper\\lib\\site-packages\\tqdm\\asyncio.py\", line 76, in wrap_awaitable\n",
      "    return i, await f\n",
      "  File \"C:\\Users\\adria\\AppData\\Local\\Temp\\ipykernel_27608\\3299729886.py\", line 22, in checker\n",
      "    async with session.get(url, allow_redirects=True, ssl=False, raise_for_status=True, timeout=100, headers=headers) as r:\n",
      "  File \"c:\\users\\adria\\miniconda3\\envs\\scraper\\lib\\site-packages\\aiohttp\\client.py\", line 1141, in __aenter__\n",
      "    self._resp = await self._coro\n",
      "  File \"c:\\users\\adria\\miniconda3\\envs\\scraper\\lib\\site-packages\\aiohttp\\client.py\", line 536, in _request\n",
      "    conn = await self._connector.connect(\n",
      "  File \"c:\\users\\adria\\miniconda3\\envs\\scraper\\lib\\site-packages\\aiohttp\\connector.py\", line 543, in connect\n",
      "    raise ClientConnectionError(\"Connector is closed.\")\n",
      "aiohttp.client_exceptions.ClientConnectionError: Connector is closed.\n",
      "Task exception was never retrieved\n",
      "future: <Task finished name='Task-27711' coro=<tqdm_asyncio.gather.<locals>.wrap_awaitable() done, defined at c:\\users\\adria\\miniconda3\\envs\\scraper\\lib\\site-packages\\tqdm\\asyncio.py:75> exception=ClientConnectionError('Connector is closed.')>\n",
      "Traceback (most recent call last):\n",
      "  File \"c:\\users\\adria\\miniconda3\\envs\\scraper\\lib\\site-packages\\tqdm\\asyncio.py\", line 76, in wrap_awaitable\n",
      "    return i, await f\n",
      "  File \"C:\\Users\\adria\\AppData\\Local\\Temp\\ipykernel_27608\\3299729886.py\", line 22, in checker\n",
      "    async with session.get(url, allow_redirects=True, ssl=False, raise_for_status=True, timeout=100, headers=headers) as r:\n",
      "  File \"c:\\users\\adria\\miniconda3\\envs\\scraper\\lib\\site-packages\\aiohttp\\client.py\", line 1141, in __aenter__\n",
      "    self._resp = await self._coro\n",
      "  File \"c:\\users\\adria\\miniconda3\\envs\\scraper\\lib\\site-packages\\aiohttp\\client.py\", line 536, in _request\n",
      "    conn = await self._connector.connect(\n",
      "  File \"c:\\users\\adria\\miniconda3\\envs\\scraper\\lib\\site-packages\\aiohttp\\connector.py\", line 543, in connect\n",
      "    raise ClientConnectionError(\"Connector is closed.\")\n",
      "aiohttp.client_exceptions.ClientConnectionError: Connector is closed.\n",
      "Task exception was never retrieved\n",
      "future: <Task finished name='Task-27397' coro=<tqdm_asyncio.gather.<locals>.wrap_awaitable() done, defined at c:\\users\\adria\\miniconda3\\envs\\scraper\\lib\\site-packages\\tqdm\\asyncio.py:75> exception=ClientConnectionError('Connector is closed.')>\n",
      "Traceback (most recent call last):\n",
      "  File \"c:\\users\\adria\\miniconda3\\envs\\scraper\\lib\\site-packages\\tqdm\\asyncio.py\", line 76, in wrap_awaitable\n",
      "    return i, await f\n",
      "  File \"C:\\Users\\adria\\AppData\\Local\\Temp\\ipykernel_27608\\3299729886.py\", line 22, in checker\n",
      "    async with session.get(url, allow_redirects=True, ssl=False, raise_for_status=True, timeout=100, headers=headers) as r:\n",
      "  File \"c:\\users\\adria\\miniconda3\\envs\\scraper\\lib\\site-packages\\aiohttp\\client.py\", line 1141, in __aenter__\n",
      "    self._resp = await self._coro\n",
      "  File \"c:\\users\\adria\\miniconda3\\envs\\scraper\\lib\\site-packages\\aiohttp\\client.py\", line 536, in _request\n",
      "    conn = await self._connector.connect(\n",
      "  File \"c:\\users\\adria\\miniconda3\\envs\\scraper\\lib\\site-packages\\aiohttp\\connector.py\", line 543, in connect\n",
      "    raise ClientConnectionError(\"Connector is closed.\")\n",
      "aiohttp.client_exceptions.ClientConnectionError: Connector is closed.\n",
      "Task exception was never retrieved\n",
      "future: <Task finished name='Task-27678' coro=<tqdm_asyncio.gather.<locals>.wrap_awaitable() done, defined at c:\\users\\adria\\miniconda3\\envs\\scraper\\lib\\site-packages\\tqdm\\asyncio.py:75> exception=ClientConnectionError('Connector is closed.')>\n",
      "Traceback (most recent call last):\n",
      "  File \"c:\\users\\adria\\miniconda3\\envs\\scraper\\lib\\site-packages\\tqdm\\asyncio.py\", line 76, in wrap_awaitable\n",
      "    return i, await f\n",
      "  File \"C:\\Users\\adria\\AppData\\Local\\Temp\\ipykernel_27608\\3299729886.py\", line 22, in checker\n",
      "    async with session.get(url, allow_redirects=True, ssl=False, raise_for_status=True, timeout=100, headers=headers) as r:\n",
      "  File \"c:\\users\\adria\\miniconda3\\envs\\scraper\\lib\\site-packages\\aiohttp\\client.py\", line 1141, in __aenter__\n",
      "    self._resp = await self._coro\n",
      "  File \"c:\\users\\adria\\miniconda3\\envs\\scraper\\lib\\site-packages\\aiohttp\\client.py\", line 536, in _request\n",
      "    conn = await self._connector.connect(\n",
      "  File \"c:\\users\\adria\\miniconda3\\envs\\scraper\\lib\\site-packages\\aiohttp\\connector.py\", line 543, in connect\n",
      "    raise ClientConnectionError(\"Connector is closed.\")\n",
      "aiohttp.client_exceptions.ClientConnectionError: Connector is closed.\n"
     ]
    },
    {
     "name": "stderr",
     "output_type": "stream",
     "text": [
      "Task exception was never retrieved\n",
      "future: <Task finished name='Task-28923' coro=<tqdm_asyncio.gather.<locals>.wrap_awaitable() done, defined at c:\\users\\adria\\miniconda3\\envs\\scraper\\lib\\site-packages\\tqdm\\asyncio.py:75> exception=ClientConnectionError('Connector is closed.')>\n",
      "Traceback (most recent call last):\n",
      "  File \"c:\\users\\adria\\miniconda3\\envs\\scraper\\lib\\site-packages\\tqdm\\asyncio.py\", line 76, in wrap_awaitable\n",
      "    return i, await f\n",
      "  File \"C:\\Users\\adria\\AppData\\Local\\Temp\\ipykernel_27608\\3299729886.py\", line 22, in checker\n",
      "    async with session.get(url, allow_redirects=True, ssl=False, raise_for_status=True, timeout=100, headers=headers) as r:\n",
      "  File \"c:\\users\\adria\\miniconda3\\envs\\scraper\\lib\\site-packages\\aiohttp\\client.py\", line 1141, in __aenter__\n",
      "    self._resp = await self._coro\n",
      "  File \"c:\\users\\adria\\miniconda3\\envs\\scraper\\lib\\site-packages\\aiohttp\\client.py\", line 536, in _request\n",
      "    conn = await self._connector.connect(\n",
      "  File \"c:\\users\\adria\\miniconda3\\envs\\scraper\\lib\\site-packages\\aiohttp\\connector.py\", line 543, in connect\n",
      "    raise ClientConnectionError(\"Connector is closed.\")\n",
      "aiohttp.client_exceptions.ClientConnectionError: Connector is closed.\n",
      "Task exception was never retrieved\n",
      "future: <Task finished name='Task-28063' coro=<tqdm_asyncio.gather.<locals>.wrap_awaitable() done, defined at c:\\users\\adria\\miniconda3\\envs\\scraper\\lib\\site-packages\\tqdm\\asyncio.py:75> exception=ClientConnectionError('Connector is closed.')>\n",
      "Traceback (most recent call last):\n",
      "  File \"c:\\users\\adria\\miniconda3\\envs\\scraper\\lib\\site-packages\\tqdm\\asyncio.py\", line 76, in wrap_awaitable\n",
      "    return i, await f\n",
      "  File \"C:\\Users\\adria\\AppData\\Local\\Temp\\ipykernel_27608\\3299729886.py\", line 22, in checker\n",
      "    async with session.get(url, allow_redirects=True, ssl=False, raise_for_status=True, timeout=100, headers=headers) as r:\n",
      "  File \"c:\\users\\adria\\miniconda3\\envs\\scraper\\lib\\site-packages\\aiohttp\\client.py\", line 1141, in __aenter__\n",
      "    self._resp = await self._coro\n",
      "  File \"c:\\users\\adria\\miniconda3\\envs\\scraper\\lib\\site-packages\\aiohttp\\client.py\", line 536, in _request\n",
      "    conn = await self._connector.connect(\n",
      "  File \"c:\\users\\adria\\miniconda3\\envs\\scraper\\lib\\site-packages\\aiohttp\\connector.py\", line 543, in connect\n",
      "    raise ClientConnectionError(\"Connector is closed.\")\n",
      "aiohttp.client_exceptions.ClientConnectionError: Connector is closed.\n",
      "Task exception was never retrieved\n",
      "future: <Task finished name='Task-30529' coro=<tqdm_asyncio.gather.<locals>.wrap_awaitable() done, defined at c:\\users\\adria\\miniconda3\\envs\\scraper\\lib\\site-packages\\tqdm\\asyncio.py:75> exception=ClientOSError(1, '[SSL: APPLICATION_DATA_AFTER_CLOSE_NOTIFY] application data after close notify (_ssl.c:2747)')>\n",
      "Traceback (most recent call last):\n",
      "  File \"c:\\users\\adria\\miniconda3\\envs\\scraper\\lib\\site-packages\\tqdm\\asyncio.py\", line 76, in wrap_awaitable\n",
      "    return i, await f\n",
      "  File \"C:\\Users\\adria\\AppData\\Local\\Temp\\ipykernel_27608\\3299729886.py\", line 22, in checker\n",
      "    async with session.get(url, allow_redirects=True, ssl=False, raise_for_status=True, timeout=100, headers=headers) as r:\n",
      "  File \"c:\\users\\adria\\miniconda3\\envs\\scraper\\lib\\site-packages\\aiohttp\\client.py\", line 1141, in __aenter__\n",
      "    self._resp = await self._coro\n",
      "  File \"c:\\users\\adria\\miniconda3\\envs\\scraper\\lib\\site-packages\\aiohttp\\client.py\", line 560, in _request\n",
      "    await resp.start(conn)\n",
      "  File \"c:\\users\\adria\\miniconda3\\envs\\scraper\\lib\\site-packages\\aiohttp\\client_reqrep.py\", line 899, in start\n",
      "    message, payload = await protocol.read()  # type: ignore[union-attr]\n",
      "  File \"c:\\users\\adria\\miniconda3\\envs\\scraper\\lib\\site-packages\\aiohttp\\streams.py\", line 616, in read\n",
      "    await self._waiter\n",
      "aiohttp.client_exceptions.ClientOSError: [Errno 1] [SSL: APPLICATION_DATA_AFTER_CLOSE_NOTIFY] application data after close notify (_ssl.c:2747)\n",
      "Task exception was never retrieved\n",
      "future: <Task finished name='Task-29695' coro=<tqdm_asyncio.gather.<locals>.wrap_awaitable() done, defined at c:\\users\\adria\\miniconda3\\envs\\scraper\\lib\\site-packages\\tqdm\\asyncio.py:75> exception=ClientConnectionError('Connector is closed.')>\n",
      "Traceback (most recent call last):\n",
      "  File \"c:\\users\\adria\\miniconda3\\envs\\scraper\\lib\\site-packages\\tqdm\\asyncio.py\", line 76, in wrap_awaitable\n",
      "    return i, await f\n",
      "  File \"C:\\Users\\adria\\AppData\\Local\\Temp\\ipykernel_27608\\3299729886.py\", line 22, in checker\n",
      "    async with session.get(url, allow_redirects=True, ssl=False, raise_for_status=True, timeout=100, headers=headers) as r:\n",
      "  File \"c:\\users\\adria\\miniconda3\\envs\\scraper\\lib\\site-packages\\aiohttp\\client.py\", line 1141, in __aenter__\n",
      "    self._resp = await self._coro\n",
      "  File \"c:\\users\\adria\\miniconda3\\envs\\scraper\\lib\\site-packages\\aiohttp\\client.py\", line 536, in _request\n",
      "    conn = await self._connector.connect(\n",
      "  File \"c:\\users\\adria\\miniconda3\\envs\\scraper\\lib\\site-packages\\aiohttp\\connector.py\", line 543, in connect\n",
      "    raise ClientConnectionError(\"Connector is closed.\")\n",
      "aiohttp.client_exceptions.ClientConnectionError: Connector is closed.\n",
      "Task exception was never retrieved\n",
      "future: <Task finished name='Task-29191' coro=<tqdm_asyncio.gather.<locals>.wrap_awaitable() done, defined at c:\\users\\adria\\miniconda3\\envs\\scraper\\lib\\site-packages\\tqdm\\asyncio.py:75> exception=ClientConnectionError('Connector is closed.')>\n",
      "Traceback (most recent call last):\n",
      "  File \"c:\\users\\adria\\miniconda3\\envs\\scraper\\lib\\site-packages\\tqdm\\asyncio.py\", line 76, in wrap_awaitable\n",
      "    return i, await f\n",
      "  File \"C:\\Users\\adria\\AppData\\Local\\Temp\\ipykernel_27608\\3299729886.py\", line 22, in checker\n",
      "    async with session.get(url, allow_redirects=True, ssl=False, raise_for_status=True, timeout=100, headers=headers) as r:\n",
      "  File \"c:\\users\\adria\\miniconda3\\envs\\scraper\\lib\\site-packages\\aiohttp\\client.py\", line 1141, in __aenter__\n",
      "    self._resp = await self._coro\n",
      "  File \"c:\\users\\adria\\miniconda3\\envs\\scraper\\lib\\site-packages\\aiohttp\\client.py\", line 536, in _request\n",
      "    conn = await self._connector.connect(\n",
      "  File \"c:\\users\\adria\\miniconda3\\envs\\scraper\\lib\\site-packages\\aiohttp\\connector.py\", line 543, in connect\n",
      "    raise ClientConnectionError(\"Connector is closed.\")\n",
      "aiohttp.client_exceptions.ClientConnectionError: Connector is closed.\n",
      "Task exception was never retrieved\n",
      "future: <Task finished name='Task-26744' coro=<tqdm_asyncio.gather.<locals>.wrap_awaitable() done, defined at c:\\users\\adria\\miniconda3\\envs\\scraper\\lib\\site-packages\\tqdm\\asyncio.py:75> exception=ClientConnectionError('Connector is closed.')>\n",
      "Traceback (most recent call last):\n",
      "  File \"c:\\users\\adria\\miniconda3\\envs\\scraper\\lib\\site-packages\\tqdm\\asyncio.py\", line 76, in wrap_awaitable\n",
      "    return i, await f\n",
      "  File \"C:\\Users\\adria\\AppData\\Local\\Temp\\ipykernel_27608\\3299729886.py\", line 22, in checker\n",
      "    async with session.get(url, allow_redirects=True, ssl=False, raise_for_status=True, timeout=100, headers=headers) as r:\n",
      "  File \"c:\\users\\adria\\miniconda3\\envs\\scraper\\lib\\site-packages\\aiohttp\\client.py\", line 1141, in __aenter__\n",
      "    self._resp = await self._coro\n",
      "  File \"c:\\users\\adria\\miniconda3\\envs\\scraper\\lib\\site-packages\\aiohttp\\client.py\", line 536, in _request\n",
      "    conn = await self._connector.connect(\n",
      "  File \"c:\\users\\adria\\miniconda3\\envs\\scraper\\lib\\site-packages\\aiohttp\\connector.py\", line 543, in connect\n",
      "    raise ClientConnectionError(\"Connector is closed.\")\n",
      "aiohttp.client_exceptions.ClientConnectionError: Connector is closed.\n",
      "Task exception was never retrieved\n",
      "future: <Task finished name='Task-29508' coro=<tqdm_asyncio.gather.<locals>.wrap_awaitable() done, defined at c:\\users\\adria\\miniconda3\\envs\\scraper\\lib\\site-packages\\tqdm\\asyncio.py:75> exception=ClientConnectionError('Connector is closed.')>\n",
      "Traceback (most recent call last):\n",
      "  File \"c:\\users\\adria\\miniconda3\\envs\\scraper\\lib\\site-packages\\tqdm\\asyncio.py\", line 76, in wrap_awaitable\n",
      "    return i, await f\n",
      "  File \"C:\\Users\\adria\\AppData\\Local\\Temp\\ipykernel_27608\\3299729886.py\", line 22, in checker\n",
      "    async with session.get(url, allow_redirects=True, ssl=False, raise_for_status=True, timeout=100, headers=headers) as r:\n",
      "  File \"c:\\users\\adria\\miniconda3\\envs\\scraper\\lib\\site-packages\\aiohttp\\client.py\", line 1141, in __aenter__\n",
      "    self._resp = await self._coro\n",
      "  File \"c:\\users\\adria\\miniconda3\\envs\\scraper\\lib\\site-packages\\aiohttp\\client.py\", line 536, in _request\n",
      "    conn = await self._connector.connect(\n",
      "  File \"c:\\users\\adria\\miniconda3\\envs\\scraper\\lib\\site-packages\\aiohttp\\connector.py\", line 543, in connect\n",
      "    raise ClientConnectionError(\"Connector is closed.\")\n",
      "aiohttp.client_exceptions.ClientConnectionError: Connector is closed.\n"
     ]
    },
    {
     "name": "stderr",
     "output_type": "stream",
     "text": [
      "Task exception was never retrieved\n",
      "future: <Task finished name='Task-28752' coro=<tqdm_asyncio.gather.<locals>.wrap_awaitable() done, defined at c:\\users\\adria\\miniconda3\\envs\\scraper\\lib\\site-packages\\tqdm\\asyncio.py:75> exception=ClientConnectionError('Connector is closed.')>\n",
      "Traceback (most recent call last):\n",
      "  File \"c:\\users\\adria\\miniconda3\\envs\\scraper\\lib\\site-packages\\tqdm\\asyncio.py\", line 76, in wrap_awaitable\n",
      "    return i, await f\n",
      "  File \"C:\\Users\\adria\\AppData\\Local\\Temp\\ipykernel_27608\\3299729886.py\", line 22, in checker\n",
      "    async with session.get(url, allow_redirects=True, ssl=False, raise_for_status=True, timeout=100, headers=headers) as r:\n",
      "  File \"c:\\users\\adria\\miniconda3\\envs\\scraper\\lib\\site-packages\\aiohttp\\client.py\", line 1141, in __aenter__\n",
      "    self._resp = await self._coro\n",
      "  File \"c:\\users\\adria\\miniconda3\\envs\\scraper\\lib\\site-packages\\aiohttp\\client.py\", line 536, in _request\n",
      "    conn = await self._connector.connect(\n",
      "  File \"c:\\users\\adria\\miniconda3\\envs\\scraper\\lib\\site-packages\\aiohttp\\connector.py\", line 543, in connect\n",
      "    raise ClientConnectionError(\"Connector is closed.\")\n",
      "aiohttp.client_exceptions.ClientConnectionError: Connector is closed.\n",
      "Task exception was never retrieved\n",
      "future: <Task finished name='Task-30414' coro=<tqdm_asyncio.gather.<locals>.wrap_awaitable() done, defined at c:\\users\\adria\\miniconda3\\envs\\scraper\\lib\\site-packages\\tqdm\\asyncio.py:75> exception=ClientConnectionError('Connector is closed.')>\n",
      "Traceback (most recent call last):\n",
      "  File \"c:\\users\\adria\\miniconda3\\envs\\scraper\\lib\\site-packages\\tqdm\\asyncio.py\", line 76, in wrap_awaitable\n",
      "    return i, await f\n",
      "  File \"C:\\Users\\adria\\AppData\\Local\\Temp\\ipykernel_27608\\3299729886.py\", line 22, in checker\n",
      "    async with session.get(url, allow_redirects=True, ssl=False, raise_for_status=True, timeout=100, headers=headers) as r:\n",
      "  File \"c:\\users\\adria\\miniconda3\\envs\\scraper\\lib\\site-packages\\aiohttp\\client.py\", line 1141, in __aenter__\n",
      "    self._resp = await self._coro\n",
      "  File \"c:\\users\\adria\\miniconda3\\envs\\scraper\\lib\\site-packages\\aiohttp\\client.py\", line 536, in _request\n",
      "    conn = await self._connector.connect(\n",
      "  File \"c:\\users\\adria\\miniconda3\\envs\\scraper\\lib\\site-packages\\aiohttp\\connector.py\", line 543, in connect\n",
      "    raise ClientConnectionError(\"Connector is closed.\")\n",
      "aiohttp.client_exceptions.ClientConnectionError: Connector is closed.\n",
      "Task exception was never retrieved\n",
      "future: <Task finished name='Task-31139' coro=<tqdm_asyncio.gather.<locals>.wrap_awaitable() done, defined at c:\\users\\adria\\miniconda3\\envs\\scraper\\lib\\site-packages\\tqdm\\asyncio.py:75> exception=ClientConnectionError('Connector is closed.')>\n",
      "Traceback (most recent call last):\n",
      "  File \"c:\\users\\adria\\miniconda3\\envs\\scraper\\lib\\site-packages\\tqdm\\asyncio.py\", line 76, in wrap_awaitable\n",
      "    return i, await f\n",
      "  File \"C:\\Users\\adria\\AppData\\Local\\Temp\\ipykernel_27608\\3299729886.py\", line 22, in checker\n",
      "    async with session.get(url, allow_redirects=True, ssl=False, raise_for_status=True, timeout=100, headers=headers) as r:\n",
      "  File \"c:\\users\\adria\\miniconda3\\envs\\scraper\\lib\\site-packages\\aiohttp\\client.py\", line 1141, in __aenter__\n",
      "    self._resp = await self._coro\n",
      "  File \"c:\\users\\adria\\miniconda3\\envs\\scraper\\lib\\site-packages\\aiohttp\\client.py\", line 536, in _request\n",
      "    conn = await self._connector.connect(\n",
      "  File \"c:\\users\\adria\\miniconda3\\envs\\scraper\\lib\\site-packages\\aiohttp\\connector.py\", line 543, in connect\n",
      "    raise ClientConnectionError(\"Connector is closed.\")\n",
      "aiohttp.client_exceptions.ClientConnectionError: Connector is closed.\n",
      "Task exception was never retrieved\n",
      "future: <Task finished name='Task-27752' coro=<tqdm_asyncio.gather.<locals>.wrap_awaitable() done, defined at c:\\users\\adria\\miniconda3\\envs\\scraper\\lib\\site-packages\\tqdm\\asyncio.py:75> exception=ClientConnectionError('Connector is closed.')>\n",
      "Traceback (most recent call last):\n",
      "  File \"c:\\users\\adria\\miniconda3\\envs\\scraper\\lib\\site-packages\\tqdm\\asyncio.py\", line 76, in wrap_awaitable\n",
      "    return i, await f\n",
      "  File \"C:\\Users\\adria\\AppData\\Local\\Temp\\ipykernel_27608\\3299729886.py\", line 22, in checker\n",
      "    async with session.get(url, allow_redirects=True, ssl=False, raise_for_status=True, timeout=100, headers=headers) as r:\n",
      "  File \"c:\\users\\adria\\miniconda3\\envs\\scraper\\lib\\site-packages\\aiohttp\\client.py\", line 1141, in __aenter__\n",
      "    self._resp = await self._coro\n",
      "  File \"c:\\users\\adria\\miniconda3\\envs\\scraper\\lib\\site-packages\\aiohttp\\client.py\", line 536, in _request\n",
      "    conn = await self._connector.connect(\n",
      "  File \"c:\\users\\adria\\miniconda3\\envs\\scraper\\lib\\site-packages\\aiohttp\\connector.py\", line 543, in connect\n",
      "    raise ClientConnectionError(\"Connector is closed.\")\n",
      "aiohttp.client_exceptions.ClientConnectionError: Connector is closed.\n",
      "Task exception was never retrieved\n",
      "future: <Task finished name='Task-26521' coro=<tqdm_asyncio.gather.<locals>.wrap_awaitable() done, defined at c:\\users\\adria\\miniconda3\\envs\\scraper\\lib\\site-packages\\tqdm\\asyncio.py:75> exception=ClientConnectionError('Connector is closed.')>\n",
      "Traceback (most recent call last):\n",
      "  File \"c:\\users\\adria\\miniconda3\\envs\\scraper\\lib\\site-packages\\tqdm\\asyncio.py\", line 76, in wrap_awaitable\n",
      "    return i, await f\n",
      "  File \"C:\\Users\\adria\\AppData\\Local\\Temp\\ipykernel_27608\\3299729886.py\", line 22, in checker\n",
      "    async with session.get(url, allow_redirects=True, ssl=False, raise_for_status=True, timeout=100, headers=headers) as r:\n",
      "  File \"c:\\users\\adria\\miniconda3\\envs\\scraper\\lib\\site-packages\\aiohttp\\client.py\", line 1141, in __aenter__\n",
      "    self._resp = await self._coro\n",
      "  File \"c:\\users\\adria\\miniconda3\\envs\\scraper\\lib\\site-packages\\aiohttp\\client.py\", line 536, in _request\n",
      "    conn = await self._connector.connect(\n",
      "  File \"c:\\users\\adria\\miniconda3\\envs\\scraper\\lib\\site-packages\\aiohttp\\connector.py\", line 543, in connect\n",
      "    raise ClientConnectionError(\"Connector is closed.\")\n",
      "aiohttp.client_exceptions.ClientConnectionError: Connector is closed.\n",
      "Task exception was never retrieved\n",
      "future: <Task finished name='Task-26795' coro=<tqdm_asyncio.gather.<locals>.wrap_awaitable() done, defined at c:\\users\\adria\\miniconda3\\envs\\scraper\\lib\\site-packages\\tqdm\\asyncio.py:75> exception=ClientConnectionError('Connector is closed.')>\n",
      "Traceback (most recent call last):\n",
      "  File \"c:\\users\\adria\\miniconda3\\envs\\scraper\\lib\\site-packages\\tqdm\\asyncio.py\", line 76, in wrap_awaitable\n",
      "    return i, await f\n",
      "  File \"C:\\Users\\adria\\AppData\\Local\\Temp\\ipykernel_27608\\3299729886.py\", line 22, in checker\n",
      "    async with session.get(url, allow_redirects=True, ssl=False, raise_for_status=True, timeout=100, headers=headers) as r:\n",
      "  File \"c:\\users\\adria\\miniconda3\\envs\\scraper\\lib\\site-packages\\aiohttp\\client.py\", line 1141, in __aenter__\n",
      "    self._resp = await self._coro\n",
      "  File \"c:\\users\\adria\\miniconda3\\envs\\scraper\\lib\\site-packages\\aiohttp\\client.py\", line 536, in _request\n",
      "    conn = await self._connector.connect(\n",
      "  File \"c:\\users\\adria\\miniconda3\\envs\\scraper\\lib\\site-packages\\aiohttp\\connector.py\", line 543, in connect\n",
      "    raise ClientConnectionError(\"Connector is closed.\")\n",
      "aiohttp.client_exceptions.ClientConnectionError: Connector is closed.\n",
      "Task exception was never retrieved\n",
      "future: <Task finished name='Task-27958' coro=<tqdm_asyncio.gather.<locals>.wrap_awaitable() done, defined at c:\\users\\adria\\miniconda3\\envs\\scraper\\lib\\site-packages\\tqdm\\asyncio.py:75> exception=ClientConnectionError('Connector is closed.')>\n",
      "Traceback (most recent call last):\n",
      "  File \"c:\\users\\adria\\miniconda3\\envs\\scraper\\lib\\site-packages\\tqdm\\asyncio.py\", line 76, in wrap_awaitable\n",
      "    return i, await f\n",
      "  File \"C:\\Users\\adria\\AppData\\Local\\Temp\\ipykernel_27608\\3299729886.py\", line 22, in checker\n",
      "    async with session.get(url, allow_redirects=True, ssl=False, raise_for_status=True, timeout=100, headers=headers) as r:\n",
      "  File \"c:\\users\\adria\\miniconda3\\envs\\scraper\\lib\\site-packages\\aiohttp\\client.py\", line 1141, in __aenter__\n",
      "    self._resp = await self._coro\n",
      "  File \"c:\\users\\adria\\miniconda3\\envs\\scraper\\lib\\site-packages\\aiohttp\\client.py\", line 536, in _request\n",
      "    conn = await self._connector.connect(\n",
      "  File \"c:\\users\\adria\\miniconda3\\envs\\scraper\\lib\\site-packages\\aiohttp\\connector.py\", line 543, in connect\n",
      "    raise ClientConnectionError(\"Connector is closed.\")\n",
      "aiohttp.client_exceptions.ClientConnectionError: Connector is closed.\n"
     ]
    },
    {
     "name": "stderr",
     "output_type": "stream",
     "text": [
      "Task exception was never retrieved\n",
      "future: <Task finished name='Task-29099' coro=<tqdm_asyncio.gather.<locals>.wrap_awaitable() done, defined at c:\\users\\adria\\miniconda3\\envs\\scraper\\lib\\site-packages\\tqdm\\asyncio.py:75> exception=ClientConnectionError('Connector is closed.')>\n",
      "Traceback (most recent call last):\n",
      "  File \"c:\\users\\adria\\miniconda3\\envs\\scraper\\lib\\site-packages\\tqdm\\asyncio.py\", line 76, in wrap_awaitable\n",
      "    return i, await f\n",
      "  File \"C:\\Users\\adria\\AppData\\Local\\Temp\\ipykernel_27608\\3299729886.py\", line 22, in checker\n",
      "    async with session.get(url, allow_redirects=True, ssl=False, raise_for_status=True, timeout=100, headers=headers) as r:\n",
      "  File \"c:\\users\\adria\\miniconda3\\envs\\scraper\\lib\\site-packages\\aiohttp\\client.py\", line 1141, in __aenter__\n",
      "    self._resp = await self._coro\n",
      "  File \"c:\\users\\adria\\miniconda3\\envs\\scraper\\lib\\site-packages\\aiohttp\\client.py\", line 536, in _request\n",
      "    conn = await self._connector.connect(\n",
      "  File \"c:\\users\\adria\\miniconda3\\envs\\scraper\\lib\\site-packages\\aiohttp\\connector.py\", line 543, in connect\n",
      "    raise ClientConnectionError(\"Connector is closed.\")\n",
      "aiohttp.client_exceptions.ClientConnectionError: Connector is closed.\n",
      "Task exception was never retrieved\n",
      "future: <Task finished name='Task-26740' coro=<tqdm_asyncio.gather.<locals>.wrap_awaitable() done, defined at c:\\users\\adria\\miniconda3\\envs\\scraper\\lib\\site-packages\\tqdm\\asyncio.py:75> exception=ClientConnectionError('Connector is closed.')>\n",
      "Traceback (most recent call last):\n",
      "  File \"c:\\users\\adria\\miniconda3\\envs\\scraper\\lib\\site-packages\\tqdm\\asyncio.py\", line 76, in wrap_awaitable\n",
      "    return i, await f\n",
      "  File \"C:\\Users\\adria\\AppData\\Local\\Temp\\ipykernel_27608\\3299729886.py\", line 22, in checker\n",
      "    async with session.get(url, allow_redirects=True, ssl=False, raise_for_status=True, timeout=100, headers=headers) as r:\n",
      "  File \"c:\\users\\adria\\miniconda3\\envs\\scraper\\lib\\site-packages\\aiohttp\\client.py\", line 1141, in __aenter__\n",
      "    self._resp = await self._coro\n",
      "  File \"c:\\users\\adria\\miniconda3\\envs\\scraper\\lib\\site-packages\\aiohttp\\client.py\", line 536, in _request\n",
      "    conn = await self._connector.connect(\n",
      "  File \"c:\\users\\adria\\miniconda3\\envs\\scraper\\lib\\site-packages\\aiohttp\\connector.py\", line 543, in connect\n",
      "    raise ClientConnectionError(\"Connector is closed.\")\n",
      "aiohttp.client_exceptions.ClientConnectionError: Connector is closed.\n",
      "Task exception was never retrieved\n",
      "future: <Task finished name='Task-27413' coro=<tqdm_asyncio.gather.<locals>.wrap_awaitable() done, defined at c:\\users\\adria\\miniconda3\\envs\\scraper\\lib\\site-packages\\tqdm\\asyncio.py:75> exception=ClientConnectionError('Connector is closed.')>\n",
      "Traceback (most recent call last):\n",
      "  File \"c:\\users\\adria\\miniconda3\\envs\\scraper\\lib\\site-packages\\tqdm\\asyncio.py\", line 76, in wrap_awaitable\n",
      "    return i, await f\n",
      "  File \"C:\\Users\\adria\\AppData\\Local\\Temp\\ipykernel_27608\\3299729886.py\", line 22, in checker\n",
      "    async with session.get(url, allow_redirects=True, ssl=False, raise_for_status=True, timeout=100, headers=headers) as r:\n",
      "  File \"c:\\users\\adria\\miniconda3\\envs\\scraper\\lib\\site-packages\\aiohttp\\client.py\", line 1141, in __aenter__\n",
      "    self._resp = await self._coro\n",
      "  File \"c:\\users\\adria\\miniconda3\\envs\\scraper\\lib\\site-packages\\aiohttp\\client.py\", line 536, in _request\n",
      "    conn = await self._connector.connect(\n",
      "  File \"c:\\users\\adria\\miniconda3\\envs\\scraper\\lib\\site-packages\\aiohttp\\connector.py\", line 543, in connect\n",
      "    raise ClientConnectionError(\"Connector is closed.\")\n",
      "aiohttp.client_exceptions.ClientConnectionError: Connector is closed.\n",
      "Task exception was never retrieved\n",
      "future: <Task finished name='Task-30363' coro=<tqdm_asyncio.gather.<locals>.wrap_awaitable() done, defined at c:\\users\\adria\\miniconda3\\envs\\scraper\\lib\\site-packages\\tqdm\\asyncio.py:75> exception=ClientConnectionError('Connector is closed.')>\n",
      "Traceback (most recent call last):\n",
      "  File \"c:\\users\\adria\\miniconda3\\envs\\scraper\\lib\\site-packages\\tqdm\\asyncio.py\", line 76, in wrap_awaitable\n",
      "    return i, await f\n",
      "  File \"C:\\Users\\adria\\AppData\\Local\\Temp\\ipykernel_27608\\3299729886.py\", line 22, in checker\n",
      "    async with session.get(url, allow_redirects=True, ssl=False, raise_for_status=True, timeout=100, headers=headers) as r:\n",
      "  File \"c:\\users\\adria\\miniconda3\\envs\\scraper\\lib\\site-packages\\aiohttp\\client.py\", line 1141, in __aenter__\n",
      "    self._resp = await self._coro\n",
      "  File \"c:\\users\\adria\\miniconda3\\envs\\scraper\\lib\\site-packages\\aiohttp\\client.py\", line 536, in _request\n",
      "    conn = await self._connector.connect(\n",
      "  File \"c:\\users\\adria\\miniconda3\\envs\\scraper\\lib\\site-packages\\aiohttp\\connector.py\", line 543, in connect\n",
      "    raise ClientConnectionError(\"Connector is closed.\")\n",
      "aiohttp.client_exceptions.ClientConnectionError: Connector is closed.\n",
      "Task exception was never retrieved\n",
      "future: <Task finished name='Task-29889' coro=<tqdm_asyncio.gather.<locals>.wrap_awaitable() done, defined at c:\\users\\adria\\miniconda3\\envs\\scraper\\lib\\site-packages\\tqdm\\asyncio.py:75> exception=ClientConnectionError('Connector is closed.')>\n",
      "Traceback (most recent call last):\n",
      "  File \"c:\\users\\adria\\miniconda3\\envs\\scraper\\lib\\site-packages\\tqdm\\asyncio.py\", line 76, in wrap_awaitable\n",
      "    return i, await f\n",
      "  File \"C:\\Users\\adria\\AppData\\Local\\Temp\\ipykernel_27608\\3299729886.py\", line 22, in checker\n",
      "    async with session.get(url, allow_redirects=True, ssl=False, raise_for_status=True, timeout=100, headers=headers) as r:\n",
      "  File \"c:\\users\\adria\\miniconda3\\envs\\scraper\\lib\\site-packages\\aiohttp\\client.py\", line 1141, in __aenter__\n",
      "    self._resp = await self._coro\n",
      "  File \"c:\\users\\adria\\miniconda3\\envs\\scraper\\lib\\site-packages\\aiohttp\\client.py\", line 536, in _request\n",
      "    conn = await self._connector.connect(\n",
      "  File \"c:\\users\\adria\\miniconda3\\envs\\scraper\\lib\\site-packages\\aiohttp\\connector.py\", line 543, in connect\n",
      "    raise ClientConnectionError(\"Connector is closed.\")\n",
      "aiohttp.client_exceptions.ClientConnectionError: Connector is closed.\n",
      "Task exception was never retrieved\n",
      "future: <Task finished name='Task-26758' coro=<tqdm_asyncio.gather.<locals>.wrap_awaitable() done, defined at c:\\users\\adria\\miniconda3\\envs\\scraper\\lib\\site-packages\\tqdm\\asyncio.py:75> exception=ClientConnectionError('Connector is closed.')>\n",
      "Traceback (most recent call last):\n",
      "  File \"c:\\users\\adria\\miniconda3\\envs\\scraper\\lib\\site-packages\\tqdm\\asyncio.py\", line 76, in wrap_awaitable\n",
      "    return i, await f\n",
      "  File \"C:\\Users\\adria\\AppData\\Local\\Temp\\ipykernel_27608\\3299729886.py\", line 22, in checker\n",
      "    async with session.get(url, allow_redirects=True, ssl=False, raise_for_status=True, timeout=100, headers=headers) as r:\n",
      "  File \"c:\\users\\adria\\miniconda3\\envs\\scraper\\lib\\site-packages\\aiohttp\\client.py\", line 1141, in __aenter__\n",
      "    self._resp = await self._coro\n",
      "  File \"c:\\users\\adria\\miniconda3\\envs\\scraper\\lib\\site-packages\\aiohttp\\client.py\", line 536, in _request\n",
      "    conn = await self._connector.connect(\n",
      "  File \"c:\\users\\adria\\miniconda3\\envs\\scraper\\lib\\site-packages\\aiohttp\\connector.py\", line 543, in connect\n",
      "    raise ClientConnectionError(\"Connector is closed.\")\n",
      "aiohttp.client_exceptions.ClientConnectionError: Connector is closed.\n",
      "Task exception was never retrieved\n",
      "future: <Task finished name='Task-30066' coro=<tqdm_asyncio.gather.<locals>.wrap_awaitable() done, defined at c:\\users\\adria\\miniconda3\\envs\\scraper\\lib\\site-packages\\tqdm\\asyncio.py:75> exception=ClientConnectionError('Connector is closed.')>\n",
      "Traceback (most recent call last):\n",
      "  File \"c:\\users\\adria\\miniconda3\\envs\\scraper\\lib\\site-packages\\tqdm\\asyncio.py\", line 76, in wrap_awaitable\n",
      "    return i, await f\n",
      "  File \"C:\\Users\\adria\\AppData\\Local\\Temp\\ipykernel_27608\\3299729886.py\", line 22, in checker\n",
      "    async with session.get(url, allow_redirects=True, ssl=False, raise_for_status=True, timeout=100, headers=headers) as r:\n",
      "  File \"c:\\users\\adria\\miniconda3\\envs\\scraper\\lib\\site-packages\\aiohttp\\client.py\", line 1141, in __aenter__\n",
      "    self._resp = await self._coro\n",
      "  File \"c:\\users\\adria\\miniconda3\\envs\\scraper\\lib\\site-packages\\aiohttp\\client.py\", line 536, in _request\n",
      "    conn = await self._connector.connect(\n",
      "  File \"c:\\users\\adria\\miniconda3\\envs\\scraper\\lib\\site-packages\\aiohttp\\connector.py\", line 543, in connect\n",
      "    raise ClientConnectionError(\"Connector is closed.\")\n",
      "aiohttp.client_exceptions.ClientConnectionError: Connector is closed.\n"
     ]
    },
    {
     "name": "stderr",
     "output_type": "stream",
     "text": [
      "Task exception was never retrieved\n",
      "future: <Task finished name='Task-27786' coro=<tqdm_asyncio.gather.<locals>.wrap_awaitable() done, defined at c:\\users\\adria\\miniconda3\\envs\\scraper\\lib\\site-packages\\tqdm\\asyncio.py:75> exception=ClientConnectionError('Connector is closed.')>\n",
      "Traceback (most recent call last):\n",
      "  File \"c:\\users\\adria\\miniconda3\\envs\\scraper\\lib\\site-packages\\tqdm\\asyncio.py\", line 76, in wrap_awaitable\n",
      "    return i, await f\n",
      "  File \"C:\\Users\\adria\\AppData\\Local\\Temp\\ipykernel_27608\\3299729886.py\", line 22, in checker\n",
      "    async with session.get(url, allow_redirects=True, ssl=False, raise_for_status=True, timeout=100, headers=headers) as r:\n",
      "  File \"c:\\users\\adria\\miniconda3\\envs\\scraper\\lib\\site-packages\\aiohttp\\client.py\", line 1141, in __aenter__\n",
      "    self._resp = await self._coro\n",
      "  File \"c:\\users\\adria\\miniconda3\\envs\\scraper\\lib\\site-packages\\aiohttp\\client.py\", line 536, in _request\n",
      "    conn = await self._connector.connect(\n",
      "  File \"c:\\users\\adria\\miniconda3\\envs\\scraper\\lib\\site-packages\\aiohttp\\connector.py\", line 543, in connect\n",
      "    raise ClientConnectionError(\"Connector is closed.\")\n",
      "aiohttp.client_exceptions.ClientConnectionError: Connector is closed.\n",
      "Task exception was never retrieved\n",
      "future: <Task finished name='Task-31275' coro=<tqdm_asyncio.gather.<locals>.wrap_awaitable() done, defined at c:\\users\\adria\\miniconda3\\envs\\scraper\\lib\\site-packages\\tqdm\\asyncio.py:75> exception=ClientConnectionError('Connector is closed.')>\n",
      "Traceback (most recent call last):\n",
      "  File \"c:\\users\\adria\\miniconda3\\envs\\scraper\\lib\\site-packages\\tqdm\\asyncio.py\", line 76, in wrap_awaitable\n",
      "    return i, await f\n",
      "  File \"C:\\Users\\adria\\AppData\\Local\\Temp\\ipykernel_27608\\3299729886.py\", line 22, in checker\n",
      "    async with session.get(url, allow_redirects=True, ssl=False, raise_for_status=True, timeout=100, headers=headers) as r:\n",
      "  File \"c:\\users\\adria\\miniconda3\\envs\\scraper\\lib\\site-packages\\aiohttp\\client.py\", line 1141, in __aenter__\n",
      "    self._resp = await self._coro\n",
      "  File \"c:\\users\\adria\\miniconda3\\envs\\scraper\\lib\\site-packages\\aiohttp\\client.py\", line 536, in _request\n",
      "    conn = await self._connector.connect(\n",
      "  File \"c:\\users\\adria\\miniconda3\\envs\\scraper\\lib\\site-packages\\aiohttp\\connector.py\", line 543, in connect\n",
      "    raise ClientConnectionError(\"Connector is closed.\")\n",
      "aiohttp.client_exceptions.ClientConnectionError: Connector is closed.\n",
      "Task exception was never retrieved\n",
      "future: <Task finished name='Task-27838' coro=<tqdm_asyncio.gather.<locals>.wrap_awaitable() done, defined at c:\\users\\adria\\miniconda3\\envs\\scraper\\lib\\site-packages\\tqdm\\asyncio.py:75> exception=ClientConnectionError('Connector is closed.')>\n",
      "Traceback (most recent call last):\n",
      "  File \"c:\\users\\adria\\miniconda3\\envs\\scraper\\lib\\site-packages\\tqdm\\asyncio.py\", line 76, in wrap_awaitable\n",
      "    return i, await f\n",
      "  File \"C:\\Users\\adria\\AppData\\Local\\Temp\\ipykernel_27608\\3299729886.py\", line 22, in checker\n",
      "    async with session.get(url, allow_redirects=True, ssl=False, raise_for_status=True, timeout=100, headers=headers) as r:\n",
      "  File \"c:\\users\\adria\\miniconda3\\envs\\scraper\\lib\\site-packages\\aiohttp\\client.py\", line 1141, in __aenter__\n",
      "    self._resp = await self._coro\n",
      "  File \"c:\\users\\adria\\miniconda3\\envs\\scraper\\lib\\site-packages\\aiohttp\\client.py\", line 536, in _request\n",
      "    conn = await self._connector.connect(\n",
      "  File \"c:\\users\\adria\\miniconda3\\envs\\scraper\\lib\\site-packages\\aiohttp\\connector.py\", line 543, in connect\n",
      "    raise ClientConnectionError(\"Connector is closed.\")\n",
      "aiohttp.client_exceptions.ClientConnectionError: Connector is closed.\n",
      "Task exception was never retrieved\n",
      "future: <Task finished name='Task-29415' coro=<tqdm_asyncio.gather.<locals>.wrap_awaitable() done, defined at c:\\users\\adria\\miniconda3\\envs\\scraper\\lib\\site-packages\\tqdm\\asyncio.py:75> exception=ClientConnectionError('Connector is closed.')>\n",
      "Traceback (most recent call last):\n",
      "  File \"c:\\users\\adria\\miniconda3\\envs\\scraper\\lib\\site-packages\\tqdm\\asyncio.py\", line 76, in wrap_awaitable\n",
      "    return i, await f\n",
      "  File \"C:\\Users\\adria\\AppData\\Local\\Temp\\ipykernel_27608\\3299729886.py\", line 22, in checker\n",
      "    async with session.get(url, allow_redirects=True, ssl=False, raise_for_status=True, timeout=100, headers=headers) as r:\n",
      "  File \"c:\\users\\adria\\miniconda3\\envs\\scraper\\lib\\site-packages\\aiohttp\\client.py\", line 1141, in __aenter__\n",
      "    self._resp = await self._coro\n",
      "  File \"c:\\users\\adria\\miniconda3\\envs\\scraper\\lib\\site-packages\\aiohttp\\client.py\", line 536, in _request\n",
      "    conn = await self._connector.connect(\n",
      "  File \"c:\\users\\adria\\miniconda3\\envs\\scraper\\lib\\site-packages\\aiohttp\\connector.py\", line 543, in connect\n",
      "    raise ClientConnectionError(\"Connector is closed.\")\n",
      "aiohttp.client_exceptions.ClientConnectionError: Connector is closed.\n",
      "Task exception was never retrieved\n",
      "future: <Task finished name='Task-28479' coro=<tqdm_asyncio.gather.<locals>.wrap_awaitable() done, defined at c:\\users\\adria\\miniconda3\\envs\\scraper\\lib\\site-packages\\tqdm\\asyncio.py:75> exception=ClientConnectionError('Connector is closed.')>\n",
      "Traceback (most recent call last):\n",
      "  File \"c:\\users\\adria\\miniconda3\\envs\\scraper\\lib\\site-packages\\tqdm\\asyncio.py\", line 76, in wrap_awaitable\n",
      "    return i, await f\n",
      "  File \"C:\\Users\\adria\\AppData\\Local\\Temp\\ipykernel_27608\\3299729886.py\", line 22, in checker\n",
      "    async with session.get(url, allow_redirects=True, ssl=False, raise_for_status=True, timeout=100, headers=headers) as r:\n",
      "  File \"c:\\users\\adria\\miniconda3\\envs\\scraper\\lib\\site-packages\\aiohttp\\client.py\", line 1141, in __aenter__\n",
      "    self._resp = await self._coro\n",
      "  File \"c:\\users\\adria\\miniconda3\\envs\\scraper\\lib\\site-packages\\aiohttp\\client.py\", line 536, in _request\n",
      "    conn = await self._connector.connect(\n",
      "  File \"c:\\users\\adria\\miniconda3\\envs\\scraper\\lib\\site-packages\\aiohttp\\connector.py\", line 543, in connect\n",
      "    raise ClientConnectionError(\"Connector is closed.\")\n",
      "aiohttp.client_exceptions.ClientConnectionError: Connector is closed.\n",
      "Task exception was never retrieved\n",
      "future: <Task finished name='Task-26722' coro=<tqdm_asyncio.gather.<locals>.wrap_awaitable() done, defined at c:\\users\\adria\\miniconda3\\envs\\scraper\\lib\\site-packages\\tqdm\\asyncio.py:75> exception=ClientConnectionError('Connector is closed.')>\n",
      "Traceback (most recent call last):\n",
      "  File \"c:\\users\\adria\\miniconda3\\envs\\scraper\\lib\\site-packages\\tqdm\\asyncio.py\", line 76, in wrap_awaitable\n",
      "    return i, await f\n",
      "  File \"C:\\Users\\adria\\AppData\\Local\\Temp\\ipykernel_27608\\3299729886.py\", line 22, in checker\n",
      "    async with session.get(url, allow_redirects=True, ssl=False, raise_for_status=True, timeout=100, headers=headers) as r:\n",
      "  File \"c:\\users\\adria\\miniconda3\\envs\\scraper\\lib\\site-packages\\aiohttp\\client.py\", line 1141, in __aenter__\n",
      "    self._resp = await self._coro\n",
      "  File \"c:\\users\\adria\\miniconda3\\envs\\scraper\\lib\\site-packages\\aiohttp\\client.py\", line 536, in _request\n",
      "    conn = await self._connector.connect(\n",
      "  File \"c:\\users\\adria\\miniconda3\\envs\\scraper\\lib\\site-packages\\aiohttp\\connector.py\", line 543, in connect\n",
      "    raise ClientConnectionError(\"Connector is closed.\")\n",
      "aiohttp.client_exceptions.ClientConnectionError: Connector is closed.\n",
      "Task exception was never retrieved\n",
      "future: <Task finished name='Task-27427' coro=<tqdm_asyncio.gather.<locals>.wrap_awaitable() done, defined at c:\\users\\adria\\miniconda3\\envs\\scraper\\lib\\site-packages\\tqdm\\asyncio.py:75> exception=ClientConnectionError('Connector is closed.')>\n",
      "Traceback (most recent call last):\n",
      "  File \"c:\\users\\adria\\miniconda3\\envs\\scraper\\lib\\site-packages\\tqdm\\asyncio.py\", line 76, in wrap_awaitable\n",
      "    return i, await f\n",
      "  File \"C:\\Users\\adria\\AppData\\Local\\Temp\\ipykernel_27608\\3299729886.py\", line 22, in checker\n",
      "    async with session.get(url, allow_redirects=True, ssl=False, raise_for_status=True, timeout=100, headers=headers) as r:\n",
      "  File \"c:\\users\\adria\\miniconda3\\envs\\scraper\\lib\\site-packages\\aiohttp\\client.py\", line 1141, in __aenter__\n",
      "    self._resp = await self._coro\n",
      "  File \"c:\\users\\adria\\miniconda3\\envs\\scraper\\lib\\site-packages\\aiohttp\\client.py\", line 536, in _request\n",
      "    conn = await self._connector.connect(\n",
      "  File \"c:\\users\\adria\\miniconda3\\envs\\scraper\\lib\\site-packages\\aiohttp\\connector.py\", line 543, in connect\n",
      "    raise ClientConnectionError(\"Connector is closed.\")\n",
      "aiohttp.client_exceptions.ClientConnectionError: Connector is closed.\n"
     ]
    },
    {
     "name": "stderr",
     "output_type": "stream",
     "text": [
      "Task exception was never retrieved\n",
      "future: <Task finished name='Task-29539' coro=<tqdm_asyncio.gather.<locals>.wrap_awaitable() done, defined at c:\\users\\adria\\miniconda3\\envs\\scraper\\lib\\site-packages\\tqdm\\asyncio.py:75> exception=ClientConnectionError('Connector is closed.')>\n",
      "Traceback (most recent call last):\n",
      "  File \"c:\\users\\adria\\miniconda3\\envs\\scraper\\lib\\site-packages\\tqdm\\asyncio.py\", line 76, in wrap_awaitable\n",
      "    return i, await f\n",
      "  File \"C:\\Users\\adria\\AppData\\Local\\Temp\\ipykernel_27608\\3299729886.py\", line 22, in checker\n",
      "    async with session.get(url, allow_redirects=True, ssl=False, raise_for_status=True, timeout=100, headers=headers) as r:\n",
      "  File \"c:\\users\\adria\\miniconda3\\envs\\scraper\\lib\\site-packages\\aiohttp\\client.py\", line 1141, in __aenter__\n",
      "    self._resp = await self._coro\n",
      "  File \"c:\\users\\adria\\miniconda3\\envs\\scraper\\lib\\site-packages\\aiohttp\\client.py\", line 536, in _request\n",
      "    conn = await self._connector.connect(\n",
      "  File \"c:\\users\\adria\\miniconda3\\envs\\scraper\\lib\\site-packages\\aiohttp\\connector.py\", line 543, in connect\n",
      "    raise ClientConnectionError(\"Connector is closed.\")\n",
      "aiohttp.client_exceptions.ClientConnectionError: Connector is closed.\n",
      "Task exception was never retrieved\n",
      "future: <Task finished name='Task-27103' coro=<tqdm_asyncio.gather.<locals>.wrap_awaitable() done, defined at c:\\users\\adria\\miniconda3\\envs\\scraper\\lib\\site-packages\\tqdm\\asyncio.py:75> exception=ClientConnectionError('Connector is closed.')>\n",
      "Traceback (most recent call last):\n",
      "  File \"c:\\users\\adria\\miniconda3\\envs\\scraper\\lib\\site-packages\\tqdm\\asyncio.py\", line 76, in wrap_awaitable\n",
      "    return i, await f\n",
      "  File \"C:\\Users\\adria\\AppData\\Local\\Temp\\ipykernel_27608\\3299729886.py\", line 22, in checker\n",
      "    async with session.get(url, allow_redirects=True, ssl=False, raise_for_status=True, timeout=100, headers=headers) as r:\n",
      "  File \"c:\\users\\adria\\miniconda3\\envs\\scraper\\lib\\site-packages\\aiohttp\\client.py\", line 1141, in __aenter__\n",
      "    self._resp = await self._coro\n",
      "  File \"c:\\users\\adria\\miniconda3\\envs\\scraper\\lib\\site-packages\\aiohttp\\client.py\", line 536, in _request\n",
      "    conn = await self._connector.connect(\n",
      "  File \"c:\\users\\adria\\miniconda3\\envs\\scraper\\lib\\site-packages\\aiohttp\\connector.py\", line 543, in connect\n",
      "    raise ClientConnectionError(\"Connector is closed.\")\n",
      "aiohttp.client_exceptions.ClientConnectionError: Connector is closed.\n",
      "  6%|███████████████████                                                                                                                                                                                                                                                                                            | 308/4892 [00:34<04:33, 16.75it/s]"
     ]
    }
   ],
   "source": [
    "import aiohttp\n",
    "import asyncio\n",
    "import re\n",
    "import cgi\n",
    "from pathlib import Path\n",
    "from urllib.parse import urlparse"
   ]
  },
  {
   "cell_type": "code",
   "execution_count": 6,
   "metadata": {
    "id": "mjOXyChH8lQK",
    "scrolled": true
   },
   "outputs": [],
   "source": [
    "def is_url(url):\n",
    "    try:\n",
    "        a = urlparse(url)\n",
    "        return all([a.scheme, a.netloc])\n",
    "    except ValueError:\n",
    "        return False"
   ]
  },
  {
   "cell_type": "code",
   "execution_count": 53,
   "metadata": {
    "id": "-s1TVWxsxEJR",
    "scrolled": true
   },
   "outputs": [],
   "source": [
    "async def checker(session, url):\n",
    "    if pd.isna(url):\n",
    "        return pd.NA\n",
    "    \n",
    "    if \"/../\" in url or \"|\" in url: # aiohttp is kinda not smart\n",
    "        return url\n",
    "\n",
    "    \n",
    "    headers= {\n",
    "    \"User-Agent\": \"Mozilla/5.0 (Windows NT 10.0; Win64; x64; rv:98.0) Gecko/20100101 Firefox/98.0\",\n",
    "    \"Accept\": \"text/html,application/xhtml+xml,application/xml;q=0.9,image/avif,image/webp,*/*;q=0.8\",\n",
    "    \"Accept-Language\": \"en-US,en;q=0.5\",\n",
    "    \"Accept-Encoding\": \"gzip, deflate\",\n",
    "    \"Connection\": \"keep-alive\",\n",
    "    \"Upgrade-Insecure-Requests\": \"1\",\n",
    "    \"Sec-Fetch-Dest\": \"document\",\n",
    "    \"Sec-Fetch-Mode\": \"navigate\",\n",
    "    \"Sec-Fetch-Site\": \"none\",\n",
    "    \"Sec-Fetch-User\": \"?1\",\n",
    "    \"Cache-Control\": \"max-age=0\",\n",
    "    \"Host\": urlparse(url).netloc,\n",
    "    \"Referer\": urlparse(url).netloc\n",
    "    }\n",
    "    try:\n",
    "        async with session.get(url, allow_redirects=True, ssl=False, raise_for_status=True, timeout=100, headers=headers) as r:\n",
    "            if r.status == 200:\n",
    "                return url\n",
    "            elif r.status == 404:\n",
    "                return pd.NA\n",
    "            elif r.status == 301 or r.status == 302:\n",
    "                new_loc = r.headers.get('location')\n",
    "                if is_url(new_loc):\n",
    "                    return new_loc\n",
    "                else:\n",
    "                    return pd.NA\n",
    "            elif r.status != 200 and r.status != 404:\n",
    "#                 print(f\"\\nUnkknown code: {r.status} {url}\")\n",
    "                return url\n",
    "\n",
    "    except aiohttp.ClientResponseError as e:\n",
    "#         print(\"ERROR\", e, url)\n",
    "        return url\n",
    "\n",
    "    except asyncio.TimeoutError:\n",
    "        return url\n",
    "\n",
    "    except aiohttp.ClientConnectionError:\n",
    "        return url    \n",
    "    \n",
    "    except KeyboardInterrupt:\n",
    "        import os; os.exit()\n",
    "    except Exception:\n",
    "        return url"
   ]
  },
  {
   "cell_type": "code",
   "execution_count": 38,
   "metadata": {
    "id": "Jla4P4ikxIGH",
    "scrolled": true
   },
   "outputs": [],
   "source": [
    "from tqdm.asyncio import tqdm\n",
    "\n",
    "async def main():\n",
    "    async with aiohttp.ClientSession(raise_for_status = True) as session:\n",
    "        cols = [\"cdm_url\", \"homepage\", \"cdm_indirect_url\"]\n",
    "        for col in cols:\n",
    "            df[col] = await tqdm.gather(*(checker(session, url) for url in df[col]), leave=True, position=0)\n",
    "        return df"
   ]
  },
  {
   "cell_type": "code",
   "execution_count": 54,
   "metadata": {
    "colab": {
     "base_uri": "https://localhost:8080/",
     "height": 1000
    },
    "id": "0jzfvZn8xN9-",
    "outputId": "d42d8f61-a106-48c8-cd2d-8cf4f8730ae0",
    "scrolled": true
   },
   "outputs": [
    {
     "name": "stderr",
     "output_type": "stream",
     "text": [
      " 16%|███████████████████████████████████████████████▍                                                                                                                                                                                                                                                               | 766/4892 [02:51<15:25,  4.46it/s]\n",
      "100%|██████████████████████████████████████████████████████████████████████████████████████████████████████████████████████████████████████████████████████████████████████████████████████████████████████████████████████████████████████████████████████████████████████████████████████████████████████████████| 4892/4892 [01:41<00:00, 48.14it/s]\n",
      "100%|██████████████████████████████████████████████████████████████████████████████████████████████████████████████████████████████████████████████████████████████████████████████████████████████████████████████████████████████████████████████████████████████████████████████████████████████████████████████| 4892/4892 [01:49<00:00, 44.51it/s]\n",
      "100%|██████████████████████████████████████████████████████████████████████████████████████████████████████████████████████████████████████████████████████████████████████████████████████████████████████████████████████████████████████████████████████████████████████████████████████████████████████████████| 4892/4892 [02:30<00:00, 32.52it/s]\n"
     ]
    }
   ],
   "source": [
    "t = await main()"
   ]
  },
  {
   "cell_type": "code",
   "execution_count": 56,
   "metadata": {
    "colab": {
     "base_uri": "https://localhost:8080/",
     "height": 424
    },
    "id": "7XiiZGZJxO8-",
    "outputId": "63403263-0072-4c12-c2cd-6f4628b9af80",
    "scrolled": false
   },
   "outputs": [],
   "source": [
    "t.to_csv(\"checked_urls.csv\", index=False)"
   ]
  },
  {
   "cell_type": "code",
   "execution_count": null,
   "metadata": {
    "id": "kiWDfsNKx0K3",
    "scrolled": true
   },
   "outputs": [],
   "source": []
  }
 ],
 "metadata": {
  "colab": {
   "provenance": []
  },
  "kernelspec": {
   "display_name": "Python 3 (ipykernel)",
   "language": "python",
   "name": "python3"
  },
  "language_info": {
   "codemirror_mode": {
    "name": "ipython",
    "version": 3
   },
   "file_extension": ".py",
   "mimetype": "text/x-python",
   "name": "python",
   "nbconvert_exporter": "python",
   "pygments_lexer": "ipython3",
   "version": "3.8.8"
  }
 },
 "nbformat": 4,
 "nbformat_minor": 1
}
